Workbook
Name Bi_Weekly: Sheet2!$Q$3
Name int: Sheet1!$D$4
Name Monthly: Sheet2!$Q$4
Name None: Sheet2!$Q$7
Name plot_date: OFFSET(Sheet1!$C$31,0,0,COUNTA(Sheet1!$C:$C)-1)
Name plot_return: OFFSET(Sheet1!$Y$31,0,0,COUNTA(Sheet1!$Y:$Y)-1)
Name plot_return2: OFFSET(Sheet1!$AD$31,0,0,COUNTA(Sheet1!$AD:$AD)-1)
Name Quarterly: Sheet2!$Q$5
Name Weekly: Sheet2!$Q$2
Name Yearly: Sheet2!$Q$6

Sheet Sheet1
C1: Dollar Cost Average Method (DCA)
C3: Initial Investment | D3: 50
C4: Interval | D4: Monthly
C5: Increment | D5: 100
C6: Amount | D6: 15000
C7: Date Range
C9: ROI | D9: =Y30 -> 0.45033962
C10: IRR | D10: =XIRR(AF31:AF930,$C31:$C930) -> #VALUE!
C11: Time-weighted | D11: =(U30-U31-(AF30+U30))/(U31-AJ30) -> -1.4219434
C12: annual
C23: Symbol | D23: T
C24: Weight | D24: 1
C25: Return(%) | D25: {=(LOOKUP(2,1/(D:D<>""),D:D)-INDEX(D:D,31))/INDEX(D:D,31)} -> -0.024652744
B29: No | C29: Date | D29: Price($) | E29: Dividends | F29: Cash Flow | J29: Shares | L29: Total Shares | N29: Dividends | O29: Cash Flow | Q29: Shares | R29: Total Shares | S29: Total Shares | T29: Cost Basis($) | U29: Mkt Value($) | W29: Gain($) | X29: Dividends($) | Y29: Return(%) | AA29: Cost Basis($) | AB29: Mkt Value($) | AC29: Gain($) | AD29: Return (%) | AF29: Cash Flows | AH29: Di | AI29: Wi | AJ29: Wi x Fi
T30: {=LOOKUP(2,1/(T:T<>""),T:T)} -> 22450 | U30: {=LOOKUP(2,1/(U:U<>""),U:U)} -> 20479.731 | V30: {=LOOKUP(2,1/(V:V<>""),V:V)} -> -0.087762554 | W30: {=LOOKUP(2,1/(W:W<>""),W:W)} -> -1970.2693 | X30: {=LOOKUP(2,1/(X:X<>""),X:X)} -> 12080.394 | Y30: {=LOOKUP(2,1/(Y:Y<>""),Y:Y)} -> 0.45033962 | AA30: {=LOOKUP(2,1/(AA:AA<>""),AA:AA)} -> 34530.394 | AB30: {=LOOKUP(2,1/(AB:AB<>""),AB:AB)} -> 30688.142 | AC30: {=LOOKUP(2,1/(AC:AC<>""),AC:AC)} -> -3842.252 | AD30: {=LOOKUP(2,1/(AD:AD<>""),AD:AD)} -> -0.11127159 | AF30: =SUM(AF31:AF929) -> -10369.606 | AG30: =SUM(AG31:AG929) -> -22450 | AH30: {=LOOKUP(2,1/(AH:AH<>""),AH:AH)} -> 6286 | AJ30: =-SUM(AJ31:AJ929) -> 7307.396 | AK30: =-SUM(AK31:AK929) -> 11225.056
B31: =IF(C30="","",IF(C$30<C31,"",B30+1)) | C31: =IF(Sheet3!A2="","",Sheet3!A2) -> 37627 | D31: =IF(C31="","",Sheet3!E2) -> 28.799999 | E31: =_xlfn.XLOOKUP(WEEKNUM(C31)&YEAR(C31),Sheet4!C:C,Sheet4!B:B,0) -> 0.27 | F31: =-D3 -> -50 | H31: =F31 -> -50 | J31: =IF(D$24=0,"",ABS($F31*D$24)/D31) -> 1.7361112 | L31: =IF(D31=0,"",J31) -> 1.7361112 | N31: =IF(D31=0,"",L31*E31) -> 0.46875002 | O31: =-(IF(D31=0,"",N31)) -> -0.46875002 | P31: =F31 -> -50 | Q31: =ABS(O31)/D31 -> 0.016276043 | R31: =Q31 -> 0.016276043 | S31: =IF(D31=0,"",L31+R31) -> 1.7523872 | T31: =D31*J31 -> 50 | U31: =IF(D31=0,"",L31*D31) -> 50 | V31: =(U31/T31)-1 -> 0 | W31: =U31-T31 -> 0 | X31: =ABS(O31) -> 0.46875002 | Y31: =((U31+X31)/T31)-1 -> 0.0093750003 | AA31: =(D31*Q31)+(D31*J31) -> 50.46875 | AB31: =(L31*D31)+(D31*R31) -> 50.46875 | AC31: =AB31-AA31 -> 0 | AD31: =(AB31/AA31)-1 -> 0 | AF31: =F31+ABS(O31) -> -49.53125 | AG31: =F31 -> -50 | AH31: =DATEDIF($C$31,C31,"d") -> 0 | AI31: =(AH$30-AH31)/AH$30 -> 1 | AJ31: =$AI31*AF31 -> -49.53125 | AK31: =$AI31*AG31 -> -50
B32: =IF(C31="","",IF(C$30<C32,"",B31+1)) | C32: =IF(Sheet3!A3="","",Sheet3!A3) -> 37634 | D32: =IF(C32="","",Sheet3!E3) -> 27.280001 | E32: =_xlfn.XLOOKUP(WEEKNUM(C32)&YEAR(C32),Sheet4!C:C,Sheet4!B:B,0) -> 0 | F32: =IF(int=Weekly,-$D$5,IF(int=Bi_Weekly,0,IF(int=Monthly,0,IF(int=Quarterly,0,IF(int=Yearly,0,IF(int=None,0,0)))))) -> 0 | H32: =H31+F32 -> -50 | J32: =IF(D$24=0,"",ABS($F32*D$24)/D32) -> 0 | L32: =IF(D32=0,"",L31+J32) -> 1.7361112 | N32: =IF(D32=0,"",L32*E32) -> 0 | O32: =-(IF(D32=0,"",N32)) -> 0 | P32: =P31+F32+O32 -> -50 | Q32: =IF(D32=0,"",ABS($O32)/D32) -> 0 | R32: =IF(D32=0,"",Q32+R31) -> 0.016276043 | S32: =IF(D32=0,"",L32+R32) -> 1.7523872 | T32: =IF(D32=0,"",D32*J32)+T31 -> 50 | U32: =IF(D32=0,"",L32*D32) -> 47.361114 | V32: =(U32/T32)-1 -> -0.05277771 | W32: =U32-T32 -> -2.6388855 | X32: =ABS(O32)+X31 -> 0.46875002 | Y32: =((U32+X32)/T32)-1 -> -0.04340271 | AA32: =(D32*Q32)+(D32*J32)+AA31 -> 50.46875 | AB32: =(L32*D32)+(D32*R32) -> 47.805125 | AC32: =AB32-AA32 -> -2.6636251 | AD32: =(AB32/AA32)-1 -> -0.05277771 | AF32: =F32+ABS(O32) -> 0 | AG32: =F32 -> 0 | AH32: =DATEDIF($C$31,C32,"d") -> 7 | AI32: =(AH$30-AH32)/AH$30 -> 0.99888641 | AJ32: =AI32*AF32 -> 0 | AK32: =$AI32*AG32 -> 0
B33: =IF(C32="","",IF(C$30<C33,"",B32+1)) | C33: =IF(Sheet3!A4="","",Sheet3!A4) -> 37641 | D33: =IF(C33="","",Sheet3!E4) -> 24.540001 | E33: =_xlfn.XLOOKUP(WEEKNUM(C33)&YEAR(C33),Sheet4!C:C,Sheet4!B:B,0) -> 0 | F33: =IF(int=Weekly,-$D$5,IF(int=Bi_Weekly,-$D$5,IF(int=Monthly,0,IF(int=Quarterly,0,IF(int=Yearly,0,IF(int=None,0,0)))))) -> 0 | H33: =H32+F33 -> -50 | J33: =IF(D$24=0,"",ABS($F33*D$24)/D33) -> 0 | L33: =IF(D33=0,"",L32+J33) -> 1.7361112 | N33: =IF(D33=0,"",L33*E33) -> 0 | O33: =-(IF(D33=0,"",N33)) -> 0 | P33: =P32+F33+O33 -> -50 | Q33: =IF(D33=0,"",ABS($O33)/D33) -> 0 | R33: =IF(D33=0,"",Q33+R32) -> 0.016276043 | S33: =IF(D33=0,"",L33+R33) -> 1.7523872 | T33: =IF(D33=0,"",D33*J33)+T32 -> 50 | U33: =IF(D33=0,"",L33*D33) -> 42.60417 | V33: =(U33/T33)-1 -> -0.1479166 | W33: =U33-T33 -> -7.3958301 | X33: =ABS(O33)+X32 -> 0.46875002 | Y33: =((U33+X33)/T33)-1 -> -0.1385416 | AA33: =(D33*Q33)+(D33*J33)+AA32 -> 50.46875 | AB33: =(L33*D33)+(D33*R33) -> 43.003584 | AC33: =AB33-AA33 -> -7.465166 | AD33: =(AB33/AA33)-1 -> -0.1479166 | AF33: =F33+ABS(O33) -> 0 | AG33: =F33 -> 0 | AH33: =DATEDIF($C$31,C33,"d") -> 14 | AI33: =(AH$30-AH33)/AH$30 -> 0.99777283 | AJ33: =AI33*AF33 -> 0 | AK33: =$AI33*AG33 -> 0
B34: =IF(C33="","",IF(C$30<C34,"",B33+1)) | C34: =IF(Sheet3!A5="","",Sheet3!A5) -> 37648 | D34: =IF(C34="","",Sheet3!E5) -> 24.440001 | E34: =_xlfn.XLOOKUP(WEEKNUM(C34)&YEAR(C34),Sheet4!C:C,Sheet4!B:B,0) -> 0 | F34: =IF(int=Weekly,-$D$5,IF(int=Bi_Weekly,0,IF(int=Monthly,0,IF(int=Quarterly,0,IF(int=Yearly,0,IF(int=None,0,0)))))) -> 0 | H34: =H33+F34 -> -50 | J34: =IF(D$24=0,"",ABS($F34*D$24)/D34) -> 0 | L34: =IF(D34=0,"",L33+J34) -> 1.7361112 | N34: =IF(D34=0,"",L34*E34) -> 0 | O34: =-(IF(D34=0,"",N34)) -> 0 | P34: =P33+F34+O34 -> -50 | Q34: =IF(D34=0,"",ABS($O34)/D34) -> 0 | R34: =IF(D34=0,"",Q34+R33) -> 0.016276043 | S34: =IF(D34=0,"",L34+R34) -> 1.7523872 | T34: =IF(D34=0,"",D34*J34)+T33 -> 50 | U34: =IF(D34=0,"",L34*D34) -> 42.430559 | V34: =(U34/T34)-1 -> -0.15138882 | W34: =U34-T34 -> -7.5694412 | X34: =ABS(O34)+X33 -> 0.46875002 | Y34: =((U34+X34)/T34)-1 -> -0.14201382 | AA34: =(D34*Q34)+(D34*J34)+AA33 -> 50.46875 | AB34: =(L34*D34)+(D34*R34) -> 42.828345 | AC34: =AB34-AA34 -> -7.6404047 | AD34: =(AB34/AA34)-1 -> -0.15138882 | AF34: =F34+ABS(O34) -> 0 | AG34: =F34 -> 0 | AH34: =DATEDIF($C$31,C34,"d") -> 21 | AI34: =(AH$30-AH34)/AH$30 -> 0.99665924 | AJ34: =AI34*AF34 -> 0 | AK34: =$AI34*AG34 -> 0
B35: =IF(C34="","",IF(C$30<C35,"",B34+1)) | C35: =IF(Sheet3!A6="","",Sheet3!A6) -> 37655 | D35: =IF(C35="","",Sheet3!E6) -> 25.18 | E35: =_xlfn.XLOOKUP(WEEKNUM(C35)&YEAR(C35),Sheet4!C:C,Sheet4!B:B,0) -> 0 | F35: =IF(int=Weekly,-$D$5,IF(int=Bi_Weekly,-$D$5,IF(int=Monthly,-$D$5,IF(int=Quarterly,0,IF(int=Yearly,0,IF(int=None,0,0)))))) -> -100 | H35: =H34+F35 -> -150 | J35: =IF(D$24=0,"",ABS($F35*D$24)/D35) -> 3.9714059 | L35: =IF(D35=0,"",L34+J35) -> 5.707517 | N35: =IF(D35=0,"",L35*E35) -> 0 | O35: =-(IF(D35=0,"",N35)) -> 0 | P35: =P34+F35+O35 -> -150 | Q35: =IF(D35=0,"",ABS($O35)/D35) -> 0 | R35: =IF(D35=0,"",Q35+R34) -> 0.016276043 | S35: =IF(D35=0,"",L35+R35) -> 5.7237931 | T35: =IF(D35=0,"",D35*J35)+T34 -> 150 | U35: =IF(D35=0,"",L35*D35) -> 143.71528 | V35: =(U35/T35)-1 -> -0.041898138 | W35: =U35-T35 -> -6.2847207 | X35: =ABS(O35)+X34 -> 0.46875002 | Y35: =((U35+X35)/T35)-1 -> -0.038773138 | AA35: =(D35*Q35)+(D35*J35)+AA34 -> 150.46875 | AB35: =(L35*D35)+(D35*R35) -> 144.12511 | AC35: =AB35-AA35 -> -6.34364 | AD35: =(AB35/AA35)-1 -> -0.042159186 | AF35: =F35+ABS(O35) -> -100 | AG35: =F35 -> -100 | AH35: =DATEDIF($C$31,C35,"d") -> 28 | AI35: =(AH$30-AH35)/AH$30 -> 0.99554566 | AJ35: =AI35*AF35 -> -99.554566 | AK35: =$AI35*AG35 -> -99.554566
B36: =IF(C35="","",IF(C$30<C36,"",B35+1)) | C36: =IF(Sheet3!A7="","",Sheet3!A7) -> 37662 | D36: =IF(C36="","",Sheet3!E7) -> 23.35 | E36: =_xlfn.XLOOKUP(WEEKNUM(C36)&YEAR(C36),Sheet4!C:C,Sheet4!B:B,0) -> 0 | F36: =IF(int=Weekly,-$D$5,IF(int=Bi_Weekly,0,IF(int=Monthly,0,IF(int=Quarterly,0,IF(int=Yearly,0,IF(int=None,0,0)))))) -> 0 | H36: =H35+F36 -> -150 | J36: =IF(D$24=0,"",ABS($F36*D$24)/D36) -> 0 | L36: =IF(D36=0,"",L35+J36) -> 5.707517 | N36: =IF(D36=0,"",L36*E36) -> 0 | O36: =-(IF(D36=0,"",N36)) -> 0 | P36: =P35+F36+O36 -> -150 | Q36: =IF(D36=0,"",ABS($O36)/D36) -> 0 | R36: =IF(D36=0,"",Q36+R35) -> 0.016276043 | S36: =IF(D36=0,"",L36+R36) -> 5.7237931 | T36: =IF(D36=0,"",D36*J36)+T35 -> 150 | U36: =IF(D36=0,"",L36*D36) -> 133.27052 | V36: =(U36/T36)-1 -> -0.11152985 | W36: =U36-T36 -> -16.729477 | X36: =ABS(O36)+X35 -> 0.46875002 | Y36: =((U36+X36)/T36)-1 -> -0.10840485 | AA36: =(D36*Q36)+(D36*J36)+AA35 -> 150.46875 | AB36: =(L36*D36)+(D36*R36) -> 133.65057 | AC36: =AB36-AA36 -> -16.818181 | AD36: =(AB36/AA36)-1 -> -0.11177192 | AF36: =F36+ABS(O36) -> 0 | AG36: =F36 -> 0 | AH36: =DATEDIF($C$31,C36,"d") -> 35 | AI36: =(AH$30-AH36)/AH$30 -> 0.99443207 | AJ36: =AI36*AF36 -> 0 | AK36: =$AI36*AG36 -> 0
B37: =IF(C36="","",IF(C$30<C37,"",B36+1)) | C37: =IF(Sheet3!A8="","",Sheet3!A8) -> 37669 | D37: =IF(C37="","",Sheet3!E8) -> 20.73 | E37: =_xlfn.XLOOKUP(WEEKNUM(C37)&YEAR(C37),Sheet4!C:C,Sheet4!B:B,0) -> 0 | F37: =IF(int=Weekly,-$D$5,IF(int=Bi_Weekly,-$D$5,IF(int=Monthly,0,IF(int=Quarterly,0,IF(int=Yearly,0,IF(int=None,0,0)))))) -> 0 | H37: =H36+F37 -> -150 | J37: =IF(D$24=0,"",ABS($F37*D$24)/D37) -> 0 | L37: =IF(D37=0,"",L36+J37) -> 5.707517 | N37: =IF(D37=0,"",L37*E37) -> 0 | O37: =-(IF(D37=0,"",N37)) -> 0 | P37: =P36+F37+O37 -> -150 | Q37: =IF(D37=0,"",ABS($O37)/D37) -> 0 | R37: =IF(D37=0,"",Q37+R36) -> 0.016276043 | S37: =IF(D37=0,"",L37+R37) -> 5.7237931 | T37: =IF(D37=0,"",D37*J37)+T36 -> 150 | U37: =IF(D37=0,"",L37*D37) -> 118.31683 | V37: =(U37/T37)-1 -> -0.21122114 | W37: =U37-T37 -> -31.683172 | X37: =ABS(O37)+X36 -> 0.46875002 | Y37: =((U37+X37)/T37)-1 -> -0.20809614 | AA37: =(D37*Q37)+(D37*J37)+AA36 -> 150.46875 | AB37: =(L37*D37)+(D37*R37) -> 118.65423 | AC37: =AB37-AA37 -> -31.814519 | AD37: =(AB37/AA37)-1 -> -0.21143606 | AF37: =F37+ABS(O37) -> 0 | AG37: =F37 -> 0 | AH37: =DATEDIF($C$31,C37,"d") -> 42 | AI37: =(AH$30-AH37)/AH$30 -> 0.99331849 | AJ37: =AI37*AF37 -> 0 | AK37: =$AI37*AG37 -> 0
B38: =IF(C37="","",IF(C$30<C38,"",B37+1)) | C38: =IF(Sheet3!A9="","",Sheet3!A9) -> 37676 | D38: =IF(C38="","",Sheet3!E9) -> 20.799999 | E38: =_xlfn.XLOOKUP(WEEKNUM(C38)&YEAR(C38),Sheet4!C:C,Sheet4!B:B,0) -> 0 | F38: =IF(int=Weekly,-$D$5,IF(int=Bi_Weekly,0,IF(int=Monthly,0,IF(int=Quarterly,0,IF(int=Yearly,0,IF(int=None,0,0)))))) -> 0 | H38: =H37+F38 -> -150 | J38: =IF(D$24=0,"",ABS($F38*D$24)/D38) -> 0 | L38: =IF(D38=0,"",L37+J38) -> 5.707517 | N38: =IF(D38=0,"",L38*E38) -> 0 | O38: =-(IF(D38=0,"",N38)) -> 0 | P38: =P37+F38+O38 -> -150 | Q38: =IF(D38=0,"",ABS($O38)/D38) -> 0 | R38: =IF(D38=0,"",Q38+R37) -> 0.016276043 | S38: =IF(D38=0,"",L38+R38) -> 5.7237931 | T38: =IF(D38=0,"",D38*J38)+T37 -> 150 | U38: =IF(D38=0,"",L38*D38) -> 118.71635 | V38: =(U38/T38)-1 -> -0.20855767 | W38: =U38-T38 -> -31.283651 | X38: =ABS(O38)+X37 -> 0.46875002 | Y38: =((U38+X38)/T38)-1 -> -0.20543267 | AA38: =(D38*Q38)+(D38*J38)+AA37 -> 150.46875 | AB38: =(L38*D38)+(D38*R38) -> 119.05489 | AC38: =AB38-AA38 -> -31.413859 | AD38: =(AB38/AA38)-1 -> -0.20877331 | AF38: =F38+ABS(O38) -> 0 | AG38: =F38 -> 0 | AH38: =DATEDIF($C$31,C38,"d") -> 49 | AI38: =(AH$30-AH38)/AH$30 -> 0.9922049 | AJ38: =AI38*AF38 -> 0 | AK38: =$AI38*AG38 -> 0
B39: =IF(C38="","",IF(C$30<C39,"",B38+1)) | C39: =IF(Sheet3!A10="","",Sheet3!A10) -> 37683 | D39: =IF(C39="","",Sheet3!E10) -> 20.49 | E39: =_xlfn.XLOOKUP(WEEKNUM(C39)&YEAR(C39),Sheet4!C:C,Sheet4!B:B,0) -> 0 | F39: =IF(int=Weekly,-$D$5,IF(int=Bi_Weekly,-$D$5,IF(int=Monthly,-$D$5,IF(int=Quarterly,0,IF(int=Yearly,0,IF(int=None,0,0)))))) -> -100 | H39: =H38+F39 -> -250 | J39: =IF(D$24=0,"",ABS($F39*D$24)/D39) -> 4.8804295 | L39: =IF(D39=0,"",L38+J39) -> 10.587947 | N39: =IF(D39=0,"",L39*E39) -> 0 | O39: =-(IF(D39=0,"",N39)) -> 0 | P39: =P38+F39+O39 -> -250 | Q39: =IF(D39=0,"",ABS($O39)/D39) -> 0 | R39: =IF(D39=0,"",Q39+R38) -> 0.016276043 | S39: =IF(D39=0,"",L39+R39) -> 10.604223 | T39: =IF(D39=0,"",D39*J39)+T38 -> 250 | U39: =IF(D39=0,"",L39*D39) -> 216.94702 | V39: =(U39/T39)-1 -> -0.1322119 | W39: =U39-T39 -> -33.052976 | X39: =ABS(O39)+X38 -> 0.46875002 | Y39: =((U39+X39)/T39)-1 -> -0.1303369 | AA39: =(D39*Q39)+(D39*J39)+AA38 -> 250.46875 | AB39: =(L39*D39)+(D39*R39) -> 217.28052 | AC39: =AB39-AA39 -> -33.18823 | AD39: =(AB39/AA39)-1 -> -0.13250447 | AF39: =F39+ABS(O39) -> -100 | AG39: =F39 -> -100 | AH39: =DATEDIF($C$31,C39,"d") -> 56 | AI39: =(AH$30-AH39)/AH$30 -> 0.99109131 | AJ39: =AI39*AF39 -> -99.109131 | AK39: =$AI39*AG39 -> -99.109131
B40: =IF(C39="","",IF(C$30<C40,"",B39+1)) | C40: =IF(Sheet3!A11="","",Sheet3!A11) -> 37690 | D40: =IF(C40="","",Sheet3!E11) -> 20.85 | E40: =_xlfn.XLOOKUP(WEEKNUM(C40)&YEAR(C40),Sheet4!C:C,Sheet4!B:B,0) -> 0 | F40: =IF(int=Weekly,-$D$5,IF(int=Bi_Weekly,0,IF(int=Monthly,0,IF(int=Quarterly,0,IF(int=Yearly,0,IF(int=None,0,0)))))) -> 0 | H40: =H39+F40 -> -250 | J40: =IF(D$24=0,"",ABS($F40*D$24)/D40) -> 0 | L40: =IF(D40=0,"",L39+J40) -> 10.587947 | N40: =IF(D40=0,"",L40*E40) -> 0 | O40: =-(IF(D40=0,"",N40)) -> 0 | P40: =P39+F40+O40 -> -250 | Q40: =IF(D40=0,"",ABS($O40)/D40) -> 0 | R40: =IF(D40=0,"",Q40+R39) -> 0.016276043 | S40: =IF(D40=0,"",L40+R40) -> 10.604223 | T40: =IF(D40=0,"",D40*J40)+T39 -> 250 | U40: =IF(D40=0,"",L40*D40) -> 220.75869 | V40: =(U40/T40)-1 -> -0.11696526 | W40: =U40-T40 -> -29.241315 | X40: =ABS(O40)+X39 -> 0.46875002 | Y40: =((U40+X40)/T40)-1 -> -0.11509026 | AA40: =(D40*Q40)+(D40*J40)+AA39 -> 250.46875 | AB40: =(L40*D40)+(D40*R40) -> 221.09804 | AC40: =AB40-AA40 -> -29.370709 | AD40: =(AB40/AA40)-1 -> -0.11726297 | AF40: =F40+ABS(O40) -> 0 | AG40: =F40 -> 0 | AH40: =DATEDIF($C$31,C40,"d") -> 63 | AI40: =(AH$30-AH40)/AH$30 -> 0.98997773 | AJ40: =AI40*AF40 -> 0 | AK40: =$AI40*AG40 -> 0
B41: =IF(C40="","",IF(C$30<C41,"",B40+1)) | C41: =IF(Sheet3!A12="","",Sheet3!A12) -> 37697 | D41: =IF(C41="","",Sheet3!E12) -> 21.639999 | E41: =_xlfn.XLOOKUP(WEEKNUM(C41)&YEAR(C41),Sheet4!C:C,Sheet4!B:B,0) -> 0 | F41: =IF(int=Weekly,-$D$5,IF(int=Bi_Weekly,-$D$5,IF(int=Monthly,0,IF(int=Quarterly,0,IF(int=Yearly,0,IF(int=None,0,0)))))) -> 0 | H41: =H40+F41 -> -250 | J41: =IF(D$24=0,"",ABS($F41*D$24)/D41) -> 0 | L41: =IF(D41=0,"",L40+J41) -> 10.587947 | N41: =IF(D41=0,"",L41*E41) -> 0 | O41: =-(IF(D41=0,"",N41)) -> 0 | P41: =P40+F41+O41 -> -250 | Q41: =IF(D41=0,"",ABS($O41)/D41) -> 0 | R41: =IF(D41=0,"",Q41+R40) -> 0.016276043 | S41: =IF(D41=0,"",L41+R41) -> 10.604223 | T41: =IF(D41=0,"",D41*J41)+T40 -> 250 | U41: =IF(D41=0,"",L41*D41) -> 229.12315 | V41: =(U41/T41)-1 -> -0.083507391 | W41: =U41-T41 -> -20.876848 | X41: =ABS(O41)+X40 -> 0.46875002 | Y41: =((U41+X41)/T41)-1 -> -0.081632391 | AA41: =(D41*Q41)+(D41*J41)+AA40 -> 250.46875 | AB41: =(L41*D41)+(D41*R41) -> 229.47537 | AC41: =AB41-AA41 -> -20.993384 | AD41: =(AB41/AA41)-1 -> -0.083816381 | AF41: =F41+ABS(O41) -> 0 | AG41: =F41 -> 0 | AH41: =DATEDIF($C$31,C41,"d") -> 70 | AI41: =(AH$30-AH41)/AH$30 -> 0.98886414 | AJ41: =AI41*AF41 -> 0 | AK41: =$AI41*AG41 -> 0
B42: =IF(C41="","",IF(C$30<C42,"",B41+1)) | C42: =IF(Sheet3!A13="","",Sheet3!A13) -> 37704 | D42: =IF(C42="","",Sheet3!E13) -> 20.24 | E42: =_xlfn.XLOOKUP(WEEKNUM(C42)&YEAR(C42),Sheet4!C:C,Sheet4!B:B,0) -> 0 | F42: =IF(int=Weekly,-$D$5,IF(int=Bi_Weekly,0,IF(int=Monthly,0,IF(int=Quarterly,0,IF(int=Yearly,0,IF(int=None,0,0)))))) -> 0 | H42: =H41+F42 -> -250 | J42: =IF(D$24=0,"",ABS($F42*D$24)/D42) -> 0 | L42: =IF(D42=0,"",L41+J42) -> 10.587947 | N42: =IF(D42=0,"",L42*E42) -> 0 | O42: =-(IF(D42=0,"",N42)) -> 0 | P42: =P41+F42+O42 -> -250 | Q42: =IF(D42=0,"",ABS($O42)/D42) -> 0 | R42: =IF(D42=0,"",Q42+R41) -> 0.016276043 | S42: =IF(D42=0,"",L42+R42) -> 10.604223 | T42: =IF(D42=0,"",D42*J42)+T41 -> 250 | U42: =IF(D42=0,"",L42*D42) -> 214.30004 | V42: =(U42/T42)-1 -> -0.14279985 | W42: =U42-T42 -> -35.699962 | X42: =ABS(O42)+X41 -> 0.46875002 | Y42: =((U42+X42)/T42)-1 -> -0.14092485 | AA42: =(D42*Q42)+(D42*J42)+AA41 -> 250.46875 | AB42: =(L42*D42)+(D42*R42) -> 214.62946 | AC42: =AB42-AA42 -> -35.839285 | AD42: =(AB42/AA42)-1 -> -0.14308885 | AF42: =F42+ABS(O42) -> 0 | AG42: =F42 -> 0 | AH42: =DATEDIF($C$31,C42,"d") -> 77 | AI42: =(AH$30-AH42)/AH$30 -> 0.98775056 | AJ42: =AI42*AF42 -> 0 | AK42: =$AI42*AG42 -> 0
B43: =IF(C42="","",IF(C$30<C43,"",B42+1)) | C43: =IF(Sheet3!A14="","",Sheet3!A14) -> 37711 | D43: =IF(C43="","",Sheet3!E14) -> 21.9 | E43: =_xlfn.XLOOKUP(WEEKNUM(C43)&YEAR(C43),Sheet4!C:C,Sheet4!B:B,0) -> 0 | F43: =IF(int=Weekly,-$D$5,IF(int=Bi_Weekly,-$D$5,IF(int=Monthly,-$D$5,IF(int=Quarterly,0,IF(int=Yearly,0,IF(int=None,0,0)))))) -> -100 | H43: =H42+F43 -> -350 | J43: =IF(D$24=0,"",ABS($F43*D$24)/D43) -> 4.56621 | L43: =IF(D43=0,"",L42+J43) -> 15.154157 | N43: =IF(D43=0,"",L43*E43) -> 0 | O43: =-(IF(D43=0,"",N43)) -> 0 | P43: =P42+F43+O43 -> -350 | Q43: =IF(D43=0,"",ABS($O43)/D43) -> 0 | R43: =IF(D43=0,"",Q43+R42) -> 0.016276043 | S43: =IF(D43=0,"",L43+R43) -> 15.170433 | T43: =IF(D43=0,"",D43*J43)+T42 -> 350 | U43: =IF(D43=0,"",L43*D43) -> 331.87603 | V43: =(U43/T43)-1 -> -0.051782774 | W43: =U43-T43 -> -18.123971 | X43: =ABS(O43)+X42 -> 0.46875002 | Y43: =((U43+X43)/T43)-1 -> -0.050443489 | AA43: =(D43*Q43)+(D43*J43)+AA42 -> 350.46875 | AB43: =(L43*D43)+(D43*R43) -> 332.23247 | AC43: =AB43-AA43 -> -18.236276 | AD43: =(AB43/AA43)-1 -> -0.052033957 | AF43: =F43+ABS(O43) -> -100 | AG43: =F43 -> -100 | AH43: =DATEDIF($C$31,C43,"d") -> 84 | AI43: =(AH$30-AH43)/AH$30 -> 0.98663697 | AJ43: =AI43*AF43 -> -98.663697 | AK43: =$AI43*AG43 -> -98.663697
B44: =IF(C43="","",IF(C$30<C44,"",B43+1)) | C44: =IF(Sheet3!A15="","",Sheet3!A15) -> 37718 | D44: =IF(C44="","",Sheet3!E15) -> 20.709999 | E44: =_xlfn.XLOOKUP(WEEKNUM(C44)&YEAR(C44),Sheet4!C:C,Sheet4!B:B,0) -> 0.2825 | F44: =IF(int=Weekly,-$D$5,IF(int=Bi_Weekly,0,IF(int=Monthly,0,IF(int=Quarterly,-$D$5,IF(int=Yearly,0,IF(int=None,0,0)))))) -> 0 | H44: =H43+F44 -> -350 | J44: =IF(D$24=0,"",ABS($F44*D$24)/D44) -> 0 | L44: =IF(D44=0,"",L43+J44) -> 15.154157 | N44: =IF(D44=0,"",L44*E44) -> 4.2810492 | O44: =-(IF(D44=0,"",N44)) -> -4.2810492 | P44: =P43+F44+O44 -> -354.28105 | Q44: =IF(D44=0,"",ABS($O44)/D44) -> 0.20671412 | R44: =IF(D44=0,"",Q44+R43) -> 0.22299016 | S44: =IF(D44=0,"",L44+R44) -> 15.377147 | T44: =IF(D44=0,"",D44*J44)+T43 -> 350 | U44: =IF(D44=0,"",L44*D44) -> 313.84257 | V44: =(U44/T44)-1 -> -0.10330695 | W44: =U44-T44 -> -36.157433 | X44: =ABS(O44)+X43 -> 4.7497992 | Y44: =((U44+X44)/T44)-1 -> -0.089736095 | AA44: =(D44*Q44)+(D44*J44)+AA43 -> 354.7498 | AB44: =(L44*D44)+(D44*R44) -> 318.46069 | AC44: =AB44-AA44 -> -36.289106 | AD44: =(AB44/AA44)-1 -> -0.10229493 | AF44: =F44+ABS(O44) -> 4.2810492 | AG44: =F44 -> 0 | AH44: =DATEDIF($C$31,C44,"d") -> 91 | AI44: =(AH$30-AH44)/AH$30 -> 0.98552339 | AJ44: =AI44*AF44 -> 4.2190741 | AK44: =$AI44*AG44 -> 0
B45: =IF(C44="","",IF(C$30<C45,"",B44+1)) | C45: =IF(Sheet3!A16="","",Sheet3!A16) -> 37725 | D45: =IF(C45="","",Sheet3!E16) -> 20.6 | E45: =_xlfn.XLOOKUP(WEEKNUM(C45)&YEAR(C45),Sheet4!C:C,Sheet4!B:B,0) -> 0 | F45: =IF(int=Weekly,-$D$5,IF(int=Bi_Weekly,-$D$5,IF(int=Monthly,0,IF(int=Quarterly,0,IF(int=Yearly,0,IF(int=None,0,0)))))) -> 0 | H45: =H44+F45 -> -350 | J45: =IF(D$24=0,"",ABS($F45*D$24)/D45) -> 0 | L45: =IF(D45=0,"",L44+J45) -> 15.154157 | N45: =IF(D45=0,"",L45*E45) -> 0 | O45: =-(IF(D45=0,"",N45)) -> 0 | P45: =P44+F45+O45 -> -354.28105 | Q45: =IF(D45=0,"",ABS($O45)/D45) -> 0 | R45: =IF(D45=0,"",Q45+R44) -> 0.22299016 | S45: =IF(D45=0,"",L45+R45) -> 15.377147 | T45: =IF(D45=0,"",D45*J45)+T44 -> 350 | U45: =IF(D45=0,"",L45*D45) -> 312.17563 | V45: =(U45/T45)-1 -> -0.10806964 | W45: =U45-T45 -> -37.824375 | X45: =ABS(O45)+X44 -> 4.7497992 | Y45: =((U45+X45)/T45)-1 -> -0.094498787 | AA45: =(D45*Q45)+(D45*J45)+AA44 -> 354.7498 | AB45: =(L45*D45)+(D45*R45) -> 316.76922 | AC45: =AB45-AA45 -> -37.980576 | AD45: =(AB45/AA45)-1 -> -0.107063 | AF45: =F45+ABS(O45) -> 0 | AG45: =F45 -> 0 | AH45: =DATEDIF($C$31,C45,"d") -> 98 | AI45: =(AH$30-AH45)/AH$30 -> 0.9844098 | AJ45: =AI45*AF45 -> 0 | AK45: =$AI45*AG45 -> 0
B46: =IF(C45="","",IF(C$30<C46,"",B45+1)) | C46: =IF(Sheet3!A17="","",Sheet3!A17) -> 37732 | D46: =IF(C46="","",Sheet3!E17) -> 22.120001 | E46: =_xlfn.XLOOKUP(WEEKNUM(C46)&YEAR(C46),Sheet4!C:C,Sheet4!B:B,0) -> 0 | F46: =IF(int=Weekly,-$D$5,IF(int=Bi_Weekly,0,IF(int=Monthly,0,IF(int=Quarterly,0,IF(int=Yearly,0,IF(int=None,0,0)))))) -> 0 | H46: =H45+F46 -> -350 | J46: =IF(D$24=0,"",ABS($F46*D$24)/D46) -> 0 | L46: =IF(D46=0,"",L45+J46) -> 15.154157 | N46: =IF(D46=0,"",L46*E46) -> 0 | O46: =-(IF(D46=0,"",N46)) -> 0 | P46: =P45+F46+O46 -> -354.28105 | Q46: =IF(D46=0,"",ABS($O46)/D46) -> 0 | R46: =IF(D46=0,"",Q46+R45) -> 0.22299016 | S46: =IF(D46=0,"",L46+R46) -> 15.377147 | T46: =IF(D46=0,"",D46*J46)+T45 -> 350 | U46: =IF(D46=0,"",L46*D46) -> 335.20996 | V46: =(U46/T46)-1 -> -0.042257261 | W46: =U46-T46 -> -14.790041 | X46: =ABS(O46)+X45 -> 4.7497992 | Y46: =((U46+X46)/T46)-1 -> -0.028686406 | AA46: =(D46*Q46)+(D46*J46)+AA45 -> 354.7498 | AB46: =(L46*D46)+(D46*R46) -> 340.1425 | AC46: =AB46-AA46 -> -14.607298 | AD46: =(AB46/AA46)-1 -> -0.041176339 | AF46: =F46+ABS(O46) -> 0 | AG46: =F46 -> 0 | AH46: =DATEDIF($C$31,C46,"d") -> 105 | AI46: =(AH$30-AH46)/AH$30 -> 0.98329621 | AJ46: =AI46*AF46 -> 0 | AK46: =$AI46*AG46 -> 0
B47: =IF(C46="","",IF(C$30<C47,"",B46+1)) | C47: =IF(Sheet3!A18="","",Sheet3!A18) -> 37739 | D47: =IF(C47="","",Sheet3!E18) -> 24.01 | E47: =_xlfn.XLOOKUP(WEEKNUM(C47)&YEAR(C47),Sheet4!C:C,Sheet4!B:B,0) -> 0 | F47: =IF(int=Weekly,-$D$5,IF(int=Bi_Weekly,-$D$5,IF(int=Monthly,-$D$5,IF(int=Quarterly,0,IF(int=Yearly,0,IF(int=None,0,0)))))) -> -100 | H47: =H46+F47 -> -450 | J47: =IF(D$24=0,"",ABS($F47*D$24)/D47) -> 4.1649313 | L47: =IF(D47=0,"",L46+J47) -> 19.319088 | N47: =IF(D47=0,"",L47*E47) -> 0 | O47: =-(IF(D47=0,"",N47)) -> 0 | P47: =P46+F47+O47 -> -454.28105 | Q47: =IF(D47=0,"",ABS($O47)/D47) -> 0 | R47: =IF(D47=0,"",Q47+R46) -> 0.22299016 | S47: =IF(D47=0,"",L47+R47) -> 19.542078 | T47: =IF(D47=0,"",D47*J47)+T46 -> 450 | U47: =IF(D47=0,"",L47*D47) -> 463.8513 | V47: =(U47/T47)-1 -> 0.030780665 | W47: =U47-T47 -> 13.851299 | X47: =ABS(O47)+X46 -> 4.7497992 | Y47: =((U47+X47)/T47)-1 -> 0.041335775 | AA47: =(D47*Q47)+(D47*J47)+AA46 -> 454.7498 | AB47: =(L47*D47)+(D47*R47) -> 469.20529 | AC47: =AB47-AA47 -> 14.455494 | AD47: =(AB47/AA47)-1 -> 0.031787796 | AF47: =F47+ABS(O47) -> -100 | AG47: =F47 -> -100 | AH47: =DATEDIF($C$31,C47,"d") -> 112 | AI47: =(AH$30-AH47)/AH$30 -> 0.98218263 | AJ47: =AI47*AF47 -> -98.218263 | AK47: =$AI47*AG47 -> -98.218263
B48: =IF(C47="","",IF(C$30<C48,"",B47+1)) | C48: =IF(Sheet3!A19="","",Sheet3!A19) -> 37746 | D48: =IF(C48="","",Sheet3!E19) -> 23.67 | E48: =_xlfn.XLOOKUP(WEEKNUM(C48)&YEAR(C48),Sheet4!C:C,Sheet4!B:B,0) -> 0 | F48: =IF(int=Weekly,-$D$5,IF(int=Bi_Weekly,0,IF(int=Monthly,0,IF(int=Quarterly,0,IF(int=Yearly,0,IF(int=None,0,0)))))) -> 0 | H48: =H47+F48 -> -450 | J48: =IF(D$24=0,"",ABS($F48*D$24)/D48) -> 0 | L48: =IF(D48=0,"",L47+J48) -> 19.319088 | N48: =IF(D48=0,"",L48*E48) -> 0 | O48: =-(IF(D48=0,"",N48)) -> 0 | P48: =P47+F48+O48 -> -454.28105 | Q48: =IF(D48=0,"",ABS($O48)/D48) -> 0 | R48: =IF(D48=0,"",Q48+R47) -> 0.22299016 | S48: =IF(D48=0,"",L48+R48) -> 19.542078 | T48: =IF(D48=0,"",D48*J48)+T47 -> 450 | U48: =IF(D48=0,"",L48*D48) -> 457.28281 | V48: =(U48/T48)-1 -> 0.016184021 | W48: =U48-T48 -> 7.2828094 | X48: =ABS(O48)+X47 -> 4.7497992 | Y48: =((U48+X48)/T48)-1 -> 0.02673913 | AA48: =(D48*Q48)+(D48*J48)+AA47 -> 454.7498 | AB48: =(L48*D48)+(D48*R48) -> 462.56099 | AC48: =AB48-AA48 -> 7.8111874 | AD48: =(AB48/AA48)-1 -> 0.01717689 | AF48: =F48+ABS(O48) -> 0 | AG48: =F48 -> 0 | AH48: =DATEDIF($C$31,C48,"d") -> 119 | AI48: =(AH$30-AH48)/AH$30 -> 0.98106904 | AJ48: =AI48*AF48 -> 0 | AK48: =$AI48*AG48 -> 0
B49: =IF(C48="","",IF(C$30<C49,"",B48+1)) | C49: =IF(Sheet3!A20="","",Sheet3!A20) -> 37753 | D49: =IF(C49="","",Sheet3!E20) -> 24.950001 | E49: =_xlfn.XLOOKUP(WEEKNUM(C49)&YEAR(C49),Sheet4!C:C,Sheet4!B:B,0) -> 0 | F49: =IF(int=Weekly,-$D$5,IF(int=Bi_Weekly,-$D$5,IF(int=Monthly,0,IF(int=Quarterly,0,IF(int=Yearly,0,IF(int=None,0,0)))))) -> 0 | H49: =H48+F49 -> -450 | J49: =IF(D$24=0,"",ABS($F49*D$24)/D49) -> 0 | L49: =IF(D49=0,"",L48+J49) -> 19.319088 | N49: =IF(D49=0,"",L49*E49) -> 0 | O49: =-(IF(D49=0,"",N49)) -> 0 | P49: =P48+F49+O49 -> -454.28105 | Q49: =IF(D49=0,"",ABS($O49)/D49) -> 0 | R49: =IF(D49=0,"",Q49+R48) -> 0.22299016 | S49: =IF(D49=0,"",L49+R49) -> 19.542078 | T49: =IF(D49=0,"",D49*J49)+T48 -> 450 | U49: =IF(D49=0,"",L49*D49) -> 482.01126 | V49: =(U49/T49)-1 -> 0.071136136 | W49: =U49-T49 -> 32.011261 | X49: =ABS(O49)+X48 -> 4.7497992 | Y49: =((U49+X49)/T49)-1 -> 0.081691245 | AA49: =(D49*Q49)+(D49*J49)+AA48 -> 454.7498 | AB49: =(L49*D49)+(D49*R49) -> 487.57487 | AC49: =AB49-AA49 -> 32.825067 | AD49: =(AB49/AA49)-1 -> 0.072182697 | AF49: =F49+ABS(O49) -> 0 | AG49: =F49 -> 0 | AH49: =DATEDIF($C$31,C49,"d") -> 126 | AI49: =(AH$30-AH49)/AH$30 -> 0.97995546 | AJ49: =AI49*AF49 -> 0 | AK49: =$AI49*AG49 -> 0
B50: =IF(C49="","",IF(C$30<C50,"",B49+1)) | C50: =IF(Sheet3!A21="","",Sheet3!A21) -> 37760 | D50: =IF(C50="","",Sheet3!E21) -> 25.15 | E50: =_xlfn.XLOOKUP(WEEKNUM(C50)&YEAR(C50),Sheet4!C:C,Sheet4!B:B,0) -> 0 | F50: =IF(int=Weekly,-$D$5,IF(int=Bi_Weekly,0,IF(int=Monthly,0,IF(int=Quarterly,0,IF(int=Yearly,0,IF(int=None,0,0)))))) -> 0 | H50: =H49+F50 -> -450 | J50: =IF(D$24=0,"",ABS($F50*D$24)/D50) -> 0 | L50: =IF(D50=0,"",L49+J50) -> 19.319088 | N50: =IF(D50=0,"",L50*E50) -> 0 | O50: =-(IF(D50=0,"",N50)) -> 0 | P50: =P49+F50+O50 -> -454.28105 | Q50: =IF(D50=0,"",ABS($O50)/D50) -> 0 | R50: =IF(D50=0,"",Q50+R49) -> 0.22299016 | S50: =IF(D50=0,"",L50+R50) -> 19.542078 | T50: =IF(D50=0,"",D50*J50)+T49 -> 450 | U50: =IF(D50=0,"",L50*D50) -> 485.87506 | V50: =(U50/T50)-1 -> 0.079722354 | W50: =U50-T50 -> 35.875059 | X50: =ABS(O50)+X49 -> 4.7497992 | Y50: =((U50+X50)/T50)-1 -> 0.090277464 | AA50: =(D50*Q50)+(D50*J50)+AA49 -> 454.7498 | AB50: =(L50*D50)+(D50*R50) -> 491.48326 | AC50: =AB50-AA50 -> 36.733463 | AD50: =(AB50/AA50)-1 -> 0.080777304 | AF50: =F50+ABS(O50) -> 0 | AG50: =F50 -> 0 | AH50: =DATEDIF($C$31,C50,"d") -> 133 | AI50: =(AH$30-AH50)/AH$30 -> 0.97884187 | AJ50: =AI50*AF50 -> 0 | AK50: =$AI50*AG50 -> 0
B51: =IF(C50="","",IF(C$30<C51,"",B50+1)) | C51: =IF(Sheet3!A22="","",Sheet3!A22) -> 37767 | D51: =IF(C51="","",Sheet3!E22) -> 25.459999 | E51: =_xlfn.XLOOKUP(WEEKNUM(C51)&YEAR(C51),Sheet4!C:C,Sheet4!B:B,0) -> 0 | F51: =IF(int=Weekly,-$D$5,IF(int=Bi_Weekly,-$D$5,IF(int=Monthly,-$D$5,IF(int=Quarterly,0,IF(int=Yearly,0,IF(int=None,0,0)))))) -> -100 | H51: =H50+F51 -> -550 | J51: =IF(D$24=0,"",ABS($F51*D$24)/D51) -> 3.9277299 | L51: =IF(D51=0,"",L50+J51) -> 23.246818 | N51: =IF(D51=0,"",L51*E51) -> 0 | O51: =-(IF(D51=0,"",N51)) -> 0 | P51: =P50+F51+O51 -> -554.28105 | Q51: =IF(D51=0,"",ABS($O51)/D51) -> 0 | R51: =IF(D51=0,"",Q51+R50) -> 0.22299016 | S51: =IF(D51=0,"",L51+R51) -> 23.469808 | T51: =IF(D51=0,"",D51*J51)+T50 -> 550 | U51: =IF(D51=0,"",L51*D51) -> 591.86396 | V51: =(U51/T51)-1 -> 0.076116286 | W51: =U51-T51 -> 41.863957 | X51: =ABS(O51)+X50 -> 4.7497992 | Y51: =((U51+X51)/T51)-1 -> 0.084752285 | AA51: =(D51*Q51)+(D51*J51)+AA50 -> 554.7498 | AB51: =(L51*D51)+(D51*R51) -> 597.54129 | AC51: =AB51-AA51 -> 42.791487 | AD51: =(AB51/AA51)-1 -> 0.077136553 | AF51: =F51+ABS(O51) -> -100 | AG51: =F51 -> -100 | AH51: =DATEDIF($C$31,C51,"d") -> 140 | AI51: =(AH$30-AH51)/AH$30 -> 0.97772829 | AJ51: =AI51*AF51 -> -97.772829 | AK51: =$AI51*AG51 -> -97.772829
B52: =IF(C51="","",IF(C$30<C52,"",B51+1)) | C52: =IF(Sheet3!A23="","",Sheet3!A23) -> 37774 | D52: =IF(C52="","",Sheet3!E23) -> 26.42 | E52: =_xlfn.XLOOKUP(WEEKNUM(C52)&YEAR(C52),Sheet4!C:C,Sheet4!B:B,0) -> 0 | F52: =IF(int=Weekly,-$D$5,IF(int=Bi_Weekly,0,IF(int=Monthly,0,IF(int=Quarterly,0,IF(int=Yearly,0,IF(int=None,0,0)))))) -> 0 | H52: =H51+F52 -> -550 | J52: =IF(D$24=0,"",ABS($F52*D$24)/D52) -> 0 | L52: =IF(D52=0,"",L51+J52) -> 23.246818 | N52: =IF(D52=0,"",L52*E52) -> 0 | O52: =-(IF(D52=0,"",N52)) -> 0 | P52: =P51+F52+O52 -> -554.28105 | Q52: =IF(D52=0,"",ABS($O52)/D52) -> 0 | R52: =IF(D52=0,"",Q52+R51) -> 0.22299016 | S52: =IF(D52=0,"",L52+R52) -> 23.469808 | T52: =IF(D52=0,"",D52*J52)+T51 -> 550 | U52: =IF(D52=0,"",L52*D52) -> 614.18093 | V52: =(U52/T52)-1 -> 0.11669259 | W52: =U52-T52 -> 64.180926 | X52: =ABS(O52)+X51 -> 4.7497992 | Y52: =((U52+X52)/T52)-1 -> 0.12532859 | AA52: =(D52*Q52)+(D52*J52)+AA51 -> 554.7498 | AB52: =(L52*D52)+(D52*R52) -> 620.07233 | AC52: =AB52-AA52 -> 65.322527 | AD52: =(AB52/AA52)-1 -> 0.11775133 | AF52: =F52+ABS(O52) -> 0 | AG52: =F52 -> 0 | AH52: =DATEDIF($C$31,C52,"d") -> 147 | AI52: =(AH$30-AH52)/AH$30 -> 0.9766147 | AJ52: =AI52*AF52 -> 0 | AK52: =$AI52*AG52 -> 0
B53: =IF(C52="","",IF(C$30<C53,"",B52+1)) | C53: =IF(Sheet3!A24="","",Sheet3!A24) -> 37781 | D53: =IF(C53="","",Sheet3!E24) -> 25.32 | E53: =_xlfn.XLOOKUP(WEEKNUM(C53)&YEAR(C53),Sheet4!C:C,Sheet4!B:B,0) -> 0 | F53: =IF(int=Weekly,-$D$5,IF(int=Bi_Weekly,-$D$5,IF(int=Monthly,0,IF(int=Quarterly,0,IF(int=Yearly,0,IF(int=None,0,0)))))) -> 0 | H53: =H52+F53 -> -550 | J53: =IF(D$24=0,"",ABS($F53*D$24)/D53) -> 0 | L53: =IF(D53=0,"",L52+J53) -> 23.246818 | N53: =IF(D53=0,"",L53*E53) -> 0 | O53: =-(IF(D53=0,"",N53)) -> 0 | P53: =P52+F53+O53 -> -554.28105 | Q53: =IF(D53=0,"",ABS($O53)/D53) -> 0 | R53: =IF(D53=0,"",Q53+R52) -> 0.22299016 | S53: =IF(D53=0,"",L53+R53) -> 23.469808 | T53: =IF(D53=0,"",D53*J53)+T52 -> 550 | U53: =IF(D53=0,"",L53*D53) -> 588.60943 | V53: =(U53/T53)-1 -> 0.070198957 | W53: =U53-T53 -> 38.609426 | X53: =ABS(O53)+X52 -> 4.7497992 | Y53: =((U53+X53)/T53)-1 -> 0.078834955 | AA53: =(D53*Q53)+(D53*J53)+AA52 -> 554.7498 | AB53: =(L53*D53)+(D53*R53) -> 594.25554 | AC53: =AB53-AA53 -> 39.505738 | AD53: =(AB53/AA53)-1 -> 0.071213614 | AF53: =F53+ABS(O53) -> 0 | AG53: =F53 -> 0 | AH53: =DATEDIF($C$31,C53,"d") -> 154 | AI53: =(AH$30-AH53)/AH$30 -> 0.97550111 | AJ53: =AI53*AF53 -> 0 | AK53: =$AI53*AG53 -> 0
B54: =IF(C53="","",IF(C$30<C54,"",B53+1)) | C54: =IF(Sheet3!A25="","",Sheet3!A25) -> 37788 | D54: =IF(C54="","",Sheet3!E25) -> 26.1 | E54: =_xlfn.XLOOKUP(WEEKNUM(C54)&YEAR(C54),Sheet4!C:C,Sheet4!B:B,0) -> 0 | F54: =IF(int=Weekly,-$D$5,IF(int=Bi_Weekly,0,IF(int=Monthly,0,IF(int=Quarterly,0,IF(int=Yearly,0,IF(int=None,0,0)))))) -> 0 | H54: =H53+F54 -> -550 | J54: =IF(D$24=0,"",ABS($F54*D$24)/D54) -> 0 | L54: =IF(D54=0,"",L53+J54) -> 23.246818 | N54: =IF(D54=0,"",L54*E54) -> 0 | O54: =-(IF(D54=0,"",N54)) -> 0 | P54: =P53+F54+O54 -> -554.28105 | Q54: =IF(D54=0,"",ABS($O54)/D54) -> 0 | R54: =IF(D54=0,"",Q54+R53) -> 0.22299016 | S54: =IF(D54=0,"",L54+R54) -> 23.469808 | T54: =IF(D54=0,"",D54*J54)+T53 -> 550 | U54: =IF(D54=0,"",L54*D54) -> 606.74194 | V54: =(U54/T54)-1 -> 0.10316717 | W54: =U54-T54 -> 56.741944 | X54: =ABS(O54)+X53 -> 4.7497992 | Y54: =((U54+X54)/T54)-1 -> 0.11180317 | AA54: =(D54*Q54)+(D54*J54)+AA53 -> 554.7498 | AB54: =(L54*D54)+(D54*R54) -> 612.56199 | AC54: =AB54-AA54 -> 57.812188 | AD54: =(AB54/AA54)-1 -> 0.10421309 | AF54: =F54+ABS(O54) -> 0 | AG54: =F54 -> 0 | AH54: =DATEDIF($C$31,C54,"d") -> 161 | AI54: =(AH$30-AH54)/AH$30 -> 0.97438753 | AJ54: =AI54*AF54 -> 0 | AK54: =$AI54*AG54 -> 0
B55: =IF(C54="","",IF(C$30<C55,"",B54+1)) | C55: =IF(Sheet3!A26="","",Sheet3!A26) -> 37795 | D55: =IF(C55="","",Sheet3!E26) -> 25.440001 | E55: =_xlfn.XLOOKUP(WEEKNUM(C55)&YEAR(C55),Sheet4!C:C,Sheet4!B:B,0) -> 0 | F55: =IF(int=Weekly,-$D$5,IF(int=Bi_Weekly,-$D$5,IF(int=Monthly,-$D$5,IF(int=Quarterly,0,IF(int=Yearly,0,IF(int=None,0,0)))))) -> -100 | H55: =H54+F55 -> -650 | J55: =IF(D$24=0,"",ABS($F55*D$24)/D55) -> 3.9308175 | L55: =IF(D55=0,"",L54+J55) -> 27.177635 | N55: =IF(D55=0,"",L55*E55) -> 0 | O55: =-(IF(D55=0,"",N55)) -> 0 | P55: =P54+F55+O55 -> -654.28105 | Q55: =IF(D55=0,"",ABS($O55)/D55) -> 0 | R55: =IF(D55=0,"",Q55+R54) -> 0.22299016 | S55: =IF(D55=0,"",L55+R55) -> 27.400625 | T55: =IF(D55=0,"",D55*J55)+T54 -> 650 | U55: =IF(D55=0,"",L55*D55) -> 691.39907 | V55: =(U55/T55)-1 -> 0.063690873 | W55: =U55-T55 -> 41.399068 | X55: =ABS(O55)+X54 -> 4.7497992 | Y55: =((U55+X55)/T55)-1 -> 0.070998257 | AA55: =(D55*Q55)+(D55*J55)+AA54 -> 654.7498 | AB55: =(L55*D55)+(D55*R55) -> 697.07194 | AC55: =AB55-AA55 -> 42.322138 | AD55: =(AB55/AA55)-1 -> 0.064638643 | AF55: =F55+ABS(O55) -> -100 | AG55: =F55 -> -100 | AH55: =DATEDIF($C$31,C55,"d") -> 168 | AI55: =(AH$30-AH55)/AH$30 -> 0.97327394 | AJ55: =AI55*AF55 -> -97.327394 | AK55: =$AI55*AG55 -> -97.327394
...

Sheet Sheet3
A1: Date | B1: Open | C1: High | D1: Low | E1: Close | G1: Date | H1: Open | I1: High | J1: Low
A2: 37627 | B2: 29.969999 | C2: 31.65 | D2: 28.549999 | E2: 28.799999 | G2: 37627 | H2: 29.969999 | I2: 31.65 | J2: 28.549999
A3: 37634 | B3: 29.25 | C3: 29.99 | D3: 27.059999 | E3: 27.280001 | G3: 37634 | H3: 29.25 | I3: 29.99 | J3: 27.059999
A4: 37641 | B4: 27.549999 | C4: 27.65 | D4: 24.25 | E4: 24.540001 | G4: 37641 | H4: 27.549999 | I4: 27.65 | J4: 24.25
A5: 37648 | B5: 24.5 | C5: 25.379999 | D5: 23.4 | E5: 24.440001 | G5: 37648 | H5: 24.5 | I5: 25.379999 | J5: 23.4
A6: 37655 | B6: 25.049999 | C6: 26.299999 | D6: 24.65 | E6: 25.18 | G6: 37655 | H6: 25.049999 | I6: 26.299999 | J6: 24.65
A7: 37662 | B7: 24.549999 | C7: 25 | D7: 22.15 | E7: 23.35 | G7: 37662 | H7: 24.549999 | I7: 25 | J7: 22.15
A8: 37669 | B8: 23.5 | C8: 23.85 | D8: 20.200001 | E8: 20.73 | G8: 37669 | H8: 23.5 | I8: 23.85 | J8: 20.200001
A9: 37676 | B9: 20.65 | C9: 21.450001 | D9: 20.120001 | E9: 20.799999 | G9: 37676 | H9: 20.65 | I9: 21.450001 | J9: 20.120001
A10: 37683 | B10: 21.200001 | C10: 21.34 | D10: 20.120001 | E10: 20.49 | G10: 37683 | H10: 21.200001 | I10: 21.34 | J10: 20.120001
A11: 37690 | B11: 20.15 | C11: 21.23 | D11: 18.85 | E11: 20.85 | G11: 37690 | H11: 20.15 | I11: 21.23 | J11: 18.85
A12: 37697 | B12: 20.85 | C12: 23.08 | D12: 20.58 | E12: 21.639999 | G12: 37697 | H12: 20.85 | I12: 23.08 | J12: 20.58
A13: 37704 | B13: 21.6 | C13: 21.6 | D13: 20.200001 | E13: 20.24 | G13: 37704 | H13: 21.6 | I13: 21.6 | J13: 20.200001
... A900: 43913 | B900: 27.389999 | C900: 28.299999 | D900: 26.08 | E900: 28.09 | G900: 43913 | H900: 27.389999 | I900: 28.299999 | J900: 26.08

Sheet Sheet4
A1: Date | B1: Dividends
A2: 37629 | B2: 0.27 | C2: =WEEKNUM(A2)&YEAR(A2) -> 22003 | E2: 37629 | F2: 0.27 | G2: =WEEKNUM(E2)&YEAR(E2) -> 22003 | I2: 37629 | J2: 0.27 | K2: =WEEKNUM(I2)&YEAR(I2) -> 22003 | M2: 37629 | N2: 0.27 | O2: =WEEKNUM(M2)&YEAR(M2) -> 22003 | Q2: 37629 | R2: 0.27 | S2: =WEEKNUM(Q2)&YEAR(Q2) -> 22003 | U2: 37629 | V2: 0.27 | W2: =WEEKNUM(U2)&YEAR(U2) -> 22003
A3: 37719 | B3: 0.2825 | C3: =WEEKNUM(A3)&YEAR(A3) -> 152003 | E3: 37719 | F3: 0.2825 | G3: =WEEKNUM(E3)&YEAR(E3) -> 152003 | I3: 37719 | J3: 0.2825 | K3: =WEEKNUM(I3)&YEAR(I3) -> 152003 | M3: 37719 | N3: 0.2825 | O3: =WEEKNUM(M3)&YEAR(M3) -> 152003 | Q3: 37719 | R3: 0.2825 | S3: =WEEKNUM(Q3)&YEAR(Q3) -> 152003 | U3: 37719 | V3: 0.2825 | W3: =WEEKNUM(U3)&YEAR(U3) -> 152003
A4: 37810 | B4: 0.2825 | C4: =WEEKNUM(A4)&YEAR(A4) -> 282003 | E4: 37810 | F4: 0.2825 | G4: =WEEKNUM(E4)&YEAR(E4) -> 282003 | I4: 37810 | J4: 0.2825 | K4: =WEEKNUM(I4)&YEAR(I4) -> 282003 | M4: 37810 | N4: 0.2825 | O4: =WEEKNUM(M4)&YEAR(M4) -> 282003 | Q4: 37810 | R4: 0.2825 | S4: =WEEKNUM(Q4)&YEAR(Q4) -> 282003 | U4: 37810 | V4: 0.2825 | W4: =WEEKNUM(U4)&YEAR(U4) -> 282003
A5: 37902 | B5: 0.2825 | C5: =WEEKNUM(A5)&YEAR(A5) -> 412003 | E5: 37902 | F5: 0.2825 | G5: =WEEKNUM(E5)&YEAR(E5) -> 412003 | I5: 37902 | J5: 0.2825 | K5: =WEEKNUM(I5)&YEAR(I5) -> 412003 | M5: 37902 | N5: 0.2825 | O5: =WEEKNUM(M5)&YEAR(M5) -> 412003 | Q5: 37902 | R5: 0.2825 | S5: =WEEKNUM(Q5)&YEAR(Q5) -> 412003 | U5: 37902 | V5: 0.2825 | W5: =WEEKNUM(U5)&YEAR(U5) -> 412003
A6: 37993 | B6: 0.3125 | C6: =WEEKNUM(A6)&YEAR(A6) -> 22004 | E6: 37993 | F6: 0.3125 | G6: =WEEKNUM(E6)&YEAR(E6) -> 22004 | I6: 37993 | J6: 0.3125 | K6: =WEEKNUM(I6)&YEAR(I6) -> 22004 | M6: 37993 | N6: 0.3125 | O6: =WEEKNUM(M6)&YEAR(M6) -> 22004 | Q6: 37993 | R6: 0.3125 | S6: =WEEKNUM(Q6)&YEAR(Q6) -> 22004 | U6: 37993 | V6: 0.3125 | W6: =WEEKNUM(U6)&YEAR(U6) -> 22004
A7: 38083 | B7: 0.3125 | C7: =WEEKNUM(A7)&YEAR(A7) -> 152004 | E7: 38083 | F7: 0.3125 | G7: =WEEKNUM(E7)&YEAR(E7) -> 152004 | I7: 38083 | J7: 0.3125 | K7: =WEEKNUM(I7)&YEAR(I7) -> 152004 | M7: 38083 | N7: 0.3125 | O7: =WEEKNUM(M7)&YEAR(M7) -> 152004 | Q7: 38083 | R7: 0.3125 | S7: =WEEKNUM(Q7)&YEAR(Q7) -> 152004 | U7: 38083 | V7: 0.3125 | W7: =WEEKNUM(U7)&YEAR(U7) -> 152004
A8: 38175 | B8: 0.3125 | C8: =WEEKNUM(A8)&YEAR(A8) -> 282004 | E8: 38175 | F8: 0.3125 | G8: =WEEKNUM(E8)&YEAR(E8) -> 282004 | I8: 38175 | J8: 0.3125 | K8: =WEEKNUM(I8)&YEAR(I8) -> 282004 | M8: 38175 | N8: 0.3125 | O8: =WEEKNUM(M8)&YEAR(M8) -> 282004 | Q8: 38175 | R8: 0.3125 | S8: =WEEKNUM(Q8)&YEAR(Q8) -> 282004 | U8: 38175 | V8: 0.3125 | W8: =WEEKNUM(U8)&YEAR(U8) -> 282004
A9: 38266 | B9: 0.3125 | C9: =WEEKNUM(A9)&YEAR(A9) -> 412004 | E9: 38266 | F9: 0.3125 | G9: =WEEKNUM(E9)&YEAR(E9) -> 412004 | I9: 38266 | J9: 0.3125 | K9: =WEEKNUM(I9)&YEAR(I9) -> 412004 | M9: 38266 | N9: 0.3125 | O9: =WEEKNUM(M9)&YEAR(M9) -> 412004 | Q9: 38266 | R9: 0.3125 | S9: =WEEKNUM(Q9)&YEAR(Q9) -> 412004 | U9: 38266 | V9: 0.3125 | W9: =WEEKNUM(U9)&YEAR(U9) -> 412004
A10: 38358 | B10: 0.3225 | C10: =WEEKNUM(A10)&YEAR(A10) -> 22005 | E10: 38358 | F10: 0.3225 | G10: =WEEKNUM(E10)&YEAR(E10) -> 22005 | I10: 38358 | J10: 0.3225 | K10: =WEEKNUM(I10)&YEAR(I10) -> 22005 | M10: 38358 | N10: 0.3225 | O10: =WEEKNUM(M10)&YEAR(M10) -> 22005 | Q10: 38358 | R10: 0.3225 | S10: =WEEKNUM(Q10)&YEAR(Q10) -> 22005 | U10: 38358 | V10: 0.3225 | W10: =WEEKNUM(U10)&YEAR(U10) -> 22005
A11: 38448 | B11: 0.3225 | C11: =WEEKNUM(A11)&YEAR(A11) -> 152005 | E11: 38448 | F11: 0.3225 | G11: =WEEKNUM(E11)&YEAR(E11) -> 152005 | I11: 38448 | J11: 0.3225 | K11: =WEEKNUM(I11)&YEAR(I11) -> 152005 | M11: 38448 | N11: 0.3225 | O11: =WEEKNUM(M11)&YEAR(M11) -> 152005 | Q11: 38448 | R11: 0.3225 | S11: =WEEKNUM(Q11)&YEAR(Q11) -> 152005 | U11: 38448 | V11: 0.3225 | W11: =WEEKNUM(U11)&YEAR(U11) -> 152005
A12: 38539 | B12: 0.3225 | C12: =WEEKNUM(A12)&YEAR(A12) -> 282005 | E12: 38539 | F12: 0.3225 | G12: =WEEKNUM(E12)&YEAR(E12) -> 282005 | I12: 38539 | J12: 0.3225 | K12: =WEEKNUM(I12)&YEAR(I12) -> 282005 | M12: 38539 | N12: 0.3225 | O12: =WEEKNUM(M12)&YEAR(M12) -> 282005 | Q12: 38539 | R12: 0.3225 | S12: =WEEKNUM(Q12)&YEAR(Q12) -> 282005 | U12: 38539 | V12: 0.3225 | W12: =WEEKNUM(U12)&YEAR(U12) -> 282005
A13: 38630 | B13: 0.3225 | C13: =WEEKNUM(A13)&YEAR(A13) -> 412005 | E13: 38630 | F13: 0.3225 | G13: =WEEKNUM(E13)&YEAR(E13) -> 412005 | I13: 38630 | J13: 0.3225 | K13: =WEEKNUM(I13)&YEAR(I13) -> 412005 | M13: 38630 | N13: 0.3225 | O13: =WEEKNUM(M13)&YEAR(M13) -> 412005 | Q13: 38630 | R13: 0.3225 | S13: =WEEKNUM(Q13)&YEAR(Q13) -> 412005 | U13: 38630 | V13: 0.3225 | W13: =WEEKNUM(U13)&YEAR(U13) -> 412005
... A70: 43839 | B70: 0.52 | C70: =WEEKNUM(A70)&YEAR(A70) -> 22020 | E70: 43839 | F70: 0.52 | G70: =WEEKNUM(E70)&YEAR(E70) -> 22020 | I70: 43839 | J70: 0.52 | K70: =WEEKNUM(I70)&YEAR(I70) -> 22020 | M70: 43839 | N70: 0.52 | O70: =WEEKNUM(M70)&YEAR(M70) -> 22020 | Q70: 43839 | R70: 0.52 | S70: =WEEKNUM(Q70)&YEAR(Q70) -> 22020 | U70: 43839 | V70: 0.52 | W70: =WEEKNUM(U70)&YEAR(U70) -> 22020

Sheet Sheet2
A1: S&P 500 | D1: NIKKEI | G1: IBEX | J1: 10-Yr Bond | M1: DJI
A2: Total | B2: =B497/B6-1 -> 0.56227233 | D2: Total | E2: =E494/E6-1 -> 0.12570833 | G2: Total | H2: =H497/H6-1 -> -0.3565497 | J2: Total | K2: =K497/K6-1 -> -0.47957447 | M2: Total | N2: =N497/N6-1 -> 0.49922123 | Q2: Weekly
A3: Annual | B3: =((B497/ABS(B6))^(1/(COUNT(B6:B497)/52)))-1 -> 0.048282546 | D3: Annual | E3: =((E494/ABS(E6))^(1/(COUNT(E6:E494)/52)))-1 -> 0.01267153 | G3: Annual | H3: =((H497/ABS(H6))^(1/(COUNT(H6:H497)/52)))-1 -> -0.045531173 | J3: Annual | K3: =((K497/ABS(K6))^(1/(COUNT(K6:K497)/52)))-1 -> -0.066699196 | M3: Annual | N3: =((N497/ABS(N6))^(1/(COUNT(N6:N497)/52)))-1 -> 0.04372824 | Q3: Bi-weekly
Q4: Monthly
A5: Date | B5: Close | C5: Return | D5: Date | E5: Close | F5: Return | G5: Date | H5: Close | I5: Return | J5: Date | K5: Close | L5: Return | M5: Date | N5: Close | O5: Return | Q5: Quarterly
A6: 39293 | B6: 1433.0601 | C6: =(B7-$B$6)/$B$6 -> 0.014360847 | D6: 39293 | E6: 16979.859 | F6: =(E7-$E$6)/$E$6 -> -0.01270738 | G6: 39293 | H6: 14534.3 | I6: =(H7-$H$6)/$H$6 -> -0.0055317019 | J6: 39293 | K6: 4.7 | L6: =(K7-$K$6)/$K$6 -> 0.016170213 | M6: 39293 | N6: 13181.91 | O6: =(N7-$N$6)/$N$6 -> 0.0043718917 | Q6: Yearly
A7: 39300 | B7: 1453.64 | C7: =(B8-$B$6)/$B$6 -> 0.0089876777 | D7: 39300 | E7: 16764.09 | F7: =(E8-$E$6)/$E$6 -> -0.10048256 | G7: 39300 | H7: 14453.9 | I7: =(H8-$H$6)/$H$6 -> -0.020420647 | J7: 39300 | K7: 4.776 | L7: =(K8-$K$6)/$K$6 -> -0.0057446809 | M7: 39300 | N7: 13239.54 | O7: =(N8-$N$6)/$N$6 -> -0.007800848 | Q7: None
A8: 39307 | B8: 1445.9399 | C8: =(B9-$B$6)/$B$6 -> 0.032315419 | D8: 39307 | E8: 15273.68 | F8: =(E9-$E$6)/$E$6 -> -0.043044505 | G8: 39307 | H8: 14237.5 | I8: =(H9-$H$6)/$H$6 -> -0.013753632 | J8: 39307 | K8: 4.673 | L8: =(K9-$K$6)/$K$6 -> -0.014255319 | M8: 39307 | N8: 13079.08 | O8: =(N9-$N$6)/$N$6 -> 0.014941686
A9: 39314 | B9: 1479.37 | C9: =(B10-$B$6)/$B$6 -> 0.028561211 | D9: 39314 | E9: 16248.97 | F9: =(E10-$E$6)/$E$6 -> -0.024191574 | G9: 39314 | H9: 14334.4 | I9: =(H10-$H$6)/$H$6 -> -0.0037497506 | J9: 39314 | K9: 4.633 | L9: =(K10-$K$6)/$K$6 -> -0.034680851 | M9: 39314 | N9: 13378.87 | O9: =(N10-$N$6)/$N$6 -> 0.01333874
A10: 39321 | B10: 1473.99 | C10: =(B11-$B$6)/$B$6 -> 0.014298068 | D10: 39321 | E10: 16569.09 | F10: =(E11-$E$6)/$E$6 -> -0.05051274 | G10: 39321 | H10: 14479.8 | I10: =(H11-$H$6)/$H$6 -> -0.045471706 | J10: 39321 | K10: 4.537 | L10: =(K11-$K$6)/$K$6 -> -0.070638298 | M10: 39321 | N10: 13357.74 | O10: =(N11-$N$6)/$N$6 -> -0.005198812
A11: 39329 | B11: 1453.55 | C11: =(B12-$B$6)/$B$6 -> 0.035720723 | D11: 39328 | E11: 16122.16 | F11: =(E12-$E$6)/$E$6 -> -0.050202975 | G11: 39328 | H11: 13873.4 | I11: =(H12-$H$6)/$H$6 -> -0.046324888 | J11: 39329 | K11: 4.368 | L11: =(K12-$K$6)/$K$6 -> -0.050638298 | M11: 39329 | N11: 13113.38 | O11: =(N12-$N$6)/$N$6 -> 0.019770228
A12: 39335 | B12: 1484.25 | C12: =(B13-$B$6)/$B$6 -> 0.064679732 | D12: 39335 | E12: 16127.42 | F12: =(E13-$E$6)/$E$6 -> -0.039296499 | G12: 39335 | H12: 13861 | I12: =(H13-$H$6)/$H$6 -> -0.0057588048 | J12: 39335 | K12: 4.462 | L12: =(K13-$K$6)/$K$6 -> -0.014468085 | M12: 39335 | N12: 13442.52 | O12: =(N13-$N$6)/$N$6 -> 0.048420924
A13: 39342 | B13: 1525.75 | C13: =(B14-$B$6)/$B$6 -> 0.06537754 | D13: 39343 | E13: 16312.61 | F13: =(E14-$E$6)/$E$6 -> -0.011435308 | G13: 39342 | H13: 14450.6 | I13: =(H14-$H$6)/$H$6 -> 0.0029034901 | J13: 39342 | K13: 4.632 | L13: =(K14-$K$6)/$K$6 -> -0.025744681 | M13: 39342 | N13: 13820.19 | O13: =(N14-$N$6)/$N$6 -> 0.054143877
A14: 39349 | B14: 1526.75 | C14: =(B15-$B$6)/$B$6 -> 0.086897898 | D14: 39350 | E14: 16785.689 | F14: =(E15-$E$6)/$E$6 -> 0.0050165131 | G14: 39349 | H14: 14576.5 | I14: =(H15-$H$6)/$H$6 -> 0.024617615 | J14: 39349 | K14: 4.579 | L14: =(K15-$K$6)/$K$6 -> -0.012765957 | M14: 39349 | N14: 13895.63 | O14: =(N15-$N$6)/$N$6 -> 0.067069158
A15: 39356 | B15: 1557.59 | C15: =(B16-$B$6)/$B$6 -> 0.089835725 | D15: 39356 | E15: 17065.039 | F15: =(E16-$E$6)/$E$6 -> 0.020689838 | G15: 39356 | H15: 14892.1 | I15: =(H16-$H$6)/$H$6 -> 0.050019609 | J15: 39356 | K15: 4.64 | L15: =(K16-$K$6)/$K$6 -> -0.0027659574 | M15: 39356 | N15: 14066.01 | O15: =(N16-$N$6)/$N$6 -> 0.069122753
A16: 39363 | B16: 1561.8 | C16: =(B17-$B$6)/$B$6 -> 0.047150812 | D16: 39364 | E16: 17331.17 | F16: =(E17-$E$6)/$E$6 -> -0.0097462665 | G16: 39363 | H16: 15261.3 | I16: =(H17-$H$6)/$H$6 -> 0.068486298 | J16: 39363 | K16: 4.687 | L16: =(K17-$K$6)/$K$6 -> -0.063617021 | M16: 39363 | N16: 14093.08 | O16: =(N17-$N$6)/$N$6 -> 0.025801221
A17: 39370 | B17: 1500.63 | C17: =(B18-$B$6)/$B$6 -> 0.071329858 | D17: 39370 | E17: 16814.369 | F17: =(E18-$E$6)/$E$6 -> -0.027928884 | G17: 39370 | H17: 15529.7 | I17: =(H18-$H$6)/$H$6 -> 0.073591477 | J17: 39370 | K17: 4.401 | L17: =(K18-$K$6)/$K$6 -> -0.066170213 | M17: 39370 | N17: 13522.02 | O17: =(N18-$N$6)/$N$6 -> 0.047397534
A18: 39377 | B18: 1535.28 | C18: =(B19-$B$6)/$B$6 -> 0.053445049 | D18: 39377 | E18: 16505.631 | F18: =(E19-$E$6)/$E$6 -> -0.027231021 | G18: 39377 | H18: 15603.9 | I18: =(H19-$H$6)/$H$6 -> 0.088714311 | J18: 39377 | K18: 4.389 | L18: =(K19-$K$6)/$K$6 -> -0.087021277 | M18: 39377 | N18: 13806.7 | O18: =(N19-$N$6)/$N$6 -> 0.031345188
A19: 39384 | B19: 1509.65 | C19: =(B20-$B$6)/$B$6 -> 0.014402671 | D19: 39384 | E19: 16517.48 | F19: =(E20-$E$6)/$E$6 -> -0.082240932 | G19: 39384 | H19: 15823.7 | I19: =(H20-$H$6)/$H$6 -> 0.082350055 | J19: 39384 | K19: 4.291 | L19: =(K20-$K$6)/$K$6 -> -0.10106383 | M19: 39384 | N19: 13595.1 | O19: =(N20-$N$6)/$N$6 -> -0.010557645
... A493: 42702 | B493: 2191.95 | C493: =(B494-$B$6)/$B$6 -> 0.57671691 | D493: 42723 | E493: 19427.67 | F493: =(E494-$E$6)/$E$6 -> 0.12570833 | G493: 42702 | H493: 8607.0996 | I493: =(H494-$H$6)/$H$6 -> -0.3691062 | J493: 42702 | K493: 2.39 | L493: =(K494-$K$6)/$K$6 -> -0.47574468 | M493: 42702 | N493: 19170.42 | O493: =(N494-$N$6)/$N$6 -> 0.49878503
A494: 42709 | B494: 2259.53 | C494: =(B495-$B$6)/$B$6 -> 0.57569814 | D494: 42730 | E494: 19114.369 | G494: 42709 | H494: 9169.5996 | I494: =(H495-$H$6)/$H$6 -> -0.35237336 | J494: 42709 | K494: 2.464 | L494: =(K495-$K$6)/$K$6 -> -0.44744681 | M494: 42709 | N494: 19756.85 | O494: =(N495-$N$6)/$N$6 -> 0.50535165
A495: 42716 | B495: 2258.0701 | C495: =(B496-$B$6)/$B$6 -> 0.57968958 | G495: 42716 | H495: 9412.7998 | I495: =(H496-$H$6)/$H$6 -> -0.35547633 | J495: 42716 | K495: 2.597 | L495: =(K496-$K$6)/$K$6 -> -0.45893617 | M495: 42716 | N495: 19843.41 | O495: =(N496-$N$6)/$N$6 -> 0.51220956
A496: 42723 | B496: 2263.79 | C496: =(B497-$B$6)/$B$6 -> 0.56227233 | G496: 42723 | H496: 9367.7002 | I496: =(H497-$H$6)/$H$6 -> -0.3565497 | J496: 42723 | K496: 2.543 | L496: =(K497-$K$6)/$K$6 -> -0.47957447 | M496: 42723 | N496: 19933.811 | O496: =(N497-$N$6)/$N$6 -> 0.49922123
A497: 42731 | B497: 2238.8301 | G497: 42731 | H497: 9352.0996 | J497: 42731 | K497: 2.446 | M497: 42731 | N497: 19762.6
