Workbook
Name Bi_Weekly: 'Dollar Average (Model) (2)'!$B$16
Name Bi_Weekly: Overview!$N$6
Name Bi_Weekly: 'Principal 401k'!$B$7
Name Bi_Weekly: 'Dollar Average (Model)'!$B$16
Name Bi_weekly_2: 'Value Average (Model)'!$B$16
Name div: 'Dollar Average (Model) (2)'!$B$5
Name div: 'Dollar Average (Model)'!$B$5
Name divi: 'Dollar Average (Model) (2)'!$B$5
Name divi: 'Dollar Average (Model)'!$B$5
Name int: 'Dollar Average (Model) (2)'!$B$3
Name int: 'Principal 401k'!$B$3
Name int: 'Dollar Average (Model)'!$B$3
Name inte: 'Dollar Average (Model) (2)'!$B$3
Name inte: 'Principal 401k'!$B$3
Name inte: 'Dollar Average (Model)'!$B$3
Name inter: 'Value Average (Model)'!$B$3
Name Monthly: 'Dollar Average (Model) (2)'!$B$17
Name Monthly: Overview!$N$9
Name Monthly: 'Principal 401k'!$B$8
Name Monthly: 'Dollar Average (Model)'!$B$17
Name Monthly_2: 'Value Average (Model)'!$B$17
Name None: 'Dollar Average (Model) (2)'!$B$20
Name None: 'Principal 401k'!$B$11
Name None: 'Dollar Average (Model)'!$B$20
Name None_2: 'Value Average (Model)'!$B$20
Name Quarterly: 'Dollar Average (Model) (2)'!$B$18
Name Quarterly: Overview!$N$10
Name Quarterly: 'Principal 401k'!$B$9
Name Quarterly: 'Dollar Average (Model)'!$B$18
Name Quarterly_2: 'Value Average (Model)'!$B$18
Name Weekly: 'Dollar Average (Model) (2)'!$B$15
Name Weekly: 'Principal 401k'!$B$6
Name Weekly: 'Dollar Average (Model)'!$B$15
Name Weekly_2: 'Value Average (Model)'!$B$15
Name Yearly: 'Dollar Average (Model) (2)'!$B$19
Name Yearly: 'Principal 401k'!$B$10
Name Yearly: 'Dollar Average (Model)'!$B$19
Name Yearly_2: 'Value Average (Model)'!$B$19

Sheet Overview
A1: Snapshot | E1: Dollar Cost | F1: Value Cost | G1: Dollar Cost | H1: Value Cost | I1: Dollar Cost | J1: Value Cost
B2: Portfolio Funds | C2: Portfolio Weight | D2: Average Price | E2: Average Cost per Share | G2: Discount Rate | I2: Average Shares Purchased | K2: Total Fund IRR | N2: Dollar Cost Average | O2: Value Cost Average
B3: VTI | C3: 0.176 | D3: ='Dollar Average (Model)'!B30 -> 77.831077 | E3: ='Dollar Average (Model)'!M30 -> 77.051582 | F3: ='Value Average (Model)'!M30 -> 75.514545 | G3: ='Dollar Average (Model)'!M29 -> -0.77949533 | H3: ='Value Average (Model)'!M29 -> -2.3165325 | I3: ='Dollar Average (Model)'!M31 -> 0.090531688 | J3: ='Value Average (Model)'!M31 -> 0.036592087 | K3: ='Dollar Average (Model)'!B31 -> 0.61989038 | M3: Initial Investment | N3: =ABS('Dollar Average (Model)'!L35) -> 1000 | O3: =ABS('Value Average (Model)'!L35) -> 5000
B4: VTV | C4: 0.176 | D4: ='Dollar Average (Model)'!C30 -> 63.830793 | E4: ='Dollar Average (Model)'!N30 -> 60.368293 | F4: ='Value Average (Model)'!N30 -> 48.61672 | G4: ='Dollar Average (Model)'!N29 -> -3.4624995 | H4: ='Value Average (Model)'!N29 -> -15.214073 | I4: ='Dollar Average (Model)'!N31 -> 0.11555089 | J4: ='Value Average (Model)'!N31 -> 0.065323765 | K4: ='Dollar Average (Model)'!C31 -> 0.38407747 | M4: Interval | N4: ='Dollar Average (Model)'!B3 -> Quarterly | O4: =inter -> Monthly
B5: VOE | C5: 0.056 | D5: ='Dollar Average (Model)'!D30 -> 63.394837 | E5: ='Dollar Average (Model)'!O30 -> 57.28289 | F5: ='Value Average (Model)'!O30 -> 35.660738 | G5: ='Dollar Average (Model)'!O29 -> -6.1119472 | H5: ='Value Average (Model)'!O29 -> -27.7341 | I5: ='Dollar Average (Model)'!O31 -> 0.038746512 | J5: ='Value Average (Model)'!O31 -> 0.019528415 | K5: ='Dollar Average (Model)'!D31 -> 0.73895158 | M5: Amount Invested | N5: ='Dollar Average (Model)'!B4 -> 500 | O5: ='Value Average (Model)'!B4 -> 100
B6: VBR | C6: 0.049 | D6: ='Dollar Average (Model)'!E30 -> 76.877317 | E6: ='Dollar Average (Model)'!P30 -> 70.419112 | F6: ='Value Average (Model)'!P30 -> 38.843664 | G6: ='Dollar Average (Model)'!P29 -> -6.4582054 | H6: ='Value Average (Model)'!P29 -> -38.033652 | I6: ='Dollar Average (Model)'!P31 -> 0.02757878 | J6: ='Value Average (Model)'!P31 -> 0.013795669 | K6: ='Dollar Average (Model)'!E31 -> 0.79845425
B7: VEA | C7: 0.411 | D7: ='Dollar Average (Model)'!F30 -> 36.556667 | E7: ='Dollar Average (Model)'!Q30 -> 36.365026 | F7: ='Value Average (Model)'!Q30 -> 34.393503 | G7: ='Dollar Average (Model)'!Q29 -> -0.19164065 | H7: ='Value Average (Model)'!Q29 -> -2.1631635 | I7: ='Dollar Average (Model)'!Q31 -> 0.44794782 | J7: ='Value Average (Model)'!Q31 -> 0.38707686 | K7: ='Dollar Average (Model)'!F31 -> -0.22535504 | M7: Total Invested | O7: =ABS('Value Average (Model)'!BJ33) -> 12184.608
B8: VWO | C8: 0.132 | D8: ='Dollar Average (Model)'!G30 -> 40.316646 | E8: ='Dollar Average (Model)'!R30 -> 41.764143 | F8: ='Value Average (Model)'!R30 -> 39.179513 | G8: ='Dollar Average (Model)'!R29 -> 1.4474964 | H8: ='Value Average (Model)'!R29 -> -1.1371332 | I8: ='Dollar Average (Model)'!R31 -> 0.12526792 | J8: ='Value Average (Model)'!R31 -> 0.10927139 | K8: ='Dollar Average (Model)'!G31 -> -0.20665188 | M8: Total Value | O8: ='Value Average (Model)'!BK33 -> 16896.5
M9: Total Return | N9: ='Dollar Average (Model)'!F4 -> 0.264261 | O9: ='Value Average (Model)'!F3 -> 9.4615385
A10: Unweighted Avg | C10: =SUM(C3:C8) -> 1 | D10: =AVERAGE(D3:D8) -> 59.801223 | E10: =AVERAGE(E3:E8) -> 57.208508 | F10: =AVERAGE(F3:F8) -> 45.368114 | G10: =AVERAGE(G3:G8) -> -2.5927153 | H10: =AVERAGE(H3:H8) -> -14.433109 | I10: =AVERAGE(I3:I8) -> 0.14093727 | J10: =AVERAGE(J3:J8) -> 0.1052647 | K10: =AVERAGE(K3:K8) -> 0.35156113 | M10: Capital Gain/Loss | O10: ='Value Average (Model)'!F4 -> 0.38670859
A11: Weighted Avg | C11: =SUM(C3:C8) -> 1 | D11: =AVERAGE(($C$3*D3)+($C$4*D4)+($C$5*D5)+($C$6*D6)+($C$7*D7)+($C$8*D8)) -> 52.596176 | E11: =AVERAGE(($C$3*E3)+($C$4*E4)+($C$5*E5)+($C$6*E6)+($C$7*E7)+($C$8*E8)) -> 51.303169 | F11: =AVERAGE(($C$3*F3)+($C$4*F4)+($C$5*F5)+($C$6*F6)+($C$7*F7)+($C$8*F8)) -> 45.054869 | G11: =AVERAGE(($C$3*G3)+($C$4*G4)+($C$5*G5)+($C$6*G6)+($C$7*G7)+($C$8*G8)) -> -1.293007 | H11: =AVERAGE(($C$3*H3)+($C$4*H4)+($C$5*H5)+($C$6*H6)+($C$7*H7)+($C$8*H8)) -> -7.5413069 | I11: =AVERAGE(($C$3*I3)+($C$4*I4)+($C$5*I5)+($C$6*I6)+($C$7*I7)+($C$8*I8)) -> 0.24043362 | J11: =AVERAGE(($C$3*J3)+($C$4*J4)+($C$5*J5)+($C$6*J6)+($C$7*J7)+($C$8*J8)) -> 0.19321918 | K11: =AVERAGE((C3*K3)+(C4*K4)+(C5*K5)+(C6*K6)+(C7*K7)+(C8*K8)) -> 0.13730492 | M11: Total Shares Bought | N11: =SUM('Dollar Average (Model)'!S33:X33) -> 422.48965 | O11: =SUM('Value Average (Model)'!S33:X33) -> 310.74139
M12: Total Shares Owned | N12: =SUM('Dollar Average (Model)'!S33:X33) -> 422.48965 | O12: =SUM('Value Average (Model)'!Y33:AD33) -> 326.68069

Sheet Dollar Average (Model)
A1: Dollar Cost Average Method (DCA)
A2: Initial Investment | B2: 1000 | E2: % Change | F2: =AVERAGE((B31*B29)+(C31*C29)+(D31*D29)+(E31*E29)+(F31*F29)+(G31*G29)) -> 0.13730492
A3: Interval | B3: Quarterly | E3: Period (Yr.) | F3: =COUNT(A35:A526)/52 -> 9.4615385
A4: Amount Invested | B4: 500 | E4: Return on Principal | F4: =BF33 -> 0.264261
E5: Gain/Loss | F5: =BE33+BD33 -> 5153.0896
E6: Annual Return | F6: =((BE33/ABS(BD33))^(1/F3))-1 -> 0.025092918
F7: Dividends Retained | H7: Dividends Reinvested
E8: Total Return (%) | F8: =BI33 -> 0.41379345 | H8: =BL33 -> 0.43697166
E9: Gain/Loss | F9: =BH33+BD33 -> 8068.9724 | H9: =BK33+BD33 -> 8520.9474
E10: Annual Return | F10: =((BH33/ABS(BD33))^(1/F3))-1 -> 0.037276292 | H10: =((BK33/ABS(BD33))^(1/F3))-1 -> 0.039060576
B15: Weekly
B16: Bi-weekly
B17: Monthly
B18: Quarterly
B19: Yearly
B20: None
A28: Symbol | B28: VTI | C28: VTV | D28: VOE | E28: VBR | F28: VEA | G28: VWO | M28: =B28 -> VTI | N28: =C28 -> VTV | O28: =D28 -> VOE | P28: =E28 -> VBR | Q28: =F28 -> VEA | R28: =G28 -> VWO
A29: Weight | B29: 0.176 | C29: 0.176 | D29: 0.056 | E29: 0.049 | F29: 0.411 | G29: 0.132 | J29: =SUM(B29:G29) -> 1 | L29: Discount Rate | M29: =M30-B30 -> -0.77949533 | N29: =N30-C30 -> -3.4624995 | O29: =O30-D30 -> -6.1119472 | P29: =P30-E30 -> -6.4582054 | Q29: =Q30-F30 -> -0.19164065 | R29: =R30-G30 -> 1.4474964
A30: Average Price | B30: =AVERAGE(BQ35:BQ80,B81:B526) -> 77.831077 | C30: =AVERAGE(C35:C526) -> 63.830793 | D30: =AVERAGE(D35:D526) -> 63.394837 | E30: =AVERAGE(E35:E526) -> 76.877317 | F30: =AVERAGE(F35:F526) -> 36.556667 | G30: =AVERAGE(BR35:BR80,G81:G526) -> 40.316646 | L30: Average Cost per Share | M30: =($M$32*B29)/M31 -> 77.051582 | N30: =($M$32*C29)/N31 -> 60.368293 | O30: =($M$32*D29)/O31 -> 57.28289 | P30: =($M$32*E29)/P31 -> 70.419112 | Q30: =($M$32*F29)/Q31 -> 36.365026 | R30: =($M$32*G29)/R31 -> 41.764143
A31: Return | B31: =(B526-($B$35/2))/($B$35/2) -> 0.61989038 | C31: =(C526-$C$35)/$C$35 -> 0.38407747 | D31: =(D526-$D$35)/$D$35 -> 0.73895158 | E31: =(E526-$E$35)/$E$35 -> 0.79845425 | F31: =(F526-$F$35)/$F$35 -> -0.22535504 | G31: =(G526-($G$35/2))/($G$35/2) -> -0.20665188 | L31: Average Shares Purchased | M31: =AVERAGE(M35:M526) -> 0.090531688 | N31: =AVERAGE(N35:N526) -> 0.11555089 | O31: =AVERAGE(O35:O526) -> 0.038746512 | P31: =AVERAGE(P35:P526) -> 0.02757878 | Q31: =AVERAGE(Q35:Q526) -> 0.44794782 | R31: =AVERAGE(R35:R526) -> 0.12526792
L32: Average Amount Invested | M32: =ABS(AVERAGE($L$35:$L$526)) -> 39.634146
A33: Date | B33: NAV ($) | C33: NAV ($) | D33: NAV ($) | E33: NAV ($) | F33: NAV ($) | G33: NAV ($) | L33: Totals | M33: =SUM(M35:M526) -> 44.54159 | N33: =SUM(N35:N526) -> 56.851036 | O33: =SUM(O35:O526) -> 19.063284 | P33: =SUM(P35:P526) -> 13.56876 | Q33: =SUM(Q35:Q526) -> 220.39033 | R33: =SUM(R35:R526) -> 61.631817 | S33: =S526 -> 47.627887 | T33: =T526 -> 56.851036 | U33: =U526 -> 19.063284 | V33: =V526 -> 13.56876 | W33: =W526 -> 220.39033 | X33: =X526 -> 64.988357 | BC33: =ABS(SUM(BC35:BC526)) -> 2915.8828 | BD33: =BD526 -> -19500 | BE33: =BE526 -> 24653.09 | BF33: =BF526 -> 0.264261 | BG33: =BG526 -> 2915.8828 | BH33: =BH526 -> 27568.972 | BI33: =BI526 -> 0.41379345 | BJ33: =BJ526 -> 3367.8578 | BK33: =BK526 -> 28020.947 | BL33: =BL526 -> 0.43697166 | BO33: =BO526 -> 28020.947
L34: Amount Invested | M34: Shares (#) | S34: Total Shares (#) | Y34: Dividend Payout/Share ($) | AE34: Dividend ($) | AK34: Additional Shares | AQ34: Total Additional Shares | AW34: New Total Shares (#) | BC34: Dividend Payout ($) | BD34: Principal ($) | BE34: Value ($) | BF34: Return (%) | BG34: Dividend Value ($) | BH34: Total Value ($) | BI34: Return (%) | BJ34: Dividend Value ($) | BK34: Total Value ($) | BL34: Return (%) | BN34: Absolute Total Invested | BQ34: VTI | BR34: VWO
A35: 39293 | B35: 142.38001 | C35: 67.199997 | D35: 55.889999 | E35: 67.279999 | F35: 47.169998 | G35: 90.199997 | L35: =-B2 -> -1000 | M35: =(ABS((L35*$B$29)/B35)) -> 1.2361286 | N35: =(ABS((L35*$C$29)/C35)) -> 2.6190477 | O35: =(ABS((L35*$D$29)/D35)) -> 1.0019682 | P35: =(ABS((L35*$E$29)/E35)) -> 0.72829965 | Q35: =(ABS((L35*$F$29)/F35)) -> 8.7131655 | R35: =(ABS((L35*$G$29)/G35)) -> 1.4634147 | S35: =M35 -> 1.2361286 | T35: =N35 -> 2.6190477 | U35: =O35 -> 1.0019682 | V35: =P35 -> 0.72829965 | W35: =Q35 -> 8.7131655 | X35: =R35 -> 1.4634147 | AE35: =(S35*Y35) -> 0 | AF35: =(T35*Z35) -> 0 | AG35: =(U35*AA35) -> 0 | AH35: =(V35*AB35) -> 0 | AI35: =(W35*AC35) -> 0 | AJ35: =(X35*AD35) -> 0 | AK35: =IF(AE35>0,AE35/B35,0) -> 0 | AL35: =IF(AF35>0,AF35/C35,0) -> 0 | AM35: =IF(AG35>0,AG35/D35,0) -> 0 | AN35: =IF(AH35>0,AH35/E35,0) -> 0 | AO35: =IF(AI35>0,AI35/F35,0) -> 0 | AP35: =IF(AJ35>0,AJ35/G35,0) -> 0 | AQ35: =AK35 -> 0 | AR35: =AL35 -> 0 | AS35: =AM35 -> 0 | AT35: =AN35 -> 0 | AU35: =AO35 -> 0 | AV35: =AP35 -> 0 | AW35: =S35+AK35 -> 1.2361286 | AX35: =T35+AL35 -> 2.6190477 | AY35: =U35+AM35 -> 1.0019682 | AZ35: =V35+AN35 -> 0.72829965 | BA35: =W35+AO35 -> 8.7131655 | BB35: =X35+AP35 -> 1.4634147 | BC35: =(AE35+AF35+AG35+AH35+AI35+AJ35) -> 0 | BD35: =L35+BC35 -> -1000 | BE35: =(S35*B35)+(T35*C35)+(U35*D35)+(V35*E35)+(W35*F35)+(X35*G35) -> 1000 | BF35: =(BE35/ABS(BD35))-1 -> 0 | BG35: =BC35 -> 0 | BH35: =BE35+BG35 -> 1000 | BI35: =(BH35/ABS(BD35))-1 -> 0 | BJ35: =(B35*AQ35)+(C35*AR35)+(D35*AS35)+(E35*AT35)+(F35*AU35)+(G35*AV35) -> 0 | BK35: =BE35+BJ35 -> 1000 | BL35: =(BK35/ABS(BD35))-1 -> 0 | BN35: =ABS(BD35) -> 1000 | BO35: =(B35*AW35)+(C35*AX35)+(D35*AY35)+(E35*AZ35)+(F35*BA35)+(G35*BB35) -> 1000 | BQ35: =B35/2 -> 71.190003 | BR35: =G35/2 -> 45.099998
A36: 39300 | B36: 143.72 | C36: 68.300003 | D36: 56.41 | E36: 69.68 | F36: 46.59 | G36: 90.449997 | L36: =IF(int=Weekly,-$B$4,IF(int=Bi_Weekly,0,IF(int=Monthly,0,IF(int=Quarterly,0,IF(int=Yearly,0,IF(int=None,0,0)))))) -> 0 | M36: =(ABS((L36*$B$29)/B36)) -> 0 | N36: =(ABS((L36*$C$29)/C36)) -> 0 | O36: =(ABS((L36*$D$29)/D36)) -> 0 | P36: =(ABS((L36*$E$29)/E36)) -> 0 | Q36: =(ABS((L36*$F$29)/F36)) -> 0 | R36: =(ABS((L36*$G$29)/G36)) -> 0 | S36: =S35+M36 -> 1.2361286 | T36: =T35+N36 -> 2.6190477 | U36: =U35+O36 -> 1.0019682 | V36: =V35+P36 -> 0.72829965 | W36: =W35+Q36 -> 8.7131655 | X36: =X35+R36 -> 1.4634147 | AE36: =(S36*Y36) -> 0 | AF36: =(T36*Z36) -> 0 | AG36: =(U36*AA36) -> 0 | AH36: =(V36*AB36) -> 0 | AI36: =(W36*AC36) -> 0 | AJ36: =(X36*AD36) -> 0 | AK36: =IF(AE36>0,AE36/B36,0) -> 0 | AL36: =IF(AF36>0,AF36/C36,0) -> 0 | AM36: =IF(AG36>0,AG36/D36,0) -> 0 | AN36: =IF(AH36>0,AH36/E36,0) -> 0 | AO36: =IF(AI36>0,AI36/F36,0) -> 0 | AP36: =IF(AJ36>0,AJ36/G36,0) -> 0 | AQ36: =AK36+AQ35+IF(AK36<0,AK36,0) -> 0 | AR36: =AL36+AR35+IF(AL36<0,AL36,0) -> 0 | AS36: =AM36+AS35+IF(AM36<0,AM36,0) -> 0 | AT36: =AN36+AT35+IF(AN36<0,AN36,0) -> 0 | AU36: =AO36+AU35+IF(AO36<0,AO36,0) -> 0 | AV36: =AP36+AV35+IF(AP36<0,AP36,0) -> 0 | AW36: =S36+AQ36 -> 1.2361286 | AX36: =T36+AR36 -> 2.6190477 | AY36: =U36+AS36 -> 1.0019682 | AZ36: =V36+AT36 -> 0.72829965 | BA36: =W36+AU36 -> 8.7131655 | BB36: =X36+AV36 -> 1.4634147 | BC36: =(AE36+AF36+AG36+AH36+AI36+AJ36) -> 0 | BD36: =BD35+L36 -> -1000 | BE36: =(S36*B36)+(T36*C36)+(U36*D36)+(V36*E36)+(W36*F36)+(X36*G36) -> 1002.1186 | BF36: =(BE36/ABS(BD36))-1 -> 0.0021185551 | BG36: =-(BG35+BC36) -> 0 | BH36: =BE36+BG36 -> 1002.1186 | BI36: =(BH36/ABS(BD36))-1 -> 0.0021185551 | BJ36: =(B36*AQ36)+(C36*AR36)+(D36*AS36)+(E36*AT36)+(F36*AU36)+(G36*AV36) -> 0 | BK36: =BE36+BJ36 -> 1002.1186 | BL36: =(BK36/ABS(BD36))-1 -> 0.0021185551 | BN36: =ABS(BD36) -> 1000 | BO36: =(B36*AW36)+(C36*AX36)+(D36*AY36)+(E36*AZ36)+(F36*BA36)+(G36*BB36) -> 1002.1186 | BQ36: =B36/2 -> 71.86 | BR36: =G36/2 -> 45.224998
A37: 39307 | B37: 143.06 | C37: 68.809998 | D37: 55.959999 | E37: 69.309998 | F37: 45.400002 | G37: 85.559998 | L37: =IF(int=Weekly,-$B$4,IF(int=Bi_Weekly,-$B$4,IF(int=Monthly,0,IF(int=Quarterly,0,IF(int=Yearly,0,IF(int=None,0,0)))))) -> 0 | M37: =(ABS((L37*$B$29)/B37)) -> 0 | N37: =(ABS((L37*$C$29)/C37)) -> 0 | O37: =(ABS((L37*$D$29)/D37)) -> 0 | P37: =(ABS((L37*$E$29)/E37)) -> 0 | Q37: =(ABS((L37*$F$29)/F37)) -> 0 | R37: =(ABS((L37*$G$29)/G37)) -> 0 | S37: =S36+M37 -> 1.2361286 | T37: =T36+N37 -> 2.6190477 | U37: =U36+O37 -> 1.0019682 | V37: =V36+P37 -> 0.72829965 | W37: =W36+Q37 -> 8.7131655 | X37: =X36+R37 -> 1.4634147 | AE37: =(S37*Y37) -> 0 | AF37: =(T37*Z37) -> 0 | AG37: =(U37*AA37) -> 0 | AH37: =(V37*AB37) -> 0 | AI37: =(W37*AC37) -> 0 | AJ37: =(X37*AD37) -> 0 | AK37: =IF(AE37>0,AE37/B37,0) -> 0 | AL37: =IF(AF37>0,AF37/C37,0) -> 0 | AM37: =IF(AG37>0,AG37/D37,0) -> 0 | AN37: =IF(AH37>0,AH37/E37,0) -> 0 | AO37: =IF(AI37>0,AI37/F37,0) -> 0 | AP37: =IF(AJ37>0,AJ37/G37,0) -> 0 | AQ37: =AK37+AQ36+IF(AK37<0,AK37,0) -> 0 | AR37: =AL37+AR36+IF(AL37<0,AL37,0) -> 0 | AS37: =AM37+AS36+IF(AM37<0,AM37,0) -> 0 | AT37: =AN37+AT36+IF(AN37<0,AN37,0) -> 0 | AU37: =AO37+AU36+IF(AO37<0,AO37,0) -> 0 | AV37: =AP37+AV36+IF(AP37<0,AP37,0) -> 0 | AW37: =S37+AQ37 -> 1.2361286 | AX37: =T37+AR37 -> 2.6190477 | AY37: =U37+AS37 -> 1.0019682 | AZ37: =V37+AT37 -> 0.72829965 | BA37: =W37+AU37 -> 8.7131655 | BB37: =X37+AV37 -> 1.4634147 | BC37: =(AE37+AF37+AG37+AH37+AI37+AJ37) -> 0 | BD37: =BD36+L37 -> -1000 | BE37: =(S37*B37)+(T37*C37)+(U37*D37)+(V37*E37)+(W37*F37)+(X37*G37) -> 984.3933 | BF37: =(BE37/ABS(BD37))-1 -> -0.015606697 | BG37: =BG36+BC37 -> 0 | BH37: =BE37+BG37 -> 984.3933 | BI37: =(BH37/ABS(BD37))-1 -> -0.015606697 | BJ37: =(B37*AQ37)+(C37*AR37)+(D37*AS37)+(E37*AT37)+(F37*AU37)+(G37*AV37) -> 0 | BK37: =BE37+BJ37 -> 984.3933 | BL37: =(BK37/ABS(BD37))-1 -> -0.015606697 | BN37: =ABS(BD37) -> 1000 | BO37: =(B37*AW37)+(C37*AX37)+(D37*AY37)+(E37*AZ37)+(F37*BA37)+(G37*BB37) -> 984.3933 | BQ37: =B37/2 -> 71.529999 | BR37: =G37/2 -> 42.779999
A38: 39314 | B38: 146.85001 | C38: 70.290001 | D38: 57.66 | E38: 70.949997 | F38: 47.540001 | G38: 91.620003 | L38: =IF(int=Weekly,-$B$4,IF(int=Bi_Weekly,0,IF(int=Monthly,0,IF(int=Quarterly,0,IF(int=Yearly,0,IF(int=None,0,0)))))) -> 0 | M38: =(ABS((L38*$B$29)/B38)) -> 0 | N38: =(ABS((L38*$C$29)/C38)) -> 0 | O38: =(ABS((L38*$D$29)/D38)) -> 0 | P38: =(ABS((L38*$E$29)/E38)) -> 0 | Q38: =(ABS((L38*$F$29)/F38)) -> 0 | R38: =(ABS((L38*$G$29)/G38)) -> 0 | S38: =S37+M38 -> 1.2361286 | T38: =T37+N38 -> 2.6190477 | U38: =U37+O38 -> 1.0019682 | V38: =V37+P38 -> 0.72829965 | W38: =W37+Q38 -> 8.7131655 | X38: =X37+R38 -> 1.4634147 | AE38: =(S38*Y38) -> 0 | AF38: =(T38*Z38) -> 0 | AG38: =(U38*AA38) -> 0 | AH38: =(V38*AB38) -> 0 | AI38: =(W38*AC38) -> 0 | AJ38: =(X38*AD38) -> 0 | AK38: =IF(AE38>0,AE38/B38,0) -> 0 | AL38: =IF(AF38>0,AF38/C38,0) -> 0 | AM38: =IF(AG38>0,AG38/D38,0) -> 0 | AN38: =IF(AH38>0,AH38/E38,0) -> 0 | AO38: =IF(AI38>0,AI38/F38,0) -> 0 | AP38: =IF(AJ38>0,AJ38/G38,0) -> 0 | AQ38: =AK38+AQ37+IF(AK38<0,AK38,0) -> 0 | AR38: =AL38+AR37+IF(AL38<0,AL38,0) -> 0 | AS38: =AM38+AS37+IF(AM38<0,AM38,0) -> 0 | AT38: =AN38+AT37+IF(AN38<0,AN38,0) -> 0 | AU38: =AO38+AU37+IF(AO38<0,AO38,0) -> 0 | AV38: =AP38+AV37+IF(AP38<0,AP38,0) -> 0 | AW38: =S38+AQ38 -> 1.2361286 | AX38: =T38+AR38 -> 2.6190477 | AY38: =U38+AS38 -> 1.0019682 | AZ38: =V38+AT38 -> 0.72829965 | BA38: =W38+AU38 -> 8.7131655 | BB38: =X38+AV38 -> 1.4634147 | BC38: =(AE38+AF38+AG38+AH38+AI38+AJ38) -> 0 | BD38: =BD37+L38 -> -1000 | BE38: =(S38*B38)+(T38*C38)+(U38*D38)+(V38*E38)+(W38*F38)+(X38*G38) -> 1023.3667 | BF38: =(BE38/ABS(BD38))-1 -> 0.023366662 | BG38: =BG37+BC38 -> 0 | BH38: =BE38+BG38 -> 1023.3667 | BI38: =(BH38/ABS(BD38))-1 -> 0.023366662 | BJ38: =(B38*AQ38)+(C38*AR38)+(D38*AS38)+(E38*AT38)+(F38*AU38)+(G38*AV38) -> 0 | BK38: =BE38+BJ38 -> 1023.3667 | BL38: =(BK38/ABS(BD38))-1 -> 0.023366662 | BN38: =ABS(BD38) -> 1000 | BO38: =(B38*AW38)+(C38*AX38)+(D38*AY38)+(E38*AZ38)+(F38*BA38)+(G38*BB38) -> 1023.3667 | BQ38: =B38/2 -> 73.425003 | BR38: =G38/2 -> 45.810001
A39: 39321 | B39: 146.22 | C39: 69.5 | D39: 57.259998 | E39: 70.220001 | F39: 47.860001 | G39: 94.489998 | L39: =IF(int=Weekly,-$B$4,IF(int=Bi_Weekly,-$B$4,IF(int=Monthly,-$B$4,IF(int=Quarterly,0,IF(int=Yearly,0,IF(int=None,0,0)))))) -> 0 | M39: =(ABS((L39*$B$29)/B39)) -> 0 | N39: =(ABS((L39*$C$29)/C39)) -> 0 | O39: =(ABS((L39*$D$29)/D39)) -> 0 | P39: =(ABS((L39*$E$29)/E39)) -> 0 | Q39: =(ABS((L39*$F$29)/F39)) -> 0 | R39: =(ABS((L39*$G$29)/G39)) -> 0 | S39: =S38+M39 -> 1.2361286 | T39: =T38+N39 -> 2.6190477 | U39: =U38+O39 -> 1.0019682 | V39: =V38+P39 -> 0.72829965 | W39: =W38+Q39 -> 8.7131655 | X39: =X38+R39 -> 1.4634147 | AE39: =(S39*Y39) -> 0 | AF39: =(T39*Z39) -> 0 | AG39: =(U39*AA39) -> 0 | AH39: =(V39*AB39) -> 0 | AI39: =(W39*AC39) -> 0 | AJ39: =(X39*AD39) -> 0 | AK39: =IF(AE39>0,AE39/B39,0) -> 0 | AL39: =IF(AF39>0,AF39/C39,0) -> 0 | AM39: =IF(AG39>0,AG39/D39,0) -> 0 | AN39: =IF(AH39>0,AH39/E39,0) -> 0 | AO39: =IF(AI39>0,AI39/F39,0) -> 0 | AP39: =IF(AJ39>0,AJ39/G39,0) -> 0 | AQ39: =AK39+AQ38+IF(AK39<0,AK39,0) -> 0 | AR39: =AL39+AR38+IF(AL39<0,AL39,0) -> 0 | AS39: =AM39+AS38+IF(AM39<0,AM39,0) -> 0 | AT39: =AN39+AT38+IF(AN39<0,AN39,0) -> 0 | AU39: =AO39+AU38+IF(AO39<0,AO39,0) -> 0 | AV39: =AP39+AV38+IF(AP39<0,AP39,0) -> 0 | AW39: =S39+AQ39 -> 1.2361286 | AX39: =T39+AR39 -> 2.6190477 | AY39: =U39+AS39 -> 1.0019682 | AZ39: =V39+AT39 -> 0.72829965 | BA39: =W39+AU39 -> 8.7131655 | BB39: =X39+AV39 -> 1.4634147 | BC39: =(AE39+AF39+AG39+AH39+AI39+AJ39) -> 0 | BD39: =BD38+L39 -> -1000 | BE39: =(S39*B39)+(T39*C39)+(U39*D39)+(V39*E39)+(W39*F39)+(X39*G39) -> 1026.5746 | BF39: =(BE39/ABS(BD39))-1 -> 0.026574605 | BG39: =BG38+BC39 -> 0 | BH39: =BE39+BG39 -> 1026.5746 | BI39: =(BH39/ABS(BD39))-1 -> 0.026574605 | BJ39: =(B39*AQ39)+(C39*AR39)+(D39*AS39)+(E39*AT39)+(F39*AU39)+(G39*AV39) -> 0 | BK39: =BE39+BJ39 -> 1026.5746 | BL39: =(BK39/ABS(BD39))-1 -> 0.026574605 | BN39: =ABS(BD39) -> 1000 | BO39: =(B39*AW39)+(C39*AX39)+(D39*AY39)+(E39*AZ39)+(F39*BA39)+(G39*BB39) -> 1026.5746 | BQ39: =B39/2 -> 73.11 | BR39: =G39/2 -> 47.244999
A40: 39329 | B40: 144.92999 | C40: 68.589996 | D40: 56.330002 | E40: 68.779999 | F40: 46.880001 | G40: 93.110001 | L40: =IF(int=Weekly,-$B$4,IF(int=Bi_Weekly,0,IF(int=Monthly,0,IF(int=Quarterly,0,IF(int=Yearly,0,IF(int=None,0,0)))))) -> 0 | M40: =(ABS((L40*$B$29)/B40)) -> 0 | N40: =(ABS((L40*$C$29)/C40)) -> 0 | O40: =(ABS((L40*$D$29)/D40)) -> 0 | P40: =(ABS((L40*$E$29)/E40)) -> 0 | Q40: =(ABS((L40*$F$29)/F40)) -> 0 | R40: =(ABS((L40*$G$29)/G40)) -> 0 | S40: =S39+M40 -> 1.2361286 | T40: =T39+N40 -> 2.6190477 | U40: =U39+O40 -> 1.0019682 | V40: =V39+P40 -> 0.72829965 | W40: =W39+Q40 -> 8.7131655 | X40: =X39+R40 -> 1.4634147 | AE40: =(S40*Y40) -> 0 | AF40: =(T40*Z40) -> 0 | AG40: =(U40*AA40) -> 0 | AH40: =(V40*AB40) -> 0 | AI40: =(W40*AC40) -> 0 | AJ40: =(X40*AD40) -> 0 | AK40: =IF(AE40>0,AE40/B40,0) -> 0 | AL40: =IF(AF40>0,AF40/C40,0) -> 0 | AM40: =IF(AG40>0,AG40/D40,0) -> 0 | AN40: =IF(AH40>0,AH40/E40,0) -> 0 | AO40: =IF(AI40>0,AI40/F40,0) -> 0 | AP40: =IF(AJ40>0,AJ40/G40,0) -> 0 | AQ40: =AK40+AQ39+IF(AK40<0,AK40,0) -> 0 | AR40: =AL40+AR39+IF(AL40<0,AL40,0) -> 0 | AS40: =AM40+AS39+IF(AM40<0,AM40,0) -> 0 | AT40: =AN40+AT39+IF(AN40<0,AN40,0) -> 0 | AU40: =AO40+AU39+IF(AO40<0,AO40,0) -> 0 | AV40: =AP40+AV39+IF(AP40<0,AP40,0) -> 0 | AW40: =S40+AQ40 -> 1.2361286 | AX40: =T40+AR40 -> 2.6190477 | AY40: =U40+AS40 -> 1.0019682 | AZ40: =V40+AT40 -> 0.72829965 | BA40: =W40+AU40 -> 8.7131655 | BB40: =X40+AV40 -> 1.4634147 | BC40: =(AE40+AF40+AG40+AH40+AI40+AJ40) -> 0 | BD40: =BD39+L40 -> -1000 | BE40: =(S40*B40)+(T40*C40)+(U40*D40)+(V40*E40)+(W40*F40)+(X40*G40) -> 1010.0577 | BF40: =(BE40/ABS(BD40))-1 -> 0.010057656 | BG40: =BG39+BC40 -> 0 | BH40: =BE40+BG40 -> 1010.0577 | BI40: =(BH40/ABS(BD40))-1 -> 0.010057656 | BJ40: =(B40*AQ40)+(C40*AR40)+(D40*AS40)+(E40*AT40)+(F40*AU40)+(G40*AV40) -> 0 | BK40: =BE40+BJ40 -> 1010.0577 | BL40: =(BK40/ABS(BD40))-1 -> 0.010057656 | BN40: =ABS(BD40) -> 1000 | BO40: =(B40*AW40)+(C40*AX40)+(D40*AY40)+(E40*AZ40)+(F40*BA40)+(G40*BB40) -> 1010.0577 | BQ40: =B40/2 -> 72.464996 | BR40: =G40/2 -> 46.555
A41: 39335 | B41: 147.38001 | C41: 70.199997 | D41: 56.91 | E41: 69.300003 | F41: 47.529999 | G41: 95.919998 | L41: =IF(int=Weekly,-$B$4,IF(int=Bi_Weekly,-$B$4,IF(int=Monthly,0,IF(int=Quarterly,0,IF(int=Yearly,0,IF(int=None,0,0)))))) -> 0 | M41: =(ABS((L41*$B$29)/B41)) -> 0 | N41: =(ABS((L41*$C$29)/C41)) -> 0 | O41: =(ABS((L41*$D$29)/D41)) -> 0 | P41: =(ABS((L41*$E$29)/E41)) -> 0 | Q41: =(ABS((L41*$F$29)/F41)) -> 0 | R41: =(ABS((L41*$G$29)/G41)) -> 0 | S41: =S40+M41 -> 1.2361286 | T41: =T40+N41 -> 2.6190477 | U41: =U40+O41 -> 1.0019682 | V41: =V40+P41 -> 0.72829965 | W41: =W40+Q41 -> 8.7131655 | X41: =X40+R41 -> 1.4634147 | AE41: =(S41*Y41) -> 0 | AF41: =(T41*Z41) -> 0 | AG41: =(U41*AA41) -> 0 | AH41: =(V41*AB41) -> 0 | AI41: =(W41*AC41) -> 0 | AJ41: =(X41*AD41) -> 0 | AK41: =IF(AE41>0,AE41/B41,0) -> 0 | AL41: =IF(AF41>0,AF41/C41,0) -> 0 | AM41: =IF(AG41>0,AG41/D41,0) -> 0 | AN41: =IF(AH41>0,AH41/E41,0) -> 0 | AO41: =IF(AI41>0,AI41/F41,0) -> 0 | AP41: =IF(AJ41>0,AJ41/G41,0) -> 0 | AQ41: =AK41+AQ40+IF(AK41<0,AK41,0) -> 0 | AR41: =AL41+AR40+IF(AL41<0,AL41,0) -> 0 | AS41: =AM41+AS40+IF(AM41<0,AM41,0) -> 0 | AT41: =AN41+AT40+IF(AN41<0,AN41,0) -> 0 | AU41: =AO41+AU40+IF(AO41<0,AO41,0) -> 0 | AV41: =AP41+AV40+IF(AP41<0,AP41,0) -> 0 | AW41: =S41+AQ41 -> 1.2361286 | AX41: =T41+AR41 -> 2.6190477 | AY41: =U41+AS41 -> 1.0019682 | AZ41: =V41+AT41 -> 0.72829965 | BA41: =W41+AU41 -> 8.7131655 | BB41: =X41+AV41 -> 1.4634147 | BC41: =(AE41+AF41+AG41+AH41+AI41+AJ41) -> 0 | BD41: =BD40+L41 -> -1000 | BE41: =(S41*B41)+(T41*C41)+(U41*D41)+(V41*E41)+(W41*F41)+(X41*G41) -> 1028.0384 | BF41: =(BE41/ABS(BD41))-1 -> 0.028038445 | BG41: =BG40+BC41 -> 0 | BH41: =BE41+BG41 -> 1028.0384 | BI41: =(BH41/ABS(BD41))-1 -> 0.028038445 | BJ41: =(B41*AQ41)+(C41*AR41)+(D41*AS41)+(E41*AT41)+(F41*AU41)+(G41*AV41) -> 0 | BK41: =BE41+BJ41 -> 1028.0384 | BL41: =(BK41/ABS(BD41))-1 -> 0.028038445 | BN41: =ABS(BD41) -> 1000 | BO41: =(B41*AW41)+(C41*AX41)+(D41*AY41)+(E41*AZ41)+(F41*BA41)+(G41*BB41) -> 1028.0384 | BQ41: =B41/2 -> 73.690003 | BR41: =G41/2 -> 47.959999
A42: 39342 | B42: 151.22 | C42: 72.18 | D42: 58.23 | E42: 71.68 | F42: 49.110001 | G42: 100.75 | L42: =IF(int=Weekly,-$B$4,IF(int=Bi_Weekly,0,IF(int=Monthly,0,IF(int=Quarterly,0,IF(int=Yearly,0,IF(int=None,0,0)))))) -> 0 | M42: =(ABS((L42*$B$29)/B42)) -> 0 | N42: =(ABS((L42*$C$29)/C42)) -> 0 | O42: =(ABS((L42*$D$29)/D42)) -> 0 | P42: =(ABS((L42*$E$29)/E42)) -> 0 | Q42: =(ABS((L42*$F$29)/F42)) -> 0 | R42: =(ABS((L42*$G$29)/G42)) -> 0 | S42: =S41+M42 -> 1.2361286 | T42: =T41+N42 -> 2.6190477 | U42: =U41+O42 -> 1.0019682 | V42: =V41+P42 -> 0.72829965 | W42: =W41+Q42 -> 8.7131655 | X42: =X41+R42 -> 1.4634147 | AE42: =(S42*Y42) -> 0 | AF42: =(T42*Z42) -> 0 | AG42: =(U42*AA42) -> 0 | AH42: =(V42*AB42) -> 0 | AI42: =(W42*AC42) -> 0 | AJ42: =(X42*AD42) -> 0 | AK42: =IF(AE42>0,AE42/B42,0) -> 0 | AL42: =IF(AF42>0,AF42/C42,0) -> 0 | AM42: =IF(AG42>0,AG42/D42,0) -> 0 | AN42: =IF(AH42>0,AH42/E42,0) -> 0 | AO42: =IF(AI42>0,AI42/F42,0) -> 0 | AP42: =IF(AJ42>0,AJ42/G42,0) -> 0 | AQ42: =AK42+AQ41+IF(AK42<0,AK42,0) -> 0 | AR42: =AL42+AR41+IF(AL42<0,AL42,0) -> 0 | AS42: =AM42+AS41+IF(AM42<0,AM42,0) -> 0 | AT42: =AN42+AT41+IF(AN42<0,AN42,0) -> 0 | AU42: =AO42+AU41+IF(AO42<0,AO42,0) -> 0 | AV42: =AP42+AV41+IF(AP42<0,AP42,0) -> 0 | AW42: =S42+AQ42 -> 1.2361286 | AX42: =T42+AR42 -> 2.6190477 | AY42: =U42+AS42 -> 1.0019682 | AZ42: =V42+AT42 -> 0.72829965 | BA42: =W42+AU42 -> 8.7131655 | BB42: =X42+AV42 -> 1.4634147 | BC42: =(AE42+AF42+AG42+AH42+AI42+AJ42) -> 0 | BD42: =BD41+L42 -> -1000 | BE42: =(S42*B42)+(T42*C42)+(U42*D42)+(V42*E42)+(W42*F42)+(X42*G42) -> 1061.862 | BF42: =(BE42/ABS(BD42))-1 -> 0.06186196 | BG42: =BG41+BC42 -> 0 | BH42: =BE42+BG42 -> 1061.862 | BI42: =(BH42/ABS(BD42))-1 -> 0.06186196 | BJ42: =(B42*AQ42)+(C42*AR42)+(D42*AS42)+(E42*AT42)+(F42*AU42)+(G42*AV42) -> 0 | BK42: =BE42+BJ42 -> 1061.862 | BL42: =(BK42/ABS(BD42))-1 -> 0.06186196 | BN42: =ABS(BD42) -> 1000 | BO42: =(B42*AW42)+(C42*AX42)+(D42*AY42)+(E42*AZ42)+(F42*BA42)+(G42*BB42) -> 1061.862 | BQ42: =B42/2 -> 75.61 | BR42: =G42/2 -> 50.375
A43: 39349 | B43: 151.2 | C43: 71.510002 | D43: 58.369999 | E43: 70.830002 | F43: 50.139999 | G43: 103.78 | L43: =IF(int=Weekly,-$B$4,IF(int=Bi_Weekly,-$B$4,IF(int=Monthly,-$B$4,IF(int=Quarterly,0,IF(int=Yearly,0,IF(int=None,0,0)))))) -> 0 | M43: =(ABS((L43*$B$29)/B43)) -> 0 | N43: =(ABS((L43*$C$29)/C43)) -> 0 | O43: =(ABS((L43*$D$29)/D43)) -> 0 | P43: =(ABS((L43*$E$29)/E43)) -> 0 | Q43: =(ABS((L43*$F$29)/F43)) -> 0 | R43: =(ABS((L43*$G$29)/G43)) -> 0 | S43: =S42+M43 -> 1.2361286 | T43: =T42+N43 -> 2.6190477 | U43: =U42+O43 -> 1.0019682 | V43: =V42+P43 -> 0.72829965 | W43: =W42+Q43 -> 8.7131655 | X43: =X42+R43 -> 1.4634147 | Y43: 0.321 | Z43: 0.46 | AE43: =(S43*Y43) -> 0.39679729 | AF43: =(T43*Z43) -> 1.204762 | AG43: =(U43*AA43) -> 0 | AH43: =(V43*AB43) -> 0 | AI43: =(W43*AC43) -> 0 | AJ43: =(X43*AD43) -> 0 | AK43: =IF(AE43>0,AE43/B43,0) -> 0.0026243207 | AL43: =IF(AF43>0,AF43/C43,0) -> 0.016847461 | AM43: =IF(AG43>0,AG43/D43,0) -> 0 | AN43: =IF(AH43>0,AH43/E43,0) -> 0 | AO43: =IF(AI43>0,AI43/F43,0) -> 0 | AP43: =IF(AJ43>0,AJ43/G43,0) -> 0 | AQ43: =AK43+AQ42+IF(AK43<0,AK43,0) -> 0.0026243207 | AR43: =AL43+AR42+IF(AL43<0,AL43,0) -> 0.016847461 | AS43: =AM43+AS42+IF(AM43<0,AM43,0) -> 0 | AT43: =AN43+AT42+IF(AN43<0,AN43,0) -> 0 | AU43: =AO43+AU42+IF(AO43<0,AO43,0) -> 0 | AV43: =AP43+AV42+IF(AP43<0,AP43,0) -> 0 | AW43: =S43+AQ43 -> 1.2387529 | AX43: =T43+AR43 -> 2.6358952 | AY43: =U43+AS43 -> 1.0019682 | AZ43: =V43+AT43 -> 0.72829965 | BA43: =W43+AU43 -> 8.7131655 | BB43: =X43+AV43 -> 1.4634147 | BC43: =(AE43+AF43+AG43+AH43+AI43+AJ43) -> 1.6015592 | BD43: =BD42+L43 -> -1000 | BE43: =(S43*B43)+(T43*C43)+(U43*D43)+(V43*E43)+(W43*F43)+(X43*G43) -> 1073.0124 | BF43: =(BE43/ABS(BD43))-1 -> 0.073012385 | BG43: =BG42+BC43 -> 1.6015592 | BH43: =BE43+BG43 -> 1074.6139 | BI43: =(BH43/ABS(BD43))-1 -> 0.074613944 | BJ43: =(B43*AQ43)+(C43*AR43)+(D43*AS43)+(E43*AT43)+(F43*AU43)+(G43*AV43) -> 1.6015592 | BK43: =BE43+BJ43 -> 1074.6139 | BL43: =(BK43/ABS(BD43))-1 -> 0.074613944 | BN43: =ABS(BD43) -> 1000 | BO43: =(B43*AW43)+(C43*AX43)+(D43*AY43)+(E43*AZ43)+(F43*BA43)+(G43*BB43) -> 1074.6139 | BQ43: =B43/2 -> 75.599998 | BR43: =G43/2 -> 51.89
A44: 39356 | B44: 154.61 | C44: 73.120003 | D44: 60.119999 | E44: 73.699997 | F44: 51.130001 | G44: 109.6 | L44: =IF(int=Weekly,-$B$4,IF(int=Bi_Weekly,0,IF(int=Monthly,0,IF(int=Quarterly,0,IF(int=Yearly,0,IF(int=None,0,0)))))) -> 0 | M44: =(ABS((L44*$B$29)/B44)) -> 0 | N44: =(ABS((L44*$C$29)/C44)) -> 0 | O44: =(ABS((L44*$D$29)/D44)) -> 0 | P44: =(ABS((L44*$E$29)/E44)) -> 0 | Q44: =(ABS((L44*$F$29)/F44)) -> 0 | R44: =(ABS((L44*$G$29)/G44)) -> 0 | S44: =S43+M44 -> 1.2361286 | T44: =T43+N44 -> 2.6190477 | U44: =U43+O44 -> 1.0019682 | V44: =V43+P44 -> 0.72829965 | W44: =W43+Q44 -> 8.7131655 | X44: =X43+R44 -> 1.4634147 | AE44: =(S44*Y44) -> 0 | AF44: =(T44*Z44) -> 0 | AG44: =(U44*AA44) -> 0 | AH44: =(V44*AB44) -> 0 | AI44: =(W44*AC44) -> 0 | AJ44: =(X44*AD44) -> 0 | AK44: =IF(AE44>0,AE44/B44,0) -> 0 | AL44: =IF(AF44>0,AF44/C44,0) -> 0 | AM44: =IF(AG44>0,AG44/D44,0) -> 0 | AN44: =IF(AH44>0,AH44/E44,0) -> 0 | AO44: =IF(AI44>0,AI44/F44,0) -> 0 | AP44: =IF(AJ44>0,AJ44/G44,0) -> 0 | AQ44: =AK44+AQ43+IF(AK44<0,AK44,0) -> 0.0026243207 | AR44: =AL44+AR43+IF(AL44<0,AL44,0) -> 0.016847461 | AS44: =AM44+AS43+IF(AM44<0,AM44,0) -> 0 | AT44: =AN44+AT43+IF(AN44<0,AN44,0) -> 0 | AU44: =AO44+AU43+IF(AO44<0,AO44,0) -> 0 | AV44: =AP44+AV43+IF(AP44<0,AP44,0) -> 0 | AW44: =S44+AQ44 -> 1.2387529 | AX44: =T44+AR44 -> 2.6358952 | AY44: =U44+AS44 -> 1.0019682 | AZ44: =V44+AT44 -> 0.72829965 | BA44: =W44+AU44 -> 8.7131655 | BB44: =X44+AV44 -> 1.4634147 | BC44: =(AE44+AF44+AG44+AH44+AI44+AJ44) -> 0 | BD44: =BD43+L44 -> -1000 | BE44: =(S44*B44)+(T44*C44)+(U44*D44)+(V44*E44)+(W44*F44)+(X44*G44) -> 1102.431 | BF44: =(BE44/ABS(BD44))-1 -> 0.10243104 | BG44: =BG43+BC44 -> 1.6015592 | BH44: =BE44+BG44 -> 1104.0326 | BI44: =(BH44/ABS(BD44))-1 -> 0.1040326 | BJ44: =(B44*AQ44)+(C44*AR44)+(D44*AS44)+(E44*AT44)+(F44*AU44)+(G44*AV44) -> 1.6376326 | BK44: =BE44+BJ44 -> 1104.0687 | BL44: =(BK44/ABS(BD44))-1 -> 0.10406867 | BN44: =ABS(BD44) -> 1000 | BO44: =(B44*AW44)+(C44*AX44)+(D44*AY44)+(E44*AZ44)+(F44*BA44)+(G44*BB44) -> 1104.0687 | BQ44: =B44/2 -> 77.305001 | BR44: =G44/2 -> 54.799999
A45: 39363 | B45: 155.08 | C45: 72.93 | D45: 59.84 | E45: 73.029999 | F45: 51.52 | G45: 111.65 | L45: =IF(int=Weekly,-$B$4,IF(int=Bi_Weekly,-$B$4,IF(int=Monthly,0,IF(int=Quarterly,0,IF(int=Yearly,0,IF(int=None,0,0)))))) -> 0 | M45: =(ABS((L45*$B$29)/B45)) -> 0 | N45: =(ABS((L45*$C$29)/C45)) -> 0 | O45: =(ABS((L45*$D$29)/D45)) -> 0 | P45: =(ABS((L45*$E$29)/E45)) -> 0 | Q45: =(ABS((L45*$F$29)/F45)) -> 0 | R45: =(ABS((L45*$G$29)/G45)) -> 0 | S45: =S44+M45 -> 1.2361286 | T45: =T44+N45 -> 2.6190477 | U45: =U44+O45 -> 1.0019682 | V45: =V44+P45 -> 0.72829965 | W45: =W44+Q45 -> 8.7131655 | X45: =X44+R45 -> 1.4634147 | AE45: =(S45*Y45) -> 0 | AF45: =(T45*Z45) -> 0 | AG45: =(U45*AA45) -> 0 | AH45: =(V45*AB45) -> 0 | AI45: =(W45*AC45) -> 0 | AJ45: =(X45*AD45) -> 0 | AK45: =IF(AE45>0,AE45/B45,0) -> 0 | AL45: =IF(AF45>0,AF45/C45,0) -> 0 | AM45: =IF(AG45>0,AG45/D45,0) -> 0 | AN45: =IF(AH45>0,AH45/E45,0) -> 0 | AO45: =IF(AI45>0,AI45/F45,0) -> 0 | AP45: =IF(AJ45>0,AJ45/G45,0) -> 0 | AQ45: =AK45+AQ44+IF(AK45<0,AK45,0) -> 0.0026243207 | AR45: =AL45+AR44+IF(AL45<0,AL45,0) -> 0.016847461 | AS45: =AM45+AS44+IF(AM45<0,AM45,0) -> 0 | AT45: =AN45+AT44+IF(AN45<0,AN45,0) -> 0 | AU45: =AO45+AU44+IF(AO45<0,AO45,0) -> 0 | AV45: =AP45+AV44+IF(AP45<0,AP45,0) -> 0 | AW45: =S45+AQ45 -> 1.2387529 | AX45: =T45+AR45 -> 2.6358952 | AY45: =U45+AS45 -> 1.0019682 | AZ45: =V45+AT45 -> 0.72829965 | BA45: =W45+AU45 -> 8.7131655 | BB45: =X45+AV45 -> 1.4634147 | BC45: =(AE45+AF45+AG45+AH45+AI45+AJ45) -> 0 | BD45: =BD44+L45 -> -1000 | BE45: =(S45*B45)+(T45*C45)+(U45*D45)+(V45*E45)+(W45*F45)+(X45*G45) -> 1108.144 | BF45: =(BE45/ABS(BD45))-1 -> 0.10814402 | BG45: =BG44+BC45 -> 1.6015592 | BH45: =BE45+BG45 -> 1109.7456 | BI45: =(BH45/ABS(BD45))-1 -> 0.10974558 | BJ45: =(B45*AQ45)+(C45*AR45)+(D45*AS45)+(E45*AT45)+(F45*AU45)+(G45*AV45) -> 1.635665 | BK45: =BE45+BJ45 -> 1109.7797 | BL45: =(BK45/ABS(BD45))-1 -> 0.10977968 | BN45: =ABS(BD45) -> 1000 | BO45: =(B45*AW45)+(C45*AX45)+(D45*AY45)+(E45*AZ45)+(F45*BA45)+(G45*BB45) -> 1109.7797 | BQ45: =B45/2 -> 77.540001 | BR45: =G45/2 -> 55.825001
A46: 39370 | B46: 149 | C46: 69.580002 | D46: 57.220001 | E46: 69.029999 | F46: 49.950001 | G46: 106.59 | L46: =IF(int=Weekly,-$B$4,IF(int=Bi_Weekly,0,IF(int=Monthly,0,IF(int=Quarterly,0,IF(int=Yearly,0,IF(int=None,0,0)))))) -> 0 | M46: =(ABS((L46*$B$29)/B46)) -> 0 | N46: =(ABS((L46*$C$29)/C46)) -> 0 | O46: =(ABS((L46*$D$29)/D46)) -> 0 | P46: =(ABS((L46*$E$29)/E46)) -> 0 | Q46: =(ABS((L46*$F$29)/F46)) -> 0 | R46: =(ABS((L46*$G$29)/G46)) -> 0 | S46: =S45+M46 -> 1.2361286 | T46: =T45+N46 -> 2.6190477 | U46: =U45+O46 -> 1.0019682 | V46: =V45+P46 -> 0.72829965 | W46: =W45+Q46 -> 8.7131655 | X46: =X45+R46 -> 1.4634147 | AE46: =(S46*Y46) -> 0 | AF46: =(T46*Z46) -> 0 | AG46: =(U46*AA46) -> 0 | AH46: =(V46*AB46) -> 0 | AI46: =(W46*AC46) -> 0 | AJ46: =(X46*AD46) -> 0 | AK46: =IF(AE46>0,AE46/B46,0) -> 0 | AL46: =IF(AF46>0,AF46/C46,0) -> 0 | AM46: =IF(AG46>0,AG46/D46,0) -> 0 | AN46: =IF(AH46>0,AH46/E46,0) -> 0 | AO46: =IF(AI46>0,AI46/F46,0) -> 0 | AP46: =IF(AJ46>0,AJ46/G46,0) -> 0 | AQ46: =AK46+AQ45+IF(AK46<0,AK46,0) -> 0.0026243207 | AR46: =AL46+AR45+IF(AL46<0,AL46,0) -> 0.016847461 | AS46: =AM46+AS45+IF(AM46<0,AM46,0) -> 0 | AT46: =AN46+AT45+IF(AN46<0,AN46,0) -> 0 | AU46: =AO46+AU45+IF(AO46<0,AO46,0) -> 0 | AV46: =AP46+AV45+IF(AP46<0,AP46,0) -> 0 | AW46: =S46+AQ46 -> 1.2387529 | AX46: =T46+AR46 -> 2.6358952 | AY46: =U46+AS46 -> 1.0019682 | AZ46: =V46+AT46 -> 0.72829965 | BA46: =W46+AU46 -> 8.7131655 | BB46: =X46+AV46 -> 1.4634147 | BC46: =(AE46+AF46+AG46+AH46+AI46+AJ46) -> 0 | BD46: =BD45+L46 -> -1000 | BE46: =(S46*B46)+(T46*C46)+(U46*D46)+(V46*E46)+(W46*F46)+(X46*G46) -> 1065.2316 | BF46: =(BE46/ABS(BD46))-1 -> 0.065231648 | BG46: =BG45+BC46 -> 1.6015592 | BH46: =BE46+BG46 -> 1066.8332 | BI46: =(BH46/ABS(BD46))-1 -> 0.066833207 | BJ46: =(B46*AQ46)+(C46*AR46)+(D46*AS46)+(E46*AT46)+(F46*AU46)+(G46*AV46) -> 1.5632702 | BK46: =BE46+BJ46 -> 1066.7949 | BL46: =(BK46/ABS(BD46))-1 -> 0.066794918 | BN46: =ABS(BD46) -> 1000 | BO46: =(B46*AW46)+(C46*AX46)+(D46*AY46)+(E46*AZ46)+(F46*BA46)+(G46*BB46) -> 1066.7949 | BQ46: =B46/2 -> 74.5 | BR46: =G46/2 -> 53.294998
A47: 39377 | B47: 152.41 | C47: 71.18 | D47: 58.040001 | E47: 71.360001 | F47: 51.57 | G47: 115.14 | L47: =IF(int=Weekly,-$B$4,IF(int=Bi_Weekly,-$B$4,IF(int=Monthly,-$B$4,IF(int=Quarterly,0,IF(int=Yearly,0,IF(int=None,0,0)))))) -> 0 | M47: =(ABS((L47*$B$29)/B47)) -> 0 | N47: =(ABS((L47*$C$29)/C47)) -> 0 | O47: =(ABS((L47*$D$29)/D47)) -> 0 | P47: =(ABS((L47*$E$29)/E47)) -> 0 | Q47: =(ABS((L47*$F$29)/F47)) -> 0 | R47: =(ABS((L47*$G$29)/G47)) -> 0 | S47: =S46+M47 -> 1.2361286 | T47: =T46+N47 -> 2.6190477 | U47: =U46+O47 -> 1.0019682 | V47: =V46+P47 -> 0.72829965 | W47: =W46+Q47 -> 8.7131655 | X47: =X46+R47 -> 1.4634147 | AE47: =(S47*Y47) -> 0 | AF47: =(T47*Z47) -> 0 | AG47: =(U47*AA47) -> 0 | AH47: =(V47*AB47) -> 0 | AI47: =(W47*AC47) -> 0 | AJ47: =(X47*AD47) -> 0 | AK47: =IF(AE47>0,AE47/B47,0) -> 0 | AL47: =IF(AF47>0,AF47/C47,0) -> 0 | AM47: =IF(AG47>0,AG47/D47,0) -> 0 | AN47: =IF(AH47>0,AH47/E47,0) -> 0 | AO47: =IF(AI47>0,AI47/F47,0) -> 0 | AP47: =IF(AJ47>0,AJ47/G47,0) -> 0 | AQ47: =AK47+AQ46+IF(AK47<0,AK47,0) -> 0.0026243207 | AR47: =AL47+AR46+IF(AL47<0,AL47,0) -> 0.016847461 | AS47: =AM47+AS46+IF(AM47<0,AM47,0) -> 0 | AT47: =AN47+AT46+IF(AN47<0,AN47,0) -> 0 | AU47: =AO47+AU46+IF(AO47<0,AO47,0) -> 0 | AV47: =AP47+AV46+IF(AP47<0,AP47,0) -> 0 | AW47: =S47+AQ47 -> 1.2387529 | AX47: =T47+AR47 -> 2.6358952 | AY47: =U47+AS47 -> 1.0019682 | AZ47: =V47+AT47 -> 0.72829965 | BA47: =W47+AU47 -> 8.7131655 | BB47: =X47+AV47 -> 1.4634147 | BC47: =(AE47+AF47+AG47+AH47+AI47+AJ47) -> 0 | BD47: =BD46+L47 -> -1000 | BE47: =(S47*B47)+(T47*C47)+(U47*D47)+(V47*E47)+(W47*F47)+(X47*G47) -> 1102.7834 | BF47: =(BE47/ABS(BD47))-1 -> 0.1027834 | BG47: =BG46+BC47 -> 1.6015592 | BH47: =BE47+BG47 -> 1104.385 | BI47: =(BH47/ABS(BD47))-1 -> 0.10438495 | BJ47: =(B47*AQ47)+(C47*AR47)+(D47*AS47)+(E47*AT47)+(F47*AU47)+(G47*AV47) -> 1.599175 | BK47: =BE47+BJ47 -> 1104.3826 | BL47: =(BK47/ABS(BD47))-1 -> 0.10438257 | BN47: =ABS(BD47) -> 1000 | BO47: =(B47*AW47)+(C47*AX47)+(D47*AY47)+(E47*AZ47)+(F47*BA47)+(G47*BB47) -> 1104.3826 | BQ47: =B47/2 -> 76.205002 | BR47: =G47/2 -> 57.57
A48: 39384 | B48: 149.98 | C48: 69.260002 | D48: 56.75 | E48: 69.07 | F48: 51.349998 | G48: 113.75 | L48: =IF(int=Weekly,-$B$4,IF(int=Bi_Weekly,0,IF(int=Monthly,0,IF(int=Quarterly,-$B$4,IF(int=Yearly,0,IF(int=None,0,0)))))) -> -500 | M48: =(ABS((L48*$B$29)/B48)) -> 0.58674491 | N48: =(ABS((L48*$C$29)/C48)) -> 1.2705746 | O48: =(ABS((L48*$D$29)/D48)) -> 0.49339207 | P48: =(ABS((L48*$E$29)/E48)) -> 0.35471261 | Q48: =(ABS((L48*$F$29)/F48)) -> 4.0019476 | R48: =(ABS((L48*$G$29)/G48)) -> 0.58021978 | S48: =S47+M48 -> 1.8228735 | T48: =T47+N48 -> 3.8896223 | U48: =U47+O48 -> 1.4953602 | V48: =V47+P48 -> 1.0830123 | W48: =W47+Q48 -> 12.715113 | X48: =X47+R48 -> 2.0436345 | AE48: =(S48*Y48) -> 0 | AF48: =(T48*Z48) -> 0 | AG48: =(U48*AA48) -> 0 | AH48: =(V48*AB48) -> 0 | AI48: =(W48*AC48) -> 0 | AJ48: =(X48*AD48) -> 0 | AK48: =IF(AE48>0,AE48/B48,0) -> 0 | AL48: =IF(AF48>0,AF48/C48,0) -> 0 | AM48: =IF(AG48>0,AG48/D48,0) -> 0 | AN48: =IF(AH48>0,AH48/E48,0) -> 0 | AO48: =IF(AI48>0,AI48/F48,0) -> 0 | AP48: =IF(AJ48>0,AJ48/G48,0) -> 0 | AQ48: =AK48+AQ47+IF(AK48<0,AK48,0) -> 0.0026243207 | AR48: =AL48+AR47+IF(AL48<0,AL48,0) -> 0.016847461 | AS48: =AM48+AS47+IF(AM48<0,AM48,0) -> 0 | AT48: =AN48+AT47+IF(AN48<0,AN48,0) -> 0 | AU48: =AO48+AU47+IF(AO48<0,AO48,0) -> 0 | AV48: =AP48+AV47+IF(AP48<0,AP48,0) -> 0 | AW48: =S48+AQ48 -> 1.8254979 | AX48: =T48+AR48 -> 3.9064698 | AY48: =U48+AS48 -> 1.4953602 | AZ48: =V48+AT48 -> 1.0830123 | BA48: =W48+AU48 -> 12.715113 | BB48: =X48+AV48 -> 2.0436345 | BC48: =(AE48+AF48+AG48+AH48+AI48+AJ48) -> 0 | BD48: =BD47+L48 -> -1500 | BE48: =(S48*B48)+(T48*C48)+(U48*D48)+(V48*E48)+(W48*F48)+(X48*G48) -> 1587.8396 | BF48: =(BE48/ABS(BD48))-1 -> 0.058559747 | BG48: =BG47+BC48 -> 1.6015592 | BH48: =BE48+BG48 -> 1589.4412 | BI48: =(BH48/ABS(BD48))-1 -> 0.059627453 | BJ48: =(B48*AQ48)+(C48*AR48)+(D48*AS48)+(E48*AT48)+(F48*AU48)+(G48*AV48) -> 1.5604508 | BK48: =BE48+BJ48 -> 1589.4001 | BL48: =(BK48/ABS(BD48))-1 -> 0.059600048 | BN48: =ABS(BD48) -> 1500 | BO48: =(B48*AW48)+(C48*AX48)+(D48*AY48)+(E48*AZ48)+(F48*BA48)+(G48*BB48) -> 1589.4001 | BQ48: =B48/2 -> 74.989998 | BR48: =G48/2 -> 56.875
A49: 39391 | B49: 144.58 | C49: 67.029999 | D49: 55.459999 | E49: 67.510002 | F49: 49.639999 | G49: 108.64 | L49: =IF(int=Weekly,-$B$4,IF(int=Bi_Weekly,-$B$4,IF(int=Monthly,0,IF(int=Quarterly,0,IF(int=Yearly,0,IF(int=None,0,0)))))) -> 0 | M49: =(ABS((L49*$B$29)/B49)) -> 0 | N49: =(ABS((L49*$C$29)/C49)) -> 0 | O49: =(ABS((L49*$D$29)/D49)) -> 0 | P49: =(ABS((L49*$E$29)/E49)) -> 0 | Q49: =(ABS((L49*$F$29)/F49)) -> 0 | R49: =(ABS((L49*$G$29)/G49)) -> 0 | S49: =S48+M49 -> 1.8228735 | T49: =T48+N49 -> 3.8896223 | U49: =U48+O49 -> 1.4953602 | V49: =V48+P49 -> 1.0830123 | W49: =W48+Q49 -> 12.715113 | X49: =X48+R49 -> 2.0436345 | AE49: =(S49*Y49) -> 0 | AF49: =(T49*Z49) -> 0 | AG49: =(U49*AA49) -> 0 | AH49: =(V49*AB49) -> 0 | AI49: =(W49*AC49) -> 0 | AJ49: =(X49*AD49) -> 0 | AK49: =IF(AE49>0,AE49/B49,0) -> 0 | AL49: =IF(AF49>0,AF49/C49,0) -> 0 | AM49: =IF(AG49>0,AG49/D49,0) -> 0 | AN49: =IF(AH49>0,AH49/E49,0) -> 0 | AO49: =IF(AI49>0,AI49/F49,0) -> 0 | AP49: =IF(AJ49>0,AJ49/G49,0) -> 0 | AQ49: =AK49+AQ48+IF(AK49<0,AK49,0) -> 0.0026243207 | AR49: =AL49+AR48+IF(AL49<0,AL49,0) -> 0.016847461 | AS49: =AM49+AS48+IF(AM49<0,AM49,0) -> 0 | AT49: =AN49+AT48+IF(AN49<0,AN49,0) -> 0 | AU49: =AO49+AU48+IF(AO49<0,AO49,0) -> 0 | AV49: =AP49+AV48+IF(AP49<0,AP49,0) -> 0 | AW49: =S49+AQ49 -> 1.8254979 | AX49: =T49+AR49 -> 3.9064698 | AY49: =U49+AS49 -> 1.4953602 | AZ49: =V49+AT49 -> 1.0830123 | BA49: =W49+AU49 -> 12.715113 | BB49: =X49+AV49 -> 2.0436345 | BC49: =(AE49+AF49+AG49+AH49+AI49+AJ49) -> 0 | BD49: =BD48+L49 -> -1500 | BE49: =(S49*B49)+(T49*C49)+(U49*D49)+(V49*E49)+(W49*F49)+(X49*G49) -> 1533.5179 | BF49: =(BE49/ABS(BD49))-1 -> 0.022345285 | BG49: =BG48+BC49 -> 1.6015592 | BH49: =BE49+BG49 -> 1535.1195 | BI49: =(BH49/ABS(BD49))-1 -> 0.023412991 | BJ49: =(B49*AQ49)+(C49*AR49)+(D49*AS49)+(E49*AT49)+(F49*AU49)+(G49*AV49) -> 1.5087096 | BK49: =BE49+BJ49 -> 1535.0266 | BL49: =(BK49/ABS(BD49))-1 -> 0.023351091 | BN49: =ABS(BD49) -> 1500 | BO49: =(B49*AW49)+(C49*AX49)+(D49*AY49)+(E49*AZ49)+(F49*BA49)+(G49*BB49) -> 1535.0266 | BQ49: =B49/2 -> 72.290001 | BR49: =G49/2 -> 54.32
A50: 39398 | B50: 144.82001 | C50: 66.970001 | D50: 55.07 | E50: 67.089996 | F50: 49.389999 | G50: 107.98 | L50: =IF(int=Weekly,-$B$4,IF(int=Bi_Weekly,0,IF(int=Monthly,0,IF(int=Quarterly,0,IF(int=Yearly,0,IF(int=None,0,0)))))) -> 0 | M50: =(ABS((L50*$B$29)/B50)) -> 0 | N50: =(ABS((L50*$C$29)/C50)) -> 0 | O50: =(ABS((L50*$D$29)/D50)) -> 0 | P50: =(ABS((L50*$E$29)/E50)) -> 0 | Q50: =(ABS((L50*$F$29)/F50)) -> 0 | R50: =(ABS((L50*$G$29)/G50)) -> 0 | S50: =S49+M50 -> 1.8228735 | T50: =T49+N50 -> 3.8896223 | U50: =U49+O50 -> 1.4953602 | V50: =V49+P50 -> 1.0830123 | W50: =W49+Q50 -> 12.715113 | X50: =X49+R50 -> 2.0436345 | AE50: =(S50*Y50) -> 0 | AF50: =(T50*Z50) -> 0 | AG50: =(U50*AA50) -> 0 | AH50: =(V50*AB50) -> 0 | AI50: =(W50*AC50) -> 0 | AJ50: =(X50*AD50) -> 0 | AK50: =IF(AE50>0,AE50/B50,0) -> 0 | AL50: =IF(AF50>0,AF50/C50,0) -> 0 | AM50: =IF(AG50>0,AG50/D50,0) -> 0 | AN50: =IF(AH50>0,AH50/E50,0) -> 0 | AO50: =IF(AI50>0,AI50/F50,0) -> 0 | AP50: =IF(AJ50>0,AJ50/G50,0) -> 0 | AQ50: =AK50+AQ49+IF(AK50<0,AK50,0) -> 0.0026243207 | AR50: =AL50+AR49+IF(AL50<0,AL50,0) -> 0.016847461 | AS50: =AM50+AS49+IF(AM50<0,AM50,0) -> 0 | AT50: =AN50+AT49+IF(AN50<0,AN50,0) -> 0 | AU50: =AO50+AU49+IF(AO50<0,AO50,0) -> 0 | AV50: =AP50+AV49+IF(AP50<0,AP50,0) -> 0 | AW50: =S50+AQ50 -> 1.8254979 | AX50: =T50+AR50 -> 3.9064698 | AY50: =U50+AS50 -> 1.4953602 | AZ50: =V50+AT50 -> 1.0830123 | BA50: =W50+AU50 -> 12.715113 | BB50: =X50+AV50 -> 2.0436345 | BC50: =(AE50+AF50+AG50+AH50+AI50+AJ50) -> 0 | BD50: =BD49+L50 -> -1500 | BE50: =(S50*B50)+(T50*C50)+(U50*D50)+(V50*E50)+(W50*F50)+(X50*G50) -> 1528.1564 | BF50: =(BE50/ABS(BD50))-1 -> 0.018770951 | BG50: =BG49+BC50 -> 1.6015592 | BH50: =BE50+BG50 -> 1529.758 | BI50: =(BH50/ABS(BD50))-1 -> 0.019838657 | BJ50: =(B50*AQ50)+(C50*AR50)+(D50*AS50)+(E50*AT50)+(F50*AU50)+(G50*AV50) -> 1.5083286 | BK50: =BE50+BJ50 -> 1529.6648 | BL50: =(BK50/ABS(BD50))-1 -> 0.019776504 | BN50: =ABS(BD50) -> 1500 | BO50: =(B50*AW50)+(C50*AX50)+(D50*AY50)+(E50*AZ50)+(F50*BA50)+(G50*BB50) -> 1529.6648 | BQ50: =B50/2 -> 72.410004 | BR50: =G50/2 -> 53.990001
A51: 39405 | B51: 142.60001 | C51: 65.839996 | D51: 53.970001 | E51: 65.93 | F51: 49.18 | G51: 103.26 | L51: =IF(int=Weekly,-$B$4,IF(int=Bi_Weekly,-$B$4,IF(int=Monthly,-$B$4,IF(int=Quarterly,0,IF(int=Yearly,0,IF(int=None,0,0)))))) -> 0 | M51: =(ABS((L51*$B$29)/B51)) -> 0 | N51: =(ABS((L51*$C$29)/C51)) -> 0 | O51: =(ABS((L51*$D$29)/D51)) -> 0 | P51: =(ABS((L51*$E$29)/E51)) -> 0 | Q51: =(ABS((L51*$F$29)/F51)) -> 0 | R51: =(ABS((L51*$G$29)/G51)) -> 0 | S51: =S50+M51 -> 1.8228735 | T51: =T50+N51 -> 3.8896223 | U51: =U50+O51 -> 1.4953602 | V51: =V50+P51 -> 1.0830123 | W51: =W50+Q51 -> 12.715113 | X51: =X50+R51 -> 2.0436345 | AE51: =(S51*Y51) -> 0 | AF51: =(T51*Z51) -> 0 | AG51: =(U51*AA51) -> 0 | AH51: =(V51*AB51) -> 0 | AI51: =(W51*AC51) -> 0 | AJ51: =(X51*AD51) -> 0 | AK51: =IF(AE51>0,AE51/B51,0) -> 0 | AL51: =IF(AF51>0,AF51/C51,0) -> 0 | AM51: =IF(AG51>0,AG51/D51,0) -> 0 | AN51: =IF(AH51>0,AH51/E51,0) -> 0 | AO51: =IF(AI51>0,AI51/F51,0) -> 0 | AP51: =IF(AJ51>0,AJ51/G51,0) -> 0 | AQ51: =AK51+AQ50+IF(AK51<0,AK51,0) -> 0.0026243207 | AR51: =AL51+AR50+IF(AL51<0,AL51,0) -> 0.016847461 | AS51: =AM51+AS50+IF(AM51<0,AM51,0) -> 0 | AT51: =AN51+AT50+IF(AN51<0,AN51,0) -> 0 | AU51: =AO51+AU50+IF(AO51<0,AO51,0) -> 0 | AV51: =AP51+AV50+IF(AP51<0,AP51,0) -> 0 | AW51: =S51+AQ51 -> 1.8254979 | AX51: =T51+AR51 -> 3.9064698 | AY51: =U51+AS51 -> 1.4953602 | AZ51: =V51+AT51 -> 1.0830123 | BA51: =W51+AU51 -> 12.715113 | BB51: =X51+AV51 -> 2.0436345 | BC51: =(AE51+AF51+AG51+AH51+AI51+AJ51) -> 0 | BD51: =BD50+L51 -> -1500 | BE51: =(S51*B51)+(T51*C51)+(U51*D51)+(V51*E51)+(W51*F51)+(X51*G51) -> 1504.4971 | BF51: =(BE51/ABS(BD51))-1 -> 0.0029980337 | BG51: =BG50+BC51 -> 1.6015592 | BH51: =BE51+BG51 -> 1506.0986 | BI51: =(BH51/ABS(BD51))-1 -> 0.0040657398 | BJ51: =(B51*AQ51)+(C51*AR51)+(D51*AS51)+(E51*AT51)+(F51*AU51)+(G51*AV51) -> 1.4834649 | BK51: =BE51+BJ51 -> 1505.9805 | BL51: =(BK51/ABS(BD51))-1 -> 0.0039870103 | BN51: =ABS(BD51) -> 1500 | BO51: =(B51*AW51)+(C51*AX51)+(D51*AY51)+(E51*AZ51)+(F51*BA51)+(G51*BB51) -> 1505.9805 | BQ51: =B51/2 -> 71.300003 | BR51: =G51/2 -> 51.630001
...

Sheet Value Average (Model)
A1: Value Cost Average Method (VCA)
A2: Initial Investment | B2: 5000 | E2: % Change | F2: =AVERAGE((B31*B29)+(C31*C29)+(D31*D29)+(E31*E29)+(F31*F29)+(G31*G29)) -> 0.13730492
A3: Interval | B3: Monthly | E3: Period (Yr.) | F3: =COUNT(A35:A526)/52 -> 9.4615385
A4: Increment | B4: 100 | E4: Return on Principal | F4: =BL33 -> 0.38670859
E5: Gain/Loss | F5: =BK33+BJ33 -> 4711.8925
E6: Annual Return | F6: =((BK33/ABS(BJ33))^(1/F3))-1 -> 0.035157818
F7: Dividends Retained | H7: Dividends Reinvested
E8: Total Return (%) | F8: =BO33 -> 0.61906809 | H8: =BR33 -> 0.66905465
E9: Gain/Loss | F9: =BN33+BJ33 -> 7543.1019 | H9: =BQ33+BJ33 -> 8152.1686
E10: Annual Return | F10: =((BN33/ABS(BJ33))^(1/F3))-1 -> 0.052246406 | H10: =((BQ33/ABS(BJ33))^(1/F3))-1 -> 0.055633462
B15: Weekly
B16: Bi-weekly
B17: Monthly
B18: Quarterly
B19: Yearly
B20: None
A28: Symbol | B28: VTI | C28: VTV | D28: VOE | E28: VBR | F28: VEA | G28: VWO | M28: VTI | N28: VTV | O28: VOE | P28: VBR | Q28: VEA | R28: VWO
A29: Portfolio Weight | B29: 0.176 | C29: 0.176 | D29: 0.056 | E29: 0.049 | F29: 0.411 | G29: 0.132 | J29: =SUM(B29:G29) -> 1 | L29: Discount Rate | M29: =M30-B30 -> -2.3165325 | N29: =N30-C30 -> -15.214073 | O29: =O30-D30 -> -27.7341 | P29: =P30-E30 -> -38.033652 | Q29: =Q30-F30 -> -2.1631635 | R29: =R30-G30 -> -1.1371332
A30: Average Price | B30: =AVERAGE(BZ35:BZ80,B81:B526) -> 77.831077 | C30: =AVERAGE(C35:C526) -> 63.830793 | D30: =AVERAGE(D35:D526) -> 63.394837 | E30: =AVERAGE(E35:E526) -> 76.877317 | F30: =AVERAGE(F35:F526) -> 36.556667 | G30: =AVERAGE(CA35:CA80,G81:G526) -> 40.316646 | L30: Aerage Cost per Share | M30: =M32/M31 -> 75.514545 | N30: =N32/N31 -> 48.61672 | O30: =O32/O31 -> 35.660738 | P30: =P32/P31 -> 38.843664 | Q30: =Q32/Q31 -> 34.393503 | R30: =R32/R31 -> 39.179513
A31: IRR | B31: =(B526-($B$35/2))/($B$35/2) -> 0.61989038 | C31: =(C526-$C$35)/$C$35 -> 0.38407747 | D31: =(D526-$D$35)/$D$35 -> 0.73895158 | E31: =(E526-$E$35)/$E$35 -> 0.79845425 | F31: =(F526-$F$35)/$F$35 -> -0.22535504 | G31: =(G526-($G$35/2))/($G$35/2) -> -0.20665188 | L31: Average Shares Purchased | M31: =AVERAGE(S35:S526) -> 0.036592087 | N31: =AVERAGE(T35:T526) -> 0.065323765 | O31: =AVERAGE(U35:U526) -> 0.019528415 | P31: =AVERAGE(V35:V526) -> 0.013795669 | Q31: =AVERAGE(W35:W526) -> 0.38707686 | R31: =AVERAGE(X35:X526) -> 0.10927139
L32: Average Amount Invested | M32: =ABS((AVERAGE(M35:M526))) -> 2.7632348 | N32: =ABS((AVERAGE(N35:N526))) -> 3.1758271 | O32: =ABS((AVERAGE(O35:O526))) -> 0.69639767 | P32: =ABS((AVERAGE(P35:P526))) -> 0.53587432 | Q32: =ABS((AVERAGE(Q35:Q526))) -> 13.312929 | R32: =ABS((AVERAGE(R35:R526))) -> 4.2811999
A33: Date | B33: NAV ($) | C33: NAV ($) | D33: NAV ($) | E33: NAV ($) | F33: NAV ($) | G33: NAV ($) | L33: Total | M33: =ABS(SUM(M35:M526)) -> 1359.5115 | N33: =ABS(SUM(N35:N526)) -> 1562.507 | O33: =ABS(SUM(O35:O526)) -> 342.62765 | P33: =ABS(SUM(P35:P526)) -> 263.65016 | Q33: =ABS(SUM(Q35:Q526)) -> 6549.9612 | R33: =ABS(SUM(R35:R526)) -> 2106.3504 | S33: =SUM(S35:S526) -> 18.003307 | T33: =SUM(T35:T526) -> 32.139292 | U33: =SUM(U35:U526) -> 9.60798 | V33: =SUM(V35:V526) -> 6.7874689 | W33: =SUM(W35:W526) -> 190.44182 | X33: =SUM(X35:X526) -> 53.761524 | Y33: =Y526 -> 25.840375 | Z33: =Z526 -> 32.139292 | AA33: =AA526 -> 9.60798 | AB33: =AB526 -> 6.7874689 | AC33: =AC526 -> 190.44182 | AD33: =AD526 -> 61.863759 | BJ33: =BJ526 -> -12184.608 | BK33: =BK526 -> 16896.5 | BL33: =BL526 -> 0.38670859 | BM33: =BM526 -> 2831.2093 | BN33: =BN526 -> 19727.71 | BO33: =BO526 -> 0.61906809 | BP33: =BP526 -> 3440.276 | BQ33: =BQ526 -> 20336.776 | BR33: =BR526 -> 0.66905465
L34: Set Value | M34: Amount Invested ($) | S34: Shares (#) | Y34: Total Shares (#) | AE34: Dividend Payout/Share ($) | AK34: Dividend ($) | AQ34: Additional Shares | AW34: Total Additional Shares | BC34: New Total Shares (#) | BI34: Dividend Payout ($) | BJ34: Principal ($) | BK34: Total Value | BL34: Return (%) | BM34: Dividend Value ($) | BN34: Total Value ($) | BO34: Return (%) | BP34: Divdend Value ($) | BQ34: Total Value ($) | BR34: Return (%) | BU34: Principal ($) | BV34: Total Value | BX34: Absolute Total Invested | BY34: Return | BZ34: VTI | CA34: VWO
A35: 39293 | B35: 142.38001 | C35: 67.199997 | D35: 55.889999 | E35: 67.279999 | F35: 47.169998 | G35: 90.199997 | L35: =B2 -> 5000 | M35: =-$L$35*B29 -> -880 | N35: =-$L$35*C29 -> -880 | O35: =-$L$35*D29 -> -280 | P35: =-$L$35*E29 -> -245 | Q35: =-$L$35*F29 -> -2055 | R35: =-$L$35*G29 -> -660 | S35: =-((M35)/B35) -> 6.1806431 | T35: =-((N35)/C35) -> 13.095239 | U35: =-(O35)/D35 -> 5.0098408 | V35: =-(P35)/E35 -> 3.6414983 | W35: =-(Q35)/F35 -> 43.565828 | X35: =-(R35)/G35 -> 7.3170734 | Y35: =S35 -> 6.1806431 | Z35: =T35 -> 13.095239 | AA35: =U35 -> 5.0098408 | AB35: =V35 -> 3.6414983 | AC35: =W35 -> 43.565828 | AD35: =X35 -> 7.3170734 | AK35: =(Y35*AE35) -> 0 | AL35: =(Z35*AF35) -> 0 | AM35: =(AA35*AG35) -> 0 | AN35: =(AB35*AH35) -> 0 | AO35: =(AC35*AI35) -> 0 | AP35: =(AD35*AJ35) -> 0 | AQ35: =IF(AK35>0,AK35/B35,0) -> 0 | AR35: =IF(AL35>0,AL35/C35,0) -> 0 | AS35: =IF(AM35>0,AM35/D35,0) -> 0 | AT35: =IF(AN35>0,AN35/E35,0) -> 0 | AU35: =IF(AO35>0,AO35/F35,0) -> 0 | AV35: =IF(AP35>0,AP35/G35,0) -> 0 | AW35: =AQ35 -> 0 | AX35: =AR35 -> 0 | AY35: =AS35 -> 0 | AZ35: =AT35 -> 0 | BA35: =AU35 -> 0 | BB35: =AV35 -> 0 | BC35: =Y35+AQ35 -> 6.1806431 | BD35: =Z35+AR35 -> 13.095239 | BE35: =AA35+AS35 -> 5.0098408 | BF35: =AB35+AT35 -> 3.6414983 | BG35: =AC35+AU35 -> 43.565828 | BH35: =AD35+AV35 -> 7.3170734 | BI35: =(AK35+AL35+AM35+AN35+AO35+AP35) -> 0 | BJ35: =M35+N35+O35+P35+Q35+R35 -> -5000 | BK35: =(Y35*B35)+(Z35*C35)+(AA35*D35)+(AB35*E35)+(AC35*F35)+(AD35*G35) -> 5000 | BL35: =BK35/ABS(BJ35)-1 -> 0 | BM35: =BI35 -> 0 | BN35: =BK35+BM35 -> 5000 | BO35: =BN35/ABS(BJ35)-1 -> 0 | BP35: =(B35*AW35)+(C35*AX35)+(D35*AY35)+(E35*AZ35)+(F35*BA35)+(G35*BB35) -> 0 | BQ35: =(B35*BC35)+(C35*BD35)+(D35*BE35)+(E35*BF35)+(F35*BG35)+(G35*BH35) -> 5000 | BR35: =(BQ35/ABS(BJ35))-1 -> 0 | BU35: =M35+N35+O35+P35+Q35+R35 -> -5000 | BV35: =(Y35*B35)+(Z35*C35)+(AA35*D35)+(AB35*E35)+(AC35*F35)+(AD35*G35) -> 5000 | BX35: =ABS(BJ35) -> 5000 | BY35: =IRR(BJ35:BK35) -> 0 | BZ35: =B35/2 -> 71.190003 | CA35: =G35/2 -> 45.099998
A36: 39300 | B36: 143.72 | C36: 68.300003 | D36: 56.41 | E36: 69.68 | F36: 46.59 | G36: 90.449997 | L36: =IF(inter=Weekly_2,L35+$B$4,IF(inter=Bi_weekly_2,0,IF(inter=Monthly_2,0,IF(inter=Quarterly_2,0,IF(inter=Yearly_2,0,IF(inter=None_2,0,0)))))) -> 0 | M36: =IF(L36=0,0,-((L36*$B$29)-(Y35*B36))) -> 0 | N36: =IF(L36=0,0,-((L36*$C$29)-(Z35*C36))) -> 0 | O36: =IF(L36=0,0,-((L36*$D$29)-(AA35*D36))) -> 0 | P36: =IF(L36=0,0,-((L36*$E$29)-(AB35*E36))) -> 0 | Q36: =IF(L36=0,0,-((L36*$F$29)-(AC35*F36))) -> 0 | R36: =IF(L36=0,0,-((L36*$G$29)-(AD35*G36))) -> 0 | S36: =-((M36)/B36) -> 0 | T36: =-((N36)/C36) -> 0 | U36: =-(O36)/D36 -> 0 | V36: =-(P36)/E36 -> 0 | W36: =-(Q36)/F36 -> 0 | X36: =-(R36)/G36 -> 0 | Y36: =Y35+S36 -> 6.1806431 | Z36: =Z35+T36 -> 13.095239 | AA36: =AA35+U36 -> 5.0098408 | AB36: =AB35+V36 -> 3.6414983 | AC36: =AC35+W36 -> 43.565828 | AD36: =AD35+X36 -> 7.3170734 | AK36: =(Y36*AE36) -> 0 | AL36: =(Z36*AF36) -> 0 | AM36: =(AA36*AG36) -> 0 | AN36: =(AB36*AH36) -> 0 | AO36: =(AC36*AI36) -> 0 | AP36: =(AD36*AJ36) -> 0 | AQ36: =IF(AK36>0,AK36/B36,0) -> 0 | AR36: =IF(AL36>0,AL36/C36,0) -> 0 | AS36: =IF(AM36>0,AM36/D36,0) -> 0 | AT36: =IF(AN36>0,AN36/E36,0) -> 0 | AU36: =IF(AO36>0,AO36/F36,0) -> 0 | AV36: =IF(AP36>0,AP36/G36,0) -> 0 | AW36: =AQ36+AW35+IF(AQ36<0,AQ36,0) -> 0 | AX36: =AR36+AX35+IF(AR36<0,AR36,0) -> 0 | AY36: =AS36+AY35+IF(AS36<0,AS36,0) -> 0 | AZ36: =AT36+AZ35+IF(AT36<0,AT36,0) -> 0 | BA36: =AU36+BA35+IF(AU36<0,AU36,0) -> 0 | BB36: =AV36+BB35+IF(AV36<0,AV36,0) -> 0 | BC36: =Y36+AW36 -> 6.1806431 | BD36: =Z36+AX36 -> 13.095239 | BE36: =AA36+AY36 -> 5.0098408 | BF36: =AB36+AZ36 -> 3.6414983 | BG36: =AC36+BA36 -> 43.565828 | BH36: =AD36+BB36 -> 7.3170734 | BI36: =(AK36+AL36+AM36+AN36+AO36+AP36) -> 0 | BJ36: =BJ35+M36+N36+O36+P36+Q36+R36 -> -5000 | BK36: =(Y36*B36)+(Z36*C36)+(AA36*D36)+(AB36*E36)+(AC36*F36)+(AD36*G36) -> 5010.5928 | BL36: =BK36/ABS(BJ36)-1 -> 0.0021185551 | BM36: =BM35+BI36 -> 0 | BN36: =BK36+BM36 -> 5010.5928 | BO36: =BN36/ABS(BJ36)-1 -> 0.0021185551 | BP36: =(B36*AW36)+(C36*AX36)+(D36*AY36)+(E36*AZ36)+(F36*BA36)+(G36*BB36) -> 0 | BQ36: =(B36*BC36)+(C36*BD36)+(D36*BE36)+(E36*BF36)+(F36*BG36)+(G36*BH36) -> 5010.5928 | BR36: =(BQ36/ABS(BJ36))-1 -> 0.0021185551 | BU36: =BU35+M36+N36+O36+P36+Q36+R36 -> -5000 | BV36: =(Y36*B36)+(Z36*C36)+(AA36*D36)+(AB36*E36)+(AC36*F36)+(AD36*G36) -> 5010.5928 | BX36: =ABS(BJ36) -> 5000 | BY36: =IRR(BJ36:BK36) -> 0.0021185551 | BZ36: =B36/2 -> 71.86 | CA36: =G36/2 -> 45.224998
A37: 39307 | B37: 143.06 | C37: 68.809998 | D37: 55.959999 | E37: 69.309998 | F37: 45.400002 | G37: 85.559998 | L37: =IF(inter=Weekly_2,L36+$B$4,IF(inter=Bi_weekly_2,L35+$B$4,IF(inter=Monthly_2,0,IF(inter=Quarterly_2,0,IF(inter=Yearly_2,0,IF(inter=None_2,0,0)))))) -> 0 | M37: =IF(L37=0,0,-((L37*$B$29)-(Y36*B37))) -> 0 | N37: =IF(L37=0,0,-((L37*$C$29)-(Z36*C37))) -> 0 | O37: =IF(L37=0,0,-((L37*$D$29)-(AA36*D37))) -> 0 | P37: =IF(L37=0,0,-((L37*$E$29)-(AB36*E37))) -> 0 | Q37: =IF(L37=0,0,-((L37*$F$29)-(AC36*F37))) -> 0 | R37: =IF(L37=0,0,-((L37*$G$29)-(AD36*G37))) -> 0 | S37: =-((M37)/B37) -> 0 | T37: =-((N37)/C37) -> 0 | U37: =-(O37)/D37 -> 0 | V37: =-(P37)/E37 -> 0 | W37: =-(Q37)/F37 -> 0 | X37: =-(R37)/G37 -> 0 | Y37: =Y36+S37 -> 6.1806431 | Z37: =Z36+T37 -> 13.095239 | AA37: =AA36+U37 -> 5.0098408 | AB37: =AB36+V37 -> 3.6414983 | AC37: =AC36+W37 -> 43.565828 | AD37: =AD36+X37 -> 7.3170734 | AK37: =(Y37*AE37) -> 0 | AL37: =(Z37*AF37) -> 0 | AM37: =(AA37*AG37) -> 0 | AN37: =(AB37*AH37) -> 0 | AO37: =(AC37*AI37) -> 0 | AP37: =(AD37*AJ37) -> 0 | AQ37: =IF(AK37>0,AK37/B37,0) -> 0 | AR37: =IF(AL37>0,AL37/C37,0) -> 0 | AS37: =IF(AM37>0,AM37/D37,0) -> 0 | AT37: =IF(AN37>0,AN37/E37,0) -> 0 | AU37: =IF(AO37>0,AO37/F37,0) -> 0 | AV37: =IF(AP37>0,AP37/G37,0) -> 0 | AW37: =AQ37+AW36+IF(AQ37<0,AQ37,0) -> 0 | AX37: =AR37+AX36+IF(AR37<0,AR37,0) -> 0 | AY37: =AS37+AY36+IF(AS37<0,AS37,0) -> 0 | AZ37: =AT37+AZ36+IF(AT37<0,AT37,0) -> 0 | BA37: =AU37+BA36+IF(AU37<0,AU37,0) -> 0 | BB37: =AV37+BB36+IF(AV37<0,AV37,0) -> 0 | BC37: =Y37+AW37 -> 6.1806431 | BD37: =Z37+AX37 -> 13.095239 | BE37: =AA37+AY37 -> 5.0098408 | BF37: =AB37+AZ37 -> 3.6414983 | BG37: =AC37+BA37 -> 43.565828 | BH37: =AD37+BB37 -> 7.3170734 | BI37: =(AK37+AL37+AM37+AN37+AO37+AP37) -> 0 | BJ37: =BJ36+M37+N37+O37+P37+Q37+R37 -> -5000 | BK37: =(Y37*B37)+(Z37*C37)+(AA37*D37)+(AB37*E37)+(AC37*F37)+(AD37*G37) -> 4921.9665 | BL37: =BK37/ABS(BJ37)-1 -> -0.015606697 | BM37: =BM36+BI37 -> 0 | BN37: =BK37+BM37 -> 4921.9665 | BO37: =BN37/ABS(BJ37)-1 -> -0.015606697 | BP37: =(B37*AW37)+(C37*AX37)+(D37*AY37)+(E37*AZ37)+(F37*BA37)+(G37*BB37) -> 0 | BQ37: =(B37*BC37)+(C37*BD37)+(D37*BE37)+(E37*BF37)+(F37*BG37)+(G37*BH37) -> 4921.9665 | BR37: =(BQ37/ABS(BJ37))-1 -> -0.015606697 | BU37: =BU36+M37+N37+O37+P37+Q37+R37 -> -5000 | BV37: =(Y37*B37)+(Z37*C37)+(AA37*D37)+(AB37*E37)+(AC37*F37)+(AD37*G37) -> 4921.9665 | BX37: =ABS(BJ37) -> 5000 | BY37: =IRR(BJ37:BK37) -> -0.015606697 | BZ37: =B37/2 -> 71.529999 | CA37: =G37/2 -> 42.779999
A38: 39314 | B38: 146.85001 | C38: 70.290001 | D38: 57.66 | E38: 70.949997 | F38: 47.540001 | G38: 91.620003 | L38: =IF(inter=Weekly_2,L37+$B$4,IF(inter=Bi_weekly_2,0,IF(inter=Monthly_2,0,IF(inter=Quarterly_2,0,IF(inter=Yearly_2,0,IF(inter=None_2,0,0)))))) -> 0 | M38: =IF(L38=0,0,-((L38*$B$29)-(Y37*B38))) -> 0 | N38: =IF(L38=0,0,-((L38*$C$29)-(Z37*C38))) -> 0 | O38: =IF(L38=0,0,-((L38*$D$29)-(AA37*D38))) -> 0 | P38: =IF(L38=0,0,-((L38*$E$29)-(AB37*E38))) -> 0 | Q38: =IF(L38=0,0,-((L38*$F$29)-(AC37*F38))) -> 0 | R38: =IF(L38=0,0,-((L38*$G$29)-(AD37*G38))) -> 0 | S38: =-((M38)/B38) -> 0 | T38: =-((N38)/C38) -> 0 | U38: =-(O38)/D38 -> 0 | V38: =-(P38)/E38 -> 0 | W38: =-(Q38)/F38 -> 0 | X38: =-(R38)/G38 -> 0 | Y38: =Y37+S38 -> 6.1806431 | Z38: =Z37+T38 -> 13.095239 | AA38: =AA37+U38 -> 5.0098408 | AB38: =AB37+V38 -> 3.6414983 | AC38: =AC37+W38 -> 43.565828 | AD38: =AD37+X38 -> 7.3170734 | AK38: =(Y38*AE38) -> 0 | AL38: =(Z38*AF38) -> 0 | AM38: =(AA38*AG38) -> 0 | AN38: =(AB38*AH38) -> 0 | AO38: =(AC38*AI38) -> 0 | AP38: =(AD38*AJ38) -> 0 | AQ38: =IF(AK38>0,AK38/B38,0) -> 0 | AR38: =IF(AL38>0,AL38/C38,0) -> 0 | AS38: =IF(AM38>0,AM38/D38,0) -> 0 | AT38: =IF(AN38>0,AN38/E38,0) -> 0 | AU38: =IF(AO38>0,AO38/F38,0) -> 0 | AV38: =IF(AP38>0,AP38/G38,0) -> 0 | AW38: =AQ38+AW37+IF(AQ38<0,AQ38,0) -> 0 | AX38: =AR38+AX37+IF(AR38<0,AR38,0) -> 0 | AY38: =AS38+AY37+IF(AS38<0,AS38,0) -> 0 | AZ38: =AT38+AZ37+IF(AT38<0,AT38,0) -> 0 | BA38: =AU38+BA37+IF(AU38<0,AU38,0) -> 0 | BB38: =AV38+BB37+IF(AV38<0,AV38,0) -> 0 | BC38: =Y38+AW38 -> 6.1806431 | BD38: =Z38+AX38 -> 13.095239 | BE38: =AA38+AY38 -> 5.0098408 | BF38: =AB38+AZ38 -> 3.6414983 | BG38: =AC38+BA38 -> 43.565828 | BH38: =AD38+BB38 -> 7.3170734 | BI38: =(AK38+AL38+AM38+AN38+AO38+AP38) -> 0 | BJ38: =BJ37+M38+N38+O38+P38+Q38+R38 -> -5000 | BK38: =(Y38*B38)+(Z38*C38)+(AA38*D38)+(AB38*E38)+(AC38*F38)+(AD38*G38) -> 5116.8333 | BL38: =BK38/ABS(BJ38)-1 -> 0.023366662 | BM38: =BM37+BI38 -> 0 | BN38: =BK38+BM38 -> 5116.8333 | BO38: =BN38/ABS(BJ38)-1 -> 0.023366662 | BP38: =(B38*AW38)+(C38*AX38)+(D38*AY38)+(E38*AZ38)+(F38*BA38)+(G38*BB38) -> 0 | BQ38: =(B38*BC38)+(C38*BD38)+(D38*BE38)+(E38*BF38)+(F38*BG38)+(G38*BH38) -> 5116.8333 | BR38: =(BQ38/ABS(BJ38))-1 -> 0.023366662 | BU38: =BU37+M38+N38+O38+P38+Q38+R38 -> -5000 | BV38: =(Y38*B38)+(Z38*C38)+(AA38*D38)+(AB38*E38)+(AC38*F38)+(AD38*G38) -> 5116.8333 | BX38: =ABS(BJ38) -> 5000 | BY38: =IRR(BJ38:BK38) -> 0.023366662 | BZ38: =B38/2 -> 73.425003 | CA38: =G38/2 -> 45.810001
