Workbook
Name data_type: 'Sheet 2'!#REF!
Name debt: 'Sheet 1'!$Z$3
Name effc: 'Sheet 1'!$AD$3
Name proft: 'Sheet 1'!$AA$3
Name ratio: 'Sheet 1'!$X$3

Sheet Sheet 1
B2: Quote | G2: Valuation | X2: Financial Health | AA2: Profitability | AD2: Effectiveness | AG2: Growth | AP2: Dividend
A3: Symbol | B3: Last Price | C3: Market Capitalization | D3: Enterprise Value | E3: Book Value | F3: Sales | I3: P / E | K3: P / S | M3: P / B | O3: P / FCF | Q3: P / CFO | S3: EV / EBITDA | U3: EV / S | X3: Current Ratio | Y3: Financial Leverage | Z3: Debt / Equity | AA3: Gross Margin | AB3: Net Margin | AC3: Operating Margin | AD3: Return on Equity | AE3: Return on Assets | AF3: Asset Turnover | AH3: Revenue | AJ3: Operating Income % | AL3: Net Income | AN3: Earnings Per Share | AP3: Yield
I4: =AVERAGE(I5:I500) -> 27.300703 | K4: =AVERAGE(K5:K500) -> #DIV/0! | M4: =AVERAGE(M5:M500) -> #DIV/0! | O4: =AVERAGE(O5:O500) -> #DIV/0! | Q4: =AVERAGE(Q5:Q500) -> #DIV/0! | S4: =AVERAGE(S5:S500) -> #DIV/0! | U4: =AVERAGE(U5:U500) -> #DIV/0! | X4: =AVERAGE(X5:X500) -> #DIV/0! | Y4: =AVERAGE(Y5:Y500) -> #DIV/0! | Z4: =AVERAGE(Z5:Z500) -> #DIV/0! | AA4: =AVERAGE(AA5:AA500) -> #DIV/0! | AB4: =AVERAGE(AB5:AB500) -> #DIV/0! | AC4: =AVERAGE(AC5:AC500) -> #DIV/0! | AD4: =AVERAGE(AD5:AD39) -> #DIV/0! | AE4: =AVERAGE(AE5:AE39) -> #DIV/0! | AF4: =AVERAGE(AF5:AF39) -> #DIV/0! | AH4: =AVERAGE(AH5:AH500) -> #DIV/0! | AI4: =AVERAGE(AI5:AI500) -> #DIV/0! | AJ4: =AVERAGE(AJ5:AJ500) -> #NUM! | AL4: =AVERAGE(AL5:AL500) -> #DIV/0! | AN4: =AVERAGE(AN5:AN500) -> #DIV/0! | AP4: =AVERAGE(AP5:AP500) -> #DIV/0!
A5: {=INDEX('Sheet 2'!T$2:T$3173,SMALL(IF(A$3='Sheet 2'!$S$2:$S$3173,ROW('Sheet 2'!T$2:T$3173)-ROW('Sheet 2'!$T$2)+1),ROW(1:1)))} -> CCUR | B5: {=INDEX('Sheet 2'!V$5:V$3173,SMALL(IF(B$3='Sheet 2'!S$5:S$3173,ROW('Sheet 2'!V$5:V$3173)-ROW('Sheet 2'!V$5)+1),ROW(1:1)))} -> 5.42 | C5: {=INDEX('Sheet 2'!V$5:V$3173,SMALL(IF(C$3='Sheet 2'!S$5:S$3173,ROW('Sheet 2'!V$5:V$3173)-ROW('Sheet 2'!V$5)+1),ROW(1:1)))} -> 50682702 | D5: {=INDEX('Sheet 2'!V$5:V$3173,SMALL(IF(D$3='Sheet 2'!S$5:S$3173,ROW('Sheet 2'!V$5:V$3173)-ROW('Sheet 2'!V$5)+1),ROW(1:1)))} -> -6864298.2 | E5: {=INDEX('Sheet 2'!V$5:V$3173,SMALL(IF(E$3='Sheet 2'!S$5:S$3173,ROW('Sheet 2'!V$5:V$3173)-ROW('Sheet 2'!V$5)+1),ROW(1:1)))} -> 62117000 | F5: {=INDEX('Sheet 2'!V$5:V$3173,SMALL(IF(F$3='Sheet 2'!S$5:S$3173,ROW('Sheet 2'!V$5:V$3173)-ROW('Sheet 2'!V$5)+1),ROW(1:1)))} -> 250000000 | I5: {=INDEX('Sheet 2'!V$5:V$3173,SMALL(IF(I$3='Sheet 2'!S$5:S$3173,ROW('Sheet 2'!V$5:V$3173)-ROW('Sheet 2'!V$5)+1),ROW(1:1)))} -> 1.0037037 | K5: {=INDEX('Sheet 2'!V$5:V$3173,SMALL(IF(K$3='Sheet 2'!S$5:S$3173,ROW('Sheet 2'!V$5:V$3173)-ROW('Sheet 2'!V$5)+1),ROW(1:1)))} -> 0.20273081 | M5: {=INDEX('Sheet 2'!V$5:V$3173,SMALL(IF(M$3='Sheet 2'!S$5:S$3173,ROW('Sheet 2'!V$5:V$3173)-ROW('Sheet 2'!V$5)+1),ROW(1:1)))} -> 0.82340905 | O5: {=INDEX('Sheet 2'!V$5:V$3173,SMALL(IF(O$3='Sheet 2'!S$5:S$3173,ROW('Sheet 2'!V$5:V$3173)-ROW('Sheet 2'!V$5)+1),ROW(1:1)))} | Q5: {=INDEX('Sheet 2'!V$5:V$3173,SMALL(IF(Q$3='Sheet 2'!S$5:S$3173,ROW('Sheet 2'!V$5:V$3173)-ROW('Sheet 2'!V$5)+1),ROW(1:1)))} | S5: {=INDEX('Sheet 2'!V$5:V$3173,SMALL(IF(S$3='Sheet 2'!S$5:S$3173,ROW('Sheet 2'!V$5:V$3173)-ROW('Sheet 2'!V$5)+1),ROW(1:1)))} -> 1.9163311 | U5: {=INDEX('Sheet 2'!V$5:V$3173,SMALL(IF(U$3='Sheet 2'!S$5:S$3173,ROW('Sheet 2'!V$5:V$3173)-ROW('Sheet 2'!V$5)+1),ROW(1:1)))} -> 4.2943763 | X5: {=INDEX('Sheet 2'!AA$13:AA$3173,SMALL(IF(X$3='Sheet 2'!X$13:X$3173,ROW('Sheet 2'!AA$13:AA$3173)-ROW('Sheet 2'!AA$13)+1),ROW(1:1)))} -> 5.4407029 | Y5: {=INDEX('Sheet 2'!AA$13:AA$3173,SMALL(IF(Y$3='Sheet 2'!X$13:X$3173,ROW('Sheet 2'!AA$13:AA$3173)-ROW('Sheet 2'!AA$13)+1),ROW(1:1)))} -> 1.3644479 | Z5: {=INDEX('Sheet 2'!AA$13:AA$3173,SMALL(IF(Z$3='Sheet 2'!X$13:X$3173,ROW('Sheet 2'!AA$13:AA$3173)-ROW('Sheet 2'!AA$13)+1),ROW(1:1)))} -> #DIV/0! | AA5: {=INDEX('Sheet 2'!V$5:V$3173,SMALL(IF(AA$3='Sheet 2'!S$5:S$3173,ROW('Sheet 2'!V$5:V$3173)-ROW('Sheet 2'!V$5)+1),ROW(1:1)))} -> 1 | AB5: {=INDEX('Sheet 2'!V$5:V$3173,SMALL(IF(AB$3='Sheet 2'!S$5:S$3173,ROW('Sheet 2'!V$5:V$3173)-ROW('Sheet 2'!V$5)+1),ROW(1:1)))} -> 0.2011 | AC5: {=INDEX('Sheet 2'!V$5:V$3173,SMALL(IF(AC$3='Sheet 2'!S$5:S$3173,ROW('Sheet 2'!V$5:V$3173)-ROW('Sheet 2'!V$5)+1),ROW(1:1)))} -> -0.119164 | AD5: {=INDEX('Sheet 2'!V$5:V$3173,SMALL(IF(AD$3='Sheet 2'!S$5:S$3173,ROW('Sheet 2'!V$5:V$3173)-ROW('Sheet 2'!V$5)+1),ROW(1:1)))} -> 1.2536 | AE5: {=INDEX('Sheet 2'!V$5:V$3173,SMALL(IF(AE$3='Sheet 2'!S$5:S$3173,ROW('Sheet 2'!V$5:V$3173)-ROW('Sheet 2'!V$5)+1),ROW(1:1)))} -> 0.91875988 | AF5: {=INDEX('Sheet 2'!V$5:V$3173,SMALL(IF(AF$3='Sheet 2'!S$5:S$3173,ROW('Sheet 2'!V$5:V$3173)-ROW('Sheet 2'!V$5)+1),ROW(1:1)))} -> 4.5686717 | AH5: {=INDEX('Sheet 2'!AA$5:AA$3173,SMALL(IF(AH$3='Sheet 2'!X$5:X$3173,ROW('Sheet 2'!AA$5:AA$3173)-ROW('Sheet 2'!AA$5)+1),ROW(1:1)))} -> -0.14293524 | AJ5: {=INDEX('Sheet 2'!V$5:V$3173,SMALL(IF(AJ$3='Sheet 2'!S$5:S$3173,ROW('Sheet 2'!V$5:V$3173)-ROW('Sheet 2'!V$5)+1),ROW(1:1)))} -> #NUM! | AL5: {=INDEX('Sheet 2'!AA$5:AA$3173,SMALL(IF(AL$3='Sheet 2'!X$5:X$3173,ROW('Sheet 2'!AA$5:AA$3173)-ROW('Sheet 2'!AA$5)+1),ROW(1:1)))} -> -13.927713 | AN5: {=INDEX('Sheet 2'!AA$5:AA$3173,SMALL(IF(AN$3='Sheet 2'!X$5:X$3173,ROW('Sheet 2'!AA$5:AA$3173)-ROW('Sheet 2'!AA$5)+1),ROW(1:1)))} -> -13.002551
A6: {=INDEX('Sheet 2'!T$2:T$3173,SMALL(IF(A$3='Sheet 2'!$S$2:$S$3173,ROW('Sheet 2'!T$2:T$3173)-ROW('Sheet 2'!$T$2)+1),ROW(2:2)))} -> CRAY | B6: {=INDEX('Sheet 2'!V$5:V$3173,SMALL(IF(B$3='Sheet 2'!S$5:S$3173,ROW('Sheet 2'!V$5:V$3173)-ROW('Sheet 2'!V$5)+1),ROW(2:2)))} -> 21.25 | C6: {=INDEX('Sheet 2'!V$5:V$3173,SMALL(IF(C$3='Sheet 2'!S$5:S$3173,ROW('Sheet 2'!V$5:V$3173)-ROW('Sheet 2'!V$5)+1),ROW(2:2)))} -> 852953750 | D6: {=INDEX('Sheet 2'!V$5:V$3173,SMALL(IF(D$3='Sheet 2'!S$5:S$3173,ROW('Sheet 2'!V$5:V$3173)-ROW('Sheet 2'!V$5)+1),ROW(2:2)))} -> 715627750 | E6: {=INDEX('Sheet 2'!V$5:V$3173,SMALL(IF(E$3='Sheet 2'!S$5:S$3173,ROW('Sheet 2'!V$5:V$3173)-ROW('Sheet 2'!V$5)+1),ROW(2:2)))} -> 400297000 | F6: {=INDEX('Sheet 2'!V$5:V$3173,SMALL(IF(F$3='Sheet 2'!S$5:S$3173,ROW('Sheet 2'!V$5:V$3173)-ROW('Sheet 2'!V$5)+1),ROW(2:2)))} -> 392509000 | I6: {=INDEX('Sheet 2'!V$5:V$3173,SMALL(IF(I$3='Sheet 2'!S$5:S$3173,ROW('Sheet 2'!V$5:V$3173)-ROW('Sheet 2'!V$5)+1),ROW(2:2)))} | K6: {=INDEX('Sheet 2'!V$5:V$3173,SMALL(IF(K$3='Sheet 2'!S$5:S$3173,ROW('Sheet 2'!V$5:V$3173)-ROW('Sheet 2'!V$5)+1),ROW(2:2)))} -> 2.1730807 | M6: {=INDEX('Sheet 2'!V$5:V$3173,SMALL(IF(M$3='Sheet 2'!S$5:S$3173,ROW('Sheet 2'!V$5:V$3173)-ROW('Sheet 2'!V$5)+1),ROW(2:2)))} -> 2.1398799 | O6: {=INDEX('Sheet 2'!V$5:V$3173,SMALL(IF(O$3='Sheet 2'!S$5:S$3173,ROW('Sheet 2'!V$5:V$3173)-ROW('Sheet 2'!V$5)+1),ROW(2:2)))} | Q6: {=INDEX('Sheet 2'!V$5:V$3173,SMALL(IF(Q$3='Sheet 2'!S$5:S$3173,ROW('Sheet 2'!V$5:V$3173)-ROW('Sheet 2'!V$5)+1),ROW(2:2)))} -> 115.7751 | S6: {=INDEX('Sheet 2'!V$5:V$3173,SMALL(IF(S$3='Sheet 2'!S$5:S$3173,ROW('Sheet 2'!V$5:V$3173)-ROW('Sheet 2'!V$5)+1),ROW(2:2)))} -> 77.090138 | U6: {=INDEX('Sheet 2'!V$5:V$3173,SMALL(IF(U$3='Sheet 2'!S$5:S$3173,ROW('Sheet 2'!V$5:V$3173)-ROW('Sheet 2'!V$5)+1),ROW(2:2)))} -> #DIV/0! | X6: {=INDEX('Sheet 2'!AA$13:AA$3173,SMALL(IF(X$3='Sheet 2'!X$13:X$3173,ROW('Sheet 2'!AA$13:AA$3173)-ROW('Sheet 2'!AA$13)+1),ROW(2:2)))} -> 3.4293805 | Y6: {=INDEX('Sheet 2'!AA$13:AA$3173,SMALL(IF(Y$3='Sheet 2'!X$13:X$3173,ROW('Sheet 2'!AA$13:AA$3173)-ROW('Sheet 2'!AA$13)+1),ROW(2:2)))} -> 1.3927086 | Z6: {=INDEX('Sheet 2'!AA$13:AA$3173,SMALL(IF(Z$3='Sheet 2'!X$13:X$3173,ROW('Sheet 2'!AA$13:AA$3173)-ROW('Sheet 2'!AA$13)+1),ROW(2:2)))} -> #DIV/0! | AA6: {=INDEX('Sheet 2'!V$5:V$3173,SMALL(IF(AA$3='Sheet 2'!S$5:S$3173,ROW('Sheet 2'!V$5:V$3173)-ROW('Sheet 2'!V$5)+1),ROW(2:2)))} -> 0.33299619 | AB6: {=INDEX('Sheet 2'!V$5:V$3173,SMALL(IF(AB$3='Sheet 2'!S$5:S$3173,ROW('Sheet 2'!V$5:V$3173)-ROW('Sheet 2'!V$5)+1),ROW(2:2)))} -> -0.34095779 | AC6: {=INDEX('Sheet 2'!V$5:V$3173,SMALL(IF(AC$3='Sheet 2'!S$5:S$3173,ROW('Sheet 2'!V$5:V$3173)-ROW('Sheet 2'!V$5)+1),ROW(2:2)))} -> -0.16725222 | AD6: {=INDEX('Sheet 2'!V$5:V$3173,SMALL(IF(AD$3='Sheet 2'!S$5:S$3173,ROW('Sheet 2'!V$5:V$3173)-ROW('Sheet 2'!V$5)+1),ROW(2:2)))} -> -0.28077865 | AE6: {=INDEX('Sheet 2'!V$5:V$3173,SMALL(IF(AE$3='Sheet 2'!S$5:S$3173,ROW('Sheet 2'!V$5:V$3173)-ROW('Sheet 2'!V$5)+1),ROW(2:2)))} -> -0.20160617 | AF6: {=INDEX('Sheet 2'!V$5:V$3173,SMALL(IF(AF$3='Sheet 2'!S$5:S$3173,ROW('Sheet 2'!V$5:V$3173)-ROW('Sheet 2'!V$5)+1),ROW(2:2)))} -> 0.59129365 | AH6: {=INDEX('Sheet 2'!AA$5:AA$3173,SMALL(IF(AH$3='Sheet 2'!X$5:X$3173,ROW('Sheet 2'!AA$5:AA$3173)-ROW('Sheet 2'!AA$5)+1),ROW(2:2)))} -> 250000000 | AJ6: {=INDEX('Sheet 2'!V$5:V$3173,SMALL(IF(AJ$3='Sheet 2'!S$5:S$3173,ROW('Sheet 2'!V$5:V$3173)-ROW('Sheet 2'!V$5)+1),ROW(2:2)))} -> #NUM! | AL6: {=INDEX('Sheet 2'!AA$5:AA$3173,SMALL(IF(AL$3='Sheet 2'!X$5:X$3173,ROW('Sheet 2'!AA$5:AA$3173)-ROW('Sheet 2'!AA$5)+1),ROW(2:2)))} -> 50275000 | AN6: {=INDEX('Sheet 2'!AA$5:AA$3173,SMALL(IF(AN$3='Sheet 2'!X$5:X$3173,ROW('Sheet 2'!AA$5:AA$3173)-ROW('Sheet 2'!AA$5)+1),ROW(2:2)))} -> 5.4
A7: {=INDEX('Sheet 2'!T$2:T$3173,SMALL(IF(A$3='Sheet 2'!$S$2:$S$3173,ROW('Sheet 2'!T$2:T$3173)-ROW('Sheet 2'!$T$2)+1),ROW(3:3)))} -> ADI | B7: {=INDEX('Sheet 2'!V$5:V$3173,SMALL(IF(B$3='Sheet 2'!S$5:S$3173,ROW('Sheet 2'!V$5:V$3173)-ROW('Sheet 2'!V$5)+1),ROW(3:3)))} -> 88.54 | C7: {=INDEX('Sheet 2'!V$5:V$3173,SMALL(IF(C$3='Sheet 2'!S$5:S$3173,ROW('Sheet 2'!V$5:V$3173)-ROW('Sheet 2'!V$5)+1),ROW(3:3)))} -> 0 | D7: {=INDEX('Sheet 2'!V$5:V$3173,SMALL(IF(D$3='Sheet 2'!S$5:S$3173,ROW('Sheet 2'!V$5:V$3173)-ROW('Sheet 2'!V$5)+1),ROW(3:3)))} -> 0 | E7: {=INDEX('Sheet 2'!V$5:V$3173,SMALL(IF(E$3='Sheet 2'!S$5:S$3173,ROW('Sheet 2'!V$5:V$3173)-ROW('Sheet 2'!V$5)+1),ROW(3:3)))} -> 0 | F7: {=INDEX('Sheet 2'!V$5:V$3173,SMALL(IF(F$3='Sheet 2'!S$5:S$3173,ROW('Sheet 2'!V$5:V$3173)-ROW('Sheet 2'!V$5)+1),ROW(3:3)))} -> 0 | I7: {=INDEX('Sheet 2'!V$5:V$3173,SMALL(IF(I$3='Sheet 2'!S$5:S$3173,ROW('Sheet 2'!V$5:V$3173)-ROW('Sheet 2'!V$5)+1),ROW(3:3)))} | K7: {=INDEX('Sheet 2'!V$5:V$3173,SMALL(IF(K$3='Sheet 2'!S$5:S$3173,ROW('Sheet 2'!V$5:V$3173)-ROW('Sheet 2'!V$5)+1),ROW(3:3)))} -> #DIV/0! | M7: {=INDEX('Sheet 2'!V$5:V$3173,SMALL(IF(M$3='Sheet 2'!S$5:S$3173,ROW('Sheet 2'!V$5:V$3173)-ROW('Sheet 2'!V$5)+1),ROW(3:3)))} -> #DIV/0! | O7: {=INDEX('Sheet 2'!V$5:V$3173,SMALL(IF(O$3='Sheet 2'!S$5:S$3173,ROW('Sheet 2'!V$5:V$3173)-ROW('Sheet 2'!V$5)+1),ROW(3:3)))} -> #DIV/0! | Q7: {=INDEX('Sheet 2'!V$5:V$3173,SMALL(IF(Q$3='Sheet 2'!S$5:S$3173,ROW('Sheet 2'!V$5:V$3173)-ROW('Sheet 2'!V$5)+1),ROW(3:3)))} -> #DIV/0! | S7: {=INDEX('Sheet 2'!V$5:V$3173,SMALL(IF(S$3='Sheet 2'!S$5:S$3173,ROW('Sheet 2'!V$5:V$3173)-ROW('Sheet 2'!V$5)+1),ROW(3:3)))} -> #DIV/0! | U7: {=INDEX('Sheet 2'!V$5:V$3173,SMALL(IF(U$3='Sheet 2'!S$5:S$3173,ROW('Sheet 2'!V$5:V$3173)-ROW('Sheet 2'!V$5)+1),ROW(3:3)))} -> 4.799019 | X7: {=INDEX('Sheet 2'!AA$13:AA$3173,SMALL(IF(X$3='Sheet 2'!X$13:X$3173,ROW('Sheet 2'!AA$13:AA$3173)-ROW('Sheet 2'!AA$13)+1),ROW(3:3)))} -> #DIV/0! | Y7: {=INDEX('Sheet 2'!AA$13:AA$3173,SMALL(IF(Y$3='Sheet 2'!X$13:X$3173,ROW('Sheet 2'!AA$13:AA$3173)-ROW('Sheet 2'!AA$13)+1),ROW(3:3)))} -> #DIV/0! | Z7: {=INDEX('Sheet 2'!AA$13:AA$3173,SMALL(IF(Z$3='Sheet 2'!X$13:X$3173,ROW('Sheet 2'!AA$13:AA$3173)-ROW('Sheet 2'!AA$13)+1),ROW(3:3)))} -> #DIV/0! | AA7: {=INDEX('Sheet 2'!V$5:V$3173,SMALL(IF(AA$3='Sheet 2'!S$5:S$3173,ROW('Sheet 2'!V$5:V$3173)-ROW('Sheet 2'!V$5)+1),ROW(3:3)))} -> #DIV/0! | AB7: {=INDEX('Sheet 2'!V$5:V$3173,SMALL(IF(AB$3='Sheet 2'!S$5:S$3173,ROW('Sheet 2'!V$5:V$3173)-ROW('Sheet 2'!V$5)+1),ROW(3:3)))} -> #DIV/0! | AC7: {=INDEX('Sheet 2'!V$5:V$3173,SMALL(IF(AC$3='Sheet 2'!S$5:S$3173,ROW('Sheet 2'!V$5:V$3173)-ROW('Sheet 2'!V$5)+1),ROW(3:3)))} -> #DIV/0! | AD7: {=INDEX('Sheet 2'!V$5:V$3173,SMALL(IF(AD$3='Sheet 2'!S$5:S$3173,ROW('Sheet 2'!V$5:V$3173)-ROW('Sheet 2'!V$5)+1),ROW(3:3)))} -> #DIV/0! | AE7: {=INDEX('Sheet 2'!V$5:V$3173,SMALL(IF(AE$3='Sheet 2'!S$5:S$3173,ROW('Sheet 2'!V$5:V$3173)-ROW('Sheet 2'!V$5)+1),ROW(3:3)))} -> #DIV/0! | AF7: {=INDEX('Sheet 2'!V$5:V$3173,SMALL(IF(AF$3='Sheet 2'!S$5:S$3173,ROW('Sheet 2'!V$5:V$3173)-ROW('Sheet 2'!V$5)+1),ROW(3:3)))} -> #DIV/0! | AH7: {=INDEX('Sheet 2'!AA$5:AA$3173,SMALL(IF(AH$3='Sheet 2'!X$5:X$3173,ROW('Sheet 2'!AA$5:AA$3173)-ROW('Sheet 2'!AA$5)+1),ROW(3:3)))} -> -0.037279356 | AJ7: {=INDEX('Sheet 2'!V$5:V$3173,SMALL(IF(AJ$3='Sheet 2'!S$5:S$3173,ROW('Sheet 2'!V$5:V$3173)-ROW('Sheet 2'!V$5)+1),ROW(3:3)))} -> #NUM! | AL7: {=INDEX('Sheet 2'!AA$5:AA$3173,SMALL(IF(AL$3='Sheet 2'!X$5:X$3173,ROW('Sheet 2'!AA$5:AA$3173)-ROW('Sheet 2'!AA$5)+1),ROW(3:3)))} -> -0.079519988 | AN7: {=INDEX('Sheet 2'!AA$5:AA$3173,SMALL(IF(AN$3='Sheet 2'!X$5:X$3173,ROW('Sheet 2'!AA$5:AA$3173)-ROW('Sheet 2'!AA$5)+1),ROW(3:3)))} -> -0.095128486
A8: {=INDEX('Sheet 2'!T$2:T$3173,SMALL(IF(A$3='Sheet 2'!$S$2:$S$3173,ROW('Sheet 2'!T$2:T$3173)-ROW('Sheet 2'!$T$2)+1),ROW(4:4)))} -> HPE | B8: {=INDEX('Sheet 2'!V$5:V$3173,SMALL(IF(B$3='Sheet 2'!S$5:S$3173,ROW('Sheet 2'!V$5:V$3173)-ROW('Sheet 2'!V$5)+1),ROW(4:4)))} -> 18.780001 | C8: {=INDEX('Sheet 2'!V$5:V$3173,SMALL(IF(C$3='Sheet 2'!S$5:S$3173,ROW('Sheet 2'!V$5:V$3173)-ROW('Sheet 2'!V$5)+1),ROW(4:4)))} -> 3.0545672e+10 | D8: {=INDEX('Sheet 2'!V$5:V$3173,SMALL(IF(D$3='Sheet 2'!S$5:S$3173,ROW('Sheet 2'!V$5:V$3173)-ROW('Sheet 2'!V$5)+1),ROW(4:4)))} -> 3.6827672e+10 | E8: {=INDEX('Sheet 2'!V$5:V$3173,SMALL(IF(E$3='Sheet 2'!S$5:S$3173,ROW('Sheet 2'!V$5:V$3173)-ROW('Sheet 2'!V$5)+1),ROW(4:4)))} -> 23951000000 | F8: {=INDEX('Sheet 2'!V$5:V$3173,SMALL(IF(F$3='Sheet 2'!S$5:S$3173,ROW('Sheet 2'!V$5:V$3173)-ROW('Sheet 2'!V$5)+1),ROW(4:4)))} -> 29643000000 | I8: {=INDEX('Sheet 2'!V$5:V$3173,SMALL(IF(I$3='Sheet 2'!S$5:S$3173,ROW('Sheet 2'!V$5:V$3173)-ROW('Sheet 2'!V$5)+1),ROW(4:4)))} -> 19.768422 | K8: {=INDEX('Sheet 2'!V$5:V$3173,SMALL(IF(K$3='Sheet 2'!S$5:S$3173,ROW('Sheet 2'!V$5:V$3173)-ROW('Sheet 2'!V$5)+1),ROW(4:4)))} -> 1.0304514 | M8: {=INDEX('Sheet 2'!V$5:V$3173,SMALL(IF(M$3='Sheet 2'!S$5:S$3173,ROW('Sheet 2'!V$5:V$3173)-ROW('Sheet 2'!V$5)+1),ROW(4:4)))} -> 1.2475046 | O8: {=INDEX('Sheet 2'!V$5:V$3173,SMALL(IF(O$3='Sheet 2'!S$5:S$3173,ROW('Sheet 2'!V$5:V$3173)-ROW('Sheet 2'!V$5)+1),ROW(4:4)))} | Q8: {=INDEX('Sheet 2'!V$5:V$3173,SMALL(IF(Q$3='Sheet 2'!S$5:S$3173,ROW('Sheet 2'!V$5:V$3173)-ROW('Sheet 2'!V$5)+1),ROW(4:4)))} -> 9.6378855 | S8: {=INDEX('Sheet 2'!V$5:V$3173,SMALL(IF(S$3='Sheet 2'!S$5:S$3173,ROW('Sheet 2'!V$5:V$3173)-ROW('Sheet 2'!V$5)+1),ROW(4:4)))} -> 32.024062 | U8: {=INDEX('Sheet 2'!V$5:V$3173,SMALL(IF(U$3='Sheet 2'!S$5:S$3173,ROW('Sheet 2'!V$5:V$3173)-ROW('Sheet 2'!V$5)+1),ROW(4:4)))} -> 2.8502006 | X8: {=INDEX('Sheet 2'!AA$13:AA$3173,SMALL(IF(X$3='Sheet 2'!X$13:X$3173,ROW('Sheet 2'!AA$13:AA$3173)-ROW('Sheet 2'!AA$13)+1),ROW(4:4)))} -> 1.1515703 | Y8: {=INDEX('Sheet 2'!AA$13:AA$3173,SMALL(IF(Y$3='Sheet 2'!X$13:X$3173,ROW('Sheet 2'!AA$13:AA$3173)-ROW('Sheet 2'!AA$13)+1),ROW(4:4)))} -> 2.4793816 | Z8: {=INDEX('Sheet 2'!AA$13:AA$3173,SMALL(IF(Z$3='Sheet 2'!X$13:X$3173,ROW('Sheet 2'!AA$13:AA$3173)-ROW('Sheet 2'!AA$13)+1),ROW(4:4)))} -> 0.44246017 | AA8: {=INDEX('Sheet 2'!V$5:V$3173,SMALL(IF(AA$3='Sheet 2'!S$5:S$3173,ROW('Sheet 2'!V$5:V$3173)-ROW('Sheet 2'!V$5)+1),ROW(4:4)))} -> 0.29227811 | AB8: {=INDEX('Sheet 2'!V$5:V$3173,SMALL(IF(AB$3='Sheet 2'!S$5:S$3173,ROW('Sheet 2'!V$5:V$3173)-ROW('Sheet 2'!V$5)+1),ROW(4:4)))} -> 0.051040718 | AC8: {=INDEX('Sheet 2'!V$5:V$3173,SMALL(IF(AC$3='Sheet 2'!S$5:S$3173,ROW('Sheet 2'!V$5:V$3173)-ROW('Sheet 2'!V$5)+1),ROW(4:4)))} -> 0.018520393 | AD8: {=INDEX('Sheet 2'!V$5:V$3173,SMALL(IF(AD$3='Sheet 2'!S$5:S$3173,ROW('Sheet 2'!V$5:V$3173)-ROW('Sheet 2'!V$5)+1),ROW(4:4)))} -> 0.057397572 | AE8: {=INDEX('Sheet 2'!V$5:V$3173,SMALL(IF(AE$3='Sheet 2'!S$5:S$3173,ROW('Sheet 2'!V$5:V$3173)-ROW('Sheet 2'!V$5)+1),ROW(4:4)))} -> 0.023149954 | AF8: {=INDEX('Sheet 2'!V$5:V$3173,SMALL(IF(AF$3='Sheet 2'!S$5:S$3173,ROW('Sheet 2'!V$5:V$3173)-ROW('Sheet 2'!V$5)+1),ROW(4:4)))} -> 0.45355856 | AH8: {=INDEX('Sheet 2'!AA$5:AA$3173,SMALL(IF(AH$3='Sheet 2'!X$5:X$3173,ROW('Sheet 2'!AA$5:AA$3173)-ROW('Sheet 2'!AA$5)+1),ROW(4:4)))} -> 392509000 | AJ8: {=INDEX('Sheet 2'!V$5:V$3173,SMALL(IF(AJ$3='Sheet 2'!S$5:S$3173,ROW('Sheet 2'!V$5:V$3173)-ROW('Sheet 2'!V$5)+1),ROW(4:4)))} -> #NUM! | AL8: {=INDEX('Sheet 2'!AA$5:AA$3173,SMALL(IF(AL$3='Sheet 2'!X$5:X$3173,ROW('Sheet 2'!AA$5:AA$3173)-ROW('Sheet 2'!AA$5)+1),ROW(4:4)))} -> -133829000 | AN8: {=INDEX('Sheet 2'!AA$5:AA$3173,SMALL(IF(AN$3='Sheet 2'!X$5:X$3173,ROW('Sheet 2'!AA$5:AA$3173)-ROW('Sheet 2'!AA$5)+1),ROW(4:4)))} -> -3.33
A9: {=INDEX('Sheet 2'!T$2:T$3173,SMALL(IF(A$3='Sheet 2'!$S$2:$S$3173,ROW('Sheet 2'!T$2:T$3173)-ROW('Sheet 2'!$T$2)+1),ROW(5:5)))} -> HPQ | B9: {=INDEX('Sheet 2'!V$5:V$3173,SMALL(IF(B$3='Sheet 2'!S$5:S$3173,ROW('Sheet 2'!V$5:V$3173)-ROW('Sheet 2'!V$5)+1),ROW(5:5)))} -> 23.280001 | C9: {=INDEX('Sheet 2'!V$5:V$3173,SMALL(IF(C$3='Sheet 2'!S$5:S$3173,ROW('Sheet 2'!V$5:V$3173)-ROW('Sheet 2'!V$5)+1),ROW(5:5)))} -> 3.8982362e+10 | D9: {=INDEX('Sheet 2'!V$5:V$3173,SMALL(IF(D$3='Sheet 2'!S$5:S$3173,ROW('Sheet 2'!V$5:V$3173)-ROW('Sheet 2'!V$5)+1),ROW(5:5)))} -> 4.1376362e+10 | E9: {=INDEX('Sheet 2'!V$5:V$3173,SMALL(IF(E$3='Sheet 2'!S$5:S$3173,ROW('Sheet 2'!V$5:V$3173)-ROW('Sheet 2'!V$5)+1),ROW(5:5)))} -> -2742000000 | F9: {=INDEX('Sheet 2'!V$5:V$3173,SMALL(IF(F$3='Sheet 2'!S$5:S$3173,ROW('Sheet 2'!V$5:V$3173)-ROW('Sheet 2'!V$5)+1),ROW(5:5)))} -> 53889000000 | I9: {=INDEX('Sheet 2'!V$5:V$3173,SMALL(IF(I$3='Sheet 2'!S$5:S$3173,ROW('Sheet 2'!V$5:V$3173)-ROW('Sheet 2'!V$5)+1),ROW(5:5)))} -> 10.077923 | K9: {=INDEX('Sheet 2'!V$5:V$3173,SMALL(IF(K$3='Sheet 2'!S$5:S$3173,ROW('Sheet 2'!V$5:V$3173)-ROW('Sheet 2'!V$5)+1),ROW(5:5)))} -> 0.72338254 | M9: {=INDEX('Sheet 2'!V$5:V$3173,SMALL(IF(M$3='Sheet 2'!S$5:S$3173,ROW('Sheet 2'!V$5:V$3173)-ROW('Sheet 2'!V$5)+1),ROW(5:5)))} -> -14.008753 | O9: {=INDEX('Sheet 2'!V$5:V$3173,SMALL(IF(O$3='Sheet 2'!S$5:S$3173,ROW('Sheet 2'!V$5:V$3173)-ROW('Sheet 2'!V$5)+1),ROW(5:5)))} -> 13.053587 | Q9: {=INDEX('Sheet 2'!V$5:V$3173,SMALL(IF(Q$3='Sheet 2'!S$5:S$3173,ROW('Sheet 2'!V$5:V$3173)-ROW('Sheet 2'!V$5)+1),ROW(5:5)))} -> 8.7293487 | S9: {=INDEX('Sheet 2'!V$5:V$3173,SMALL(IF(S$3='Sheet 2'!S$5:S$3173,ROW('Sheet 2'!V$5:V$3173)-ROW('Sheet 2'!V$5)+1),ROW(5:5)))} -> 36.910225 | U9: {=INDEX('Sheet 2'!V$5:V$3173,SMALL(IF(U$3='Sheet 2'!S$5:S$3173,ROW('Sheet 2'!V$5:V$3173)-ROW('Sheet 2'!V$5)+1),ROW(5:5)))} -> 3.6331437 | X9: {=INDEX('Sheet 2'!AA$13:AA$3173,SMALL(IF(X$3='Sheet 2'!X$13:X$3173,ROW('Sheet 2'!AA$13:AA$3173)-ROW('Sheet 2'!AA$13)+1),ROW(5:5)))} -> 0.96361007 | Y9: {=INDEX('Sheet 2'!AA$13:AA$3173,SMALL(IF(Y$3='Sheet 2'!X$13:X$3173,ROW('Sheet 2'!AA$13:AA$3173)-ROW('Sheet 2'!AA$13)+1),ROW(5:5)))} -> -8.9156743 | Z9: {=INDEX('Sheet 2'!AA$13:AA$3173,SMALL(IF(Z$3='Sheet 2'!X$13:X$3173,ROW('Sheet 2'!AA$13:AA$3173)-ROW('Sheet 2'!AA$13)+1),ROW(5:5)))} -> -1.8375104 | AA9: {=INDEX('Sheet 2'!V$5:V$3173,SMALL(IF(AA$3='Sheet 2'!S$5:S$3173,ROW('Sheet 2'!V$5:V$3173)-ROW('Sheet 2'!V$5)+1),ROW(5:5)))} -> 0.18393364 | AB9: {=INDEX('Sheet 2'!V$5:V$3173,SMALL(IF(AB$3='Sheet 2'!S$5:S$3173,ROW('Sheet 2'!V$5:V$3173)-ROW('Sheet 2'!V$5)+1),ROW(5:5)))} -> 0.071498822 | AC9: {=INDEX('Sheet 2'!V$5:V$3173,SMALL(IF(AC$3='Sheet 2'!S$5:S$3173,ROW('Sheet 2'!V$5:V$3173)-ROW('Sheet 2'!V$5)+1),ROW(5:5)))} -> 0.067472026 | AD9: {=INDEX('Sheet 2'!V$5:V$3173,SMALL(IF(AD$3='Sheet 2'!S$5:S$3173,ROW('Sheet 2'!V$5:V$3173)-ROW('Sheet 2'!V$5)+1),ROW(5:5)))} -> -1.0670174 | AE9: {=INDEX('Sheet 2'!V$5:V$3173,SMALL(IF(AE$3='Sheet 2'!S$5:S$3173,ROW('Sheet 2'!V$5:V$3173)-ROW('Sheet 2'!V$5)+1),ROW(5:5)))} -> 0.11967883 | AF9: {=INDEX('Sheet 2'!V$5:V$3173,SMALL(IF(AF$3='Sheet 2'!S$5:S$3173,ROW('Sheet 2'!V$5:V$3173)-ROW('Sheet 2'!V$5)+1),ROW(5:5)))} -> 1.6738573 | AH9: {=INDEX('Sheet 2'!AA$5:AA$3173,SMALL(IF(AH$3='Sheet 2'!X$5:X$3173,ROW('Sheet 2'!AA$5:AA$3173)-ROW('Sheet 2'!AA$5)+1),ROW(5:5)))} -> #DIV/0! | AJ9: {=INDEX('Sheet 2'!V$5:V$3173,SMALL(IF(AJ$3='Sheet 2'!S$5:S$3173,ROW('Sheet 2'!V$5:V$3173)-ROW('Sheet 2'!V$5)+1),ROW(5:5)))} -> #NUM! | AL9: {=INDEX('Sheet 2'!AA$5:AA$3173,SMALL(IF(AL$3='Sheet 2'!X$5:X$3173,ROW('Sheet 2'!AA$5:AA$3173)-ROW('Sheet 2'!AA$5)+1),ROW(5:5)))} -> #DIV/0! | AN9: {=INDEX('Sheet 2'!AA$5:AA$3173,SMALL(IF(AN$3='Sheet 2'!X$5:X$3173,ROW('Sheet 2'!AA$5:AA$3173)-ROW('Sheet 2'!AA$5)+1),ROW(5:5)))} -> #DIV/0!
A10: {=INDEX('Sheet 2'!T$2:T$3173,SMALL(IF(A$3='Sheet 2'!$S$2:$S$3173,ROW('Sheet 2'!T$2:T$3173)-ROW('Sheet 2'!$T$2)+1),ROW(6:6)))} -> NCR | B10: {=INDEX('Sheet 2'!V$5:V$3173,SMALL(IF(B$3='Sheet 2'!S$5:S$3173,ROW('Sheet 2'!V$5:V$3173)-ROW('Sheet 2'!V$5)+1),ROW(6:6)))} -> 32.98 | C10: {=INDEX('Sheet 2'!V$5:V$3173,SMALL(IF(C$3='Sheet 2'!S$5:S$3173,ROW('Sheet 2'!V$5:V$3173)-ROW('Sheet 2'!V$5)+1),ROW(6:6)))} -> 4.020262e+09 | D10: {=INDEX('Sheet 2'!V$5:V$3173,SMALL(IF(D$3='Sheet 2'!S$5:S$3173,ROW('Sheet 2'!V$5:V$3173)-ROW('Sheet 2'!V$5)+1),ROW(6:6)))} -> 6474262000 | E10: {=INDEX('Sheet 2'!V$5:V$3173,SMALL(IF(E$3='Sheet 2'!S$5:S$3173,ROW('Sheet 2'!V$5:V$3173)-ROW('Sheet 2'!V$5)+1),ROW(6:6)))} -> 719000000 | F10: {=INDEX('Sheet 2'!V$5:V$3173,SMALL(IF(F$3='Sheet 2'!S$5:S$3173,ROW('Sheet 2'!V$5:V$3173)-ROW('Sheet 2'!V$5)+1),ROW(6:6)))} -> 6516000000 | I10: {=INDEX('Sheet 2'!V$5:V$3173,SMALL(IF(I$3='Sheet 2'!S$5:S$3173,ROW('Sheet 2'!V$5:V$3173)-ROW('Sheet 2'!V$5)+1),ROW(6:6)))} -> 32.653465 | K10: {=INDEX('Sheet 2'!V$5:V$3173,SMALL(IF(K$3='Sheet 2'!S$5:S$3173,ROW('Sheet 2'!V$5:V$3173)-ROW('Sheet 2'!V$5)+1),ROW(6:6)))} -> 0.61698312 | M10: {=INDEX('Sheet 2'!V$5:V$3173,SMALL(IF(M$3='Sheet 2'!S$5:S$3173,ROW('Sheet 2'!V$5:V$3173)-ROW('Sheet 2'!V$5)+1),ROW(6:6)))} -> 5.5914631 | O10: {=INDEX('Sheet 2'!V$5:V$3173,SMALL(IF(O$3='Sheet 2'!S$5:S$3173,ROW('Sheet 2'!V$5:V$3173)-ROW('Sheet 2'!V$5)+1),ROW(6:6)))} -> 7.6334089 | Q10: {=INDEX('Sheet 2'!V$5:V$3173,SMALL(IF(Q$3='Sheet 2'!S$5:S$3173,ROW('Sheet 2'!V$5:V$3173)-ROW('Sheet 2'!V$5)+1),ROW(6:6)))} -> 5.176303 | S10: {=INDEX('Sheet 2'!V$5:V$3173,SMALL(IF(S$3='Sheet 2'!S$5:S$3173,ROW('Sheet 2'!V$5:V$3173)-ROW('Sheet 2'!V$5)+1),ROW(6:6)))} -> 24.616966 | U10: {=INDEX('Sheet 2'!V$5:V$3173,SMALL(IF(U$3='Sheet 2'!S$5:S$3173,ROW('Sheet 2'!V$5:V$3173)-ROW('Sheet 2'!V$5)+1),ROW(6:6)))} -> 6.6043093 | X10: {=INDEX('Sheet 2'!AA$13:AA$3173,SMALL(IF(X$3='Sheet 2'!X$13:X$3173,ROW('Sheet 2'!AA$13:AA$3173)-ROW('Sheet 2'!AA$13)+1),ROW(6:6)))} -> 1.3800414 | Y10: {=INDEX('Sheet 2'!AA$13:AA$3173,SMALL(IF(Y$3='Sheet 2'!X$13:X$3173,ROW('Sheet 2'!AA$13:AA$3173)-ROW('Sheet 2'!AA$13)+1),ROW(6:6)))} -> 11.648253 | Z10: {=INDEX('Sheet 2'!AA$13:AA$3173,SMALL(IF(Z$3='Sheet 2'!X$13:X$3173,ROW('Sheet 2'!AA$13:AA$3173)-ROW('Sheet 2'!AA$13)+1),ROW(6:6)))} -> 4.514844 | AA10: {=INDEX('Sheet 2'!V$5:V$3173,SMALL(IF(AA$3='Sheet 2'!S$5:S$3173,ROW('Sheet 2'!V$5:V$3173)-ROW('Sheet 2'!V$5)+1),ROW(6:6)))} -> 0.28606507 | AB10: {=INDEX('Sheet 2'!V$5:V$3173,SMALL(IF(AB$3='Sheet 2'!S$5:S$3173,ROW('Sheet 2'!V$5:V$3173)-ROW('Sheet 2'!V$5)+1),ROW(6:6)))} -> 0.035604665 | AC10: {=INDEX('Sheet 2'!V$5:V$3173,SMALL(IF(AC$3='Sheet 2'!S$5:S$3173,ROW('Sheet 2'!V$5:V$3173)-ROW('Sheet 2'!V$5)+1),ROW(6:6)))} -> 0.10374463 | AD10: {=INDEX('Sheet 2'!V$5:V$3173,SMALL(IF(AD$3='Sheet 2'!S$5:S$3173,ROW('Sheet 2'!V$5:V$3173)-ROW('Sheet 2'!V$5)+1),ROW(6:6)))} -> 0.34874107 | AE10: {=INDEX('Sheet 2'!V$5:V$3173,SMALL(IF(AE$3='Sheet 2'!S$5:S$3173,ROW('Sheet 2'!V$5:V$3173)-ROW('Sheet 2'!V$5)+1),ROW(6:6)))} -> 0.029939347 | AF10: {=INDEX('Sheet 2'!V$5:V$3173,SMALL(IF(AF$3='Sheet 2'!S$5:S$3173,ROW('Sheet 2'!V$5:V$3173)-ROW('Sheet 2'!V$5)+1),ROW(6:6)))} -> 0.84088269 | AH10: {=INDEX('Sheet 2'!AA$5:AA$3173,SMALL(IF(AH$3='Sheet 2'!X$5:X$3173,ROW('Sheet 2'!AA$5:AA$3173)-ROW('Sheet 2'!AA$5)+1),ROW(6:6)))} -> 0 | AJ10: {=INDEX('Sheet 2'!V$5:V$3173,SMALL(IF(AJ$3='Sheet 2'!S$5:S$3173,ROW('Sheet 2'!V$5:V$3173)-ROW('Sheet 2'!V$5)+1),ROW(6:6)))} -> #NUM! | AL10: {=INDEX('Sheet 2'!AA$5:AA$3173,SMALL(IF(AL$3='Sheet 2'!X$5:X$3173,ROW('Sheet 2'!AA$5:AA$3173)-ROW('Sheet 2'!AA$5)+1),ROW(6:6)))} -> 0 | AN10: {=INDEX('Sheet 2'!AA$5:AA$3173,SMALL(IF(AN$3='Sheet 2'!X$5:X$3173,ROW('Sheet 2'!AA$5:AA$3173)-ROW('Sheet 2'!AA$5)+1),ROW(6:6)))} -> 0
A11: {=INDEX('Sheet 2'!T$2:T$3173,SMALL(IF(A$3='Sheet 2'!$S$2:$S$3173,ROW('Sheet 2'!T$2:T$3173)-ROW('Sheet 2'!$T$2)+1),ROW(7:7)))} -> OSS | B11: {=INDEX('Sheet 2'!V$5:V$3173,SMALL(IF(B$3='Sheet 2'!S$5:S$3173,ROW('Sheet 2'!V$5:V$3173)-ROW('Sheet 2'!V$5)+1),ROW(7:7)))} -> 5.065 | C11: {=INDEX('Sheet 2'!V$5:V$3173,SMALL(IF(C$3='Sheet 2'!S$5:S$3173,ROW('Sheet 2'!V$5:V$3173)-ROW('Sheet 2'!V$5)+1),ROW(7:7)))} -> 39606036 | D11: {=INDEX('Sheet 2'!V$5:V$3173,SMALL(IF(D$3='Sheet 2'!S$5:S$3173,ROW('Sheet 2'!V$5:V$3173)-ROW('Sheet 2'!V$5)+1),ROW(7:7)))} -> 42892598 | E11: {=INDEX('Sheet 2'!V$5:V$3173,SMALL(IF(E$3='Sheet 2'!S$5:S$3173,ROW('Sheet 2'!V$5:V$3173)-ROW('Sheet 2'!V$5)+1),ROW(7:7)))} -> 6241885 | F11: {=INDEX('Sheet 2'!V$5:V$3173,SMALL(IF(F$3='Sheet 2'!S$5:S$3173,ROW('Sheet 2'!V$5:V$3173)-ROW('Sheet 2'!V$5)+1),ROW(7:7)))} -> 26980014 | I11: {=INDEX('Sheet 2'!V$5:V$3173,SMALL(IF(I$3='Sheet 2'!S$5:S$3173,ROW('Sheet 2'!V$5:V$3173)-ROW('Sheet 2'!V$5)+1),ROW(7:7)))} | K11: {=INDEX('Sheet 2'!V$5:V$3173,SMALL(IF(K$3='Sheet 2'!S$5:S$3173,ROW('Sheet 2'!V$5:V$3173)-ROW('Sheet 2'!V$5)+1),ROW(7:7)))} -> 1.4679768 | M11: {=INDEX('Sheet 2'!V$5:V$3173,SMALL(IF(M$3='Sheet 2'!S$5:S$3173,ROW('Sheet 2'!V$5:V$3173)-ROW('Sheet 2'!V$5)+1),ROW(7:7)))} -> #DIV/0! | O11: {=INDEX('Sheet 2'!V$5:V$3173,SMALL(IF(O$3='Sheet 2'!S$5:S$3173,ROW('Sheet 2'!V$5:V$3173)-ROW('Sheet 2'!V$5)+1),ROW(7:7)))} | Q11: {=INDEX('Sheet 2'!V$5:V$3173,SMALL(IF(Q$3='Sheet 2'!S$5:S$3173,ROW('Sheet 2'!V$5:V$3173)-ROW('Sheet 2'!V$5)+1),ROW(7:7)))} -> 459.76546 | S11: {=INDEX('Sheet 2'!V$5:V$3173,SMALL(IF(S$3='Sheet 2'!S$5:S$3173,ROW('Sheet 2'!V$5:V$3173)-ROW('Sheet 2'!V$5)+1),ROW(7:7)))} -> -447.01209 | U11: {=INDEX('Sheet 2'!V$5:V$3173,SMALL(IF(U$3='Sheet 2'!S$5:S$3173,ROW('Sheet 2'!V$5:V$3173)-ROW('Sheet 2'!V$5)+1),ROW(7:7)))} -> 3.3251578 | X11: {=INDEX('Sheet 2'!AA$13:AA$3173,SMALL(IF(X$3='Sheet 2'!X$13:X$3173,ROW('Sheet 2'!AA$13:AA$3173)-ROW('Sheet 2'!AA$13)+1),ROW(7:7)))} -> 1.1417412 | Y11: {=INDEX('Sheet 2'!AA$13:AA$3173,SMALL(IF(Y$3='Sheet 2'!X$13:X$3173,ROW('Sheet 2'!AA$13:AA$3173)-ROW('Sheet 2'!AA$13)+1),ROW(7:7)))} -> 1.2286032 | Z11: {=INDEX('Sheet 2'!AA$13:AA$3173,SMALL(IF(Z$3='Sheet 2'!X$13:X$3173,ROW('Sheet 2'!AA$13:AA$3173)-ROW('Sheet 2'!AA$13)+1),ROW(7:7)))} -> 0.13852941 | AA11: {=INDEX('Sheet 2'!V$5:V$3173,SMALL(IF(AA$3='Sheet 2'!S$5:S$3173,ROW('Sheet 2'!V$5:V$3173)-ROW('Sheet 2'!V$5)+1),ROW(7:7)))} -> 0.31959568 | AB11: {=INDEX('Sheet 2'!V$5:V$3173,SMALL(IF(AB$3='Sheet 2'!S$5:S$3173,ROW('Sheet 2'!V$5:V$3173)-ROW('Sheet 2'!V$5)+1),ROW(7:7)))} -> 0.0019291688 | AC11: {=INDEX('Sheet 2'!V$5:V$3173,SMALL(IF(AC$3='Sheet 2'!S$5:S$3173,ROW('Sheet 2'!V$5:V$3173)-ROW('Sheet 2'!V$5)+1),ROW(7:7)))} -> 0.00033198648 | AD11: {=INDEX('Sheet 2'!V$5:V$3173,SMALL(IF(AD$3='Sheet 2'!S$5:S$3173,ROW('Sheet 2'!V$5:V$3173)-ROW('Sheet 2'!V$5)+1),ROW(7:7)))} -> 0.008629793 | AE11: {=INDEX('Sheet 2'!V$5:V$3173,SMALL(IF(AE$3='Sheet 2'!S$5:S$3173,ROW('Sheet 2'!V$5:V$3173)-ROW('Sheet 2'!V$5)+1),ROW(7:7)))} -> 0.0070240684 | AF11: {=INDEX('Sheet 2'!V$5:V$3173,SMALL(IF(AF$3='Sheet 2'!S$5:S$3173,ROW('Sheet 2'!V$5:V$3173)-ROW('Sheet 2'!V$5)+1),ROW(7:7)))} -> 3.6409818 | AH11: {=INDEX('Sheet 2'!AA$5:AA$3173,SMALL(IF(AH$3='Sheet 2'!X$5:X$3173,ROW('Sheet 2'!AA$5:AA$3173)-ROW('Sheet 2'!AA$5)+1),ROW(7:7)))} -> -0.13899251 | AJ11: {=INDEX('Sheet 2'!V$5:V$3173,SMALL(IF(AJ$3='Sheet 2'!S$5:S$3173,ROW('Sheet 2'!V$5:V$3173)-ROW('Sheet 2'!V$5)+1),ROW(7:7)))} -> #NUM! | AL11: {=INDEX('Sheet 2'!AA$5:AA$3173,SMALL(IF(AL$3='Sheet 2'!X$5:X$3173,ROW('Sheet 2'!AA$5:AA$3173)-ROW('Sheet 2'!AA$5)+1),ROW(7:7)))} -> -0.077475183 | AN11: {=INDEX('Sheet 2'!AA$5:AA$3173,SMALL(IF(AN$3='Sheet 2'!X$5:X$3173,ROW('Sheet 2'!AA$5:AA$3173)-ROW('Sheet 2'!AA$5)+1),ROW(7:7)))} -> 0.085515098
A12: {=INDEX('Sheet 2'!T$2:T$3173,SMALL(IF(A$3='Sheet 2'!$S$2:$S$3173,ROW('Sheet 2'!T$2:T$3173)-ROW('Sheet 2'!$T$2)+1),ROW(8:8)))} -> PAR | B12: {=INDEX('Sheet 2'!V$5:V$3173,SMALL(IF(B$3='Sheet 2'!S$5:S$3173,ROW('Sheet 2'!V$5:V$3173)-ROW('Sheet 2'!V$5)+1),ROW(8:8)))} -> 11.91 | C12: {=INDEX('Sheet 2'!V$5:V$3173,SMALL(IF(C$3='Sheet 2'!S$5:S$3173,ROW('Sheet 2'!V$5:V$3173)-ROW('Sheet 2'!V$5)+1),ROW(8:8)))} -> 189952590 | D12: {=INDEX('Sheet 2'!V$5:V$3173,SMALL(IF(D$3='Sheet 2'!S$5:S$3173,ROW('Sheet 2'!V$5:V$3173)-ROW('Sheet 2'!V$5)+1),ROW(8:8)))} -> 184682590 | E12: {=INDEX('Sheet 2'!V$5:V$3173,SMALL(IF(E$3='Sheet 2'!S$5:S$3173,ROW('Sheet 2'!V$5:V$3173)-ROW('Sheet 2'!V$5)+1),ROW(8:8)))} -> 68986000 | F12: {=INDEX('Sheet 2'!V$5:V$3173,SMALL(IF(F$3='Sheet 2'!S$5:S$3173,ROW('Sheet 2'!V$5:V$3173)-ROW('Sheet 2'!V$5)+1),ROW(8:8)))} -> 232605000 | I12: {=INDEX('Sheet 2'!V$5:V$3173,SMALL(IF(I$3='Sheet 2'!S$5:S$3173,ROW('Sheet 2'!V$5:V$3173)-ROW('Sheet 2'!V$5)+1),ROW(8:8)))} | K12: {=INDEX('Sheet 2'!V$5:V$3173,SMALL(IF(K$3='Sheet 2'!S$5:S$3173,ROW('Sheet 2'!V$5:V$3173)-ROW('Sheet 2'!V$5)+1),ROW(8:8)))} -> 0.81663159 | M12: {=INDEX('Sheet 2'!V$5:V$3173,SMALL(IF(M$3='Sheet 2'!S$5:S$3173,ROW('Sheet 2'!V$5:V$3173)-ROW('Sheet 2'!V$5)+1),ROW(8:8)))} -> 2.7534948 | O12: {=INDEX('Sheet 2'!V$5:V$3173,SMALL(IF(O$3='Sheet 2'!S$5:S$3173,ROW('Sheet 2'!V$5:V$3173)-ROW('Sheet 2'!V$5)+1),ROW(8:8)))} | Q12: {=INDEX('Sheet 2'!V$5:V$3173,SMALL(IF(Q$3='Sheet 2'!S$5:S$3173,ROW('Sheet 2'!V$5:V$3173)-ROW('Sheet 2'!V$5)+1),ROW(8:8)))} -> 47.871116 | S12: {=INDEX('Sheet 2'!V$5:V$3173,SMALL(IF(S$3='Sheet 2'!S$5:S$3173,ROW('Sheet 2'!V$5:V$3173)-ROW('Sheet 2'!V$5)+1),ROW(8:8)))} -> -142.94318 | U12: {=INDEX('Sheet 2'!V$5:V$3173,SMALL(IF(U$3='Sheet 2'!S$5:S$3173,ROW('Sheet 2'!V$5:V$3173)-ROW('Sheet 2'!V$5)+1),ROW(8:8)))} -> 7.9715845 | X12: {=INDEX('Sheet 2'!AA$13:AA$3173,SMALL(IF(X$3='Sheet 2'!X$13:X$3173,ROW('Sheet 2'!AA$13:AA$3173)-ROW('Sheet 2'!AA$13)+1),ROW(8:8)))} -> 1.6735686 | Y12: {=INDEX('Sheet 2'!AA$13:AA$3173,SMALL(IF(Y$3='Sheet 2'!X$13:X$3173,ROW('Sheet 2'!AA$13:AA$3173)-ROW('Sheet 2'!AA$13)+1),ROW(8:8)))} -> 1.661484 | Z12: {=INDEX('Sheet 2'!AA$13:AA$3173,SMALL(IF(Z$3='Sheet 2'!X$13:X$3173,ROW('Sheet 2'!AA$13:AA$3173)-ROW('Sheet 2'!AA$13)+1),ROW(8:8)))} -> 0.0035863718 | AA12: {=INDEX('Sheet 2'!V$5:V$3173,SMALL(IF(AA$3='Sheet 2'!S$5:S$3173,ROW('Sheet 2'!V$5:V$3173)-ROW('Sheet 2'!V$5)+1),ROW(8:8)))} -> 0.22712323 | AB12: {=INDEX('Sheet 2'!V$5:V$3173,SMALL(IF(AB$3='Sheet 2'!S$5:S$3173,ROW('Sheet 2'!V$5:V$3173)-ROW('Sheet 2'!V$5)+1),ROW(8:8)))} -> -0.014556867 | AC12: {=INDEX('Sheet 2'!V$5:V$3173,SMALL(IF(AC$3='Sheet 2'!S$5:S$3173,ROW('Sheet 2'!V$5:V$3173)-ROW('Sheet 2'!V$5)+1),ROW(8:8)))} -> -0.00052019518 | AD12: {=INDEX('Sheet 2'!V$5:V$3173,SMALL(IF(AD$3='Sheet 2'!S$5:S$3173,ROW('Sheet 2'!V$5:V$3173)-ROW('Sheet 2'!V$5)+1),ROW(8:8)))} -> -0.047067655 | AE12: {=INDEX('Sheet 2'!V$5:V$3173,SMALL(IF(AE$3='Sheet 2'!S$5:S$3173,ROW('Sheet 2'!V$5:V$3173)-ROW('Sheet 2'!V$5)+1),ROW(8:8)))} -> -0.028328683 | AF12: {=INDEX('Sheet 2'!V$5:V$3173,SMALL(IF(AF$3='Sheet 2'!S$5:S$3173,ROW('Sheet 2'!V$5:V$3173)-ROW('Sheet 2'!V$5)+1),ROW(8:8)))} -> 1.9460701 | AH12: {=INDEX('Sheet 2'!AA$5:AA$3173,SMALL(IF(AH$3='Sheet 2'!X$5:X$3173,ROW('Sheet 2'!AA$5:AA$3173)-ROW('Sheet 2'!AA$5)+1),ROW(8:8)))} -> 29643000000 | AJ12: {=INDEX('Sheet 2'!V$5:V$3173,SMALL(IF(AJ$3='Sheet 2'!S$5:S$3173,ROW('Sheet 2'!V$5:V$3173)-ROW('Sheet 2'!V$5)+1),ROW(8:8)))} -> #NUM! | AL12: {=INDEX('Sheet 2'!AA$5:AA$3173,SMALL(IF(AL$3='Sheet 2'!X$5:X$3173,ROW('Sheet 2'!AA$5:AA$3173)-ROW('Sheet 2'!AA$5)+1),ROW(8:8)))} -> 1513000000 | AN12: {=INDEX('Sheet 2'!AA$5:AA$3173,SMALL(IF(AN$3='Sheet 2'!X$5:X$3173,ROW('Sheet 2'!AA$5:AA$3173)-ROW('Sheet 2'!AA$5)+1),ROW(8:8)))} -> 0.95
A13: {=INDEX('Sheet 2'!T$2:T$3173,SMALL(IF(A$3='Sheet 2'!$S$2:$S$3173,ROW('Sheet 2'!T$2:T$3173)-ROW('Sheet 2'!$T$2)+1),ROW(9:9)))} -> TDC | B13: {=INDEX('Sheet 2'!V$5:V$3173,SMALL(IF(B$3='Sheet 2'!S$5:S$3173,ROW('Sheet 2'!V$5:V$3173)-ROW('Sheet 2'!V$5)+1),ROW(9:9)))} -> 42.139999 | C13: {=INDEX('Sheet 2'!V$5:V$3173,SMALL(IF(C$3='Sheet 2'!S$5:S$3173,ROW('Sheet 2'!V$5:V$3173)-ROW('Sheet 2'!V$5)+1),ROW(9:9)))} -> 5.3012119e+09 | D13: {=INDEX('Sheet 2'!V$5:V$3173,SMALL(IF(D$3='Sheet 2'!S$5:S$3173,ROW('Sheet 2'!V$5:V$3173)-ROW('Sheet 2'!V$5)+1),ROW(9:9)))} -> 4.9902119e+09 | E13: {=INDEX('Sheet 2'!V$5:V$3173,SMALL(IF(E$3='Sheet 2'!S$5:S$3173,ROW('Sheet 2'!V$5:V$3173)-ROW('Sheet 2'!V$5)+1),ROW(9:9)))} -> 668000000 | F13: {=INDEX('Sheet 2'!V$5:V$3173,SMALL(IF(F$3='Sheet 2'!S$5:S$3173,ROW('Sheet 2'!V$5:V$3173)-ROW('Sheet 2'!V$5)+1),ROW(9:9)))} -> 2156000000 | I13: {=INDEX('Sheet 2'!V$5:V$3173,SMALL(IF(I$3='Sheet 2'!S$5:S$3173,ROW('Sheet 2'!V$5:V$3173)-ROW('Sheet 2'!V$5)+1),ROW(9:9)))} | K13: {=INDEX('Sheet 2'!V$5:V$3173,SMALL(IF(K$3='Sheet 2'!S$5:S$3173,ROW('Sheet 2'!V$5:V$3173)-ROW('Sheet 2'!V$5)+1),ROW(9:9)))} -> 2.4588181 | M13: {=INDEX('Sheet 2'!V$5:V$3173,SMALL(IF(M$3='Sheet 2'!S$5:S$3173,ROW('Sheet 2'!V$5:V$3173)-ROW('Sheet 2'!V$5)+1),ROW(9:9)))} -> 7.6520687 | O13: {=INDEX('Sheet 2'!V$5:V$3173,SMALL(IF(O$3='Sheet 2'!S$5:S$3173,ROW('Sheet 2'!V$5:V$3173)-ROW('Sheet 2'!V$5)+1),ROW(9:9)))} -> 18.798624 | Q13: {=INDEX('Sheet 2'!V$5:V$3173,SMALL(IF(Q$3='Sheet 2'!S$5:S$3173,ROW('Sheet 2'!V$5:V$3173)-ROW('Sheet 2'!V$5)+1),ROW(9:9)))} -> 13.581243 | S13: {=INDEX('Sheet 2'!V$5:V$3173,SMALL(IF(S$3='Sheet 2'!S$5:S$3173,ROW('Sheet 2'!V$5:V$3173)-ROW('Sheet 2'!V$5)+1),ROW(9:9)))} -> 51.981374 | U13: {=INDEX('Sheet 2'!V$5:V$3173,SMALL(IF(U$3='Sheet 2'!S$5:S$3173,ROW('Sheet 2'!V$5:V$3173)-ROW('Sheet 2'!V$5)+1),ROW(9:9)))} -> 2.28219 | X13: {=INDEX('Sheet 2'!AA$13:AA$3173,SMALL(IF(X$3='Sheet 2'!X$13:X$3173,ROW('Sheet 2'!AA$13:AA$3173)-ROW('Sheet 2'!AA$13)+1),ROW(9:9)))} -> 1.7953668 | Y13: {=INDEX('Sheet 2'!AA$13:AA$3173,SMALL(IF(Y$3='Sheet 2'!X$13:X$3173,ROW('Sheet 2'!AA$13:AA$3173)-ROW('Sheet 2'!AA$13)+1),ROW(9:9)))} -> 3.0140056 | Z13: {=INDEX('Sheet 2'!AA$13:AA$3173,SMALL(IF(Z$3='Sheet 2'!X$13:X$3173,ROW('Sheet 2'!AA$13:AA$3173)-ROW('Sheet 2'!AA$13)+1),ROW(9:9)))} -> 0.62309368 | AA13: {=INDEX('Sheet 2'!V$5:V$3173,SMALL(IF(AA$3='Sheet 2'!S$5:S$3173,ROW('Sheet 2'!V$5:V$3173)-ROW('Sheet 2'!V$5)+1),ROW(9:9)))} -> 0.47402597 | AB13: {=INDEX('Sheet 2'!V$5:V$3173,SMALL(IF(AB$3='Sheet 2'!S$5:S$3173,ROW('Sheet 2'!V$5:V$3173)-ROW('Sheet 2'!V$5)+1),ROW(9:9)))} -> -0.031076067 | AC13: {=INDEX('Sheet 2'!V$5:V$3173,SMALL(IF(AC$3='Sheet 2'!S$5:S$3173,ROW('Sheet 2'!V$5:V$3173)-ROW('Sheet 2'!V$5)+1),ROW(9:9)))} -> 0.029684601 | AD13: {=INDEX('Sheet 2'!V$5:V$3173,SMALL(IF(AD$3='Sheet 2'!S$5:S$3173,ROW('Sheet 2'!V$5:V$3173)-ROW('Sheet 2'!V$5)+1),ROW(9:9)))} -> -0.083411142 | AE13: {=INDEX('Sheet 2'!V$5:V$3173,SMALL(IF(AE$3='Sheet 2'!S$5:S$3173,ROW('Sheet 2'!V$5:V$3173)-ROW('Sheet 2'!V$5)+1),ROW(9:9)))} -> -0.027674515 | AF13: {=INDEX('Sheet 2'!V$5:V$3173,SMALL(IF(AF$3='Sheet 2'!S$5:S$3173,ROW('Sheet 2'!V$5:V$3173)-ROW('Sheet 2'!V$5)+1),ROW(9:9)))} -> 0.8905411 | AH13: {=INDEX('Sheet 2'!AA$5:AA$3173,SMALL(IF(AH$3='Sheet 2'!X$5:X$3173,ROW('Sheet 2'!AA$5:AA$3173)-ROW('Sheet 2'!AA$5)+1),ROW(9:9)))} -> -0.13357794 | AJ13: {=INDEX('Sheet 2'!V$5:V$3173,SMALL(IF(AJ$3='Sheet 2'!S$5:S$3173,ROW('Sheet 2'!V$5:V$3173)-ROW('Sheet 2'!V$5)+1),ROW(9:9)))} -> #NUM! | AL13: {=INDEX('Sheet 2'!AA$5:AA$3173,SMALL(IF(AL$3='Sheet 2'!X$5:X$3173,ROW('Sheet 2'!AA$5:AA$3173)-ROW('Sheet 2'!AA$5)+1),ROW(9:9)))} -> -0.13775278 | AN13: {=INDEX('Sheet 2'!AA$5:AA$3173,SMALL(IF(AN$3='Sheet 2'!X$5:X$3173,ROW('Sheet 2'!AA$5:AA$3173)-ROW('Sheet 2'!AA$5)+1),ROW(9:9)))} -> -0.10836084
A14: {=INDEX('Sheet 2'!T$2:T$3173,SMALL(IF(A$3='Sheet 2'!$S$2:$S$3173,ROW('Sheet 2'!T$2:T$3173)-ROW('Sheet 2'!$T$2)+1),ROW(10:10)))} -> XPLR | B14: {=INDEX('Sheet 2'!V$5:V$3173,SMALL(IF(B$3='Sheet 2'!S$5:S$3173,ROW('Sheet 2'!V$5:V$3173)-ROW('Sheet 2'!V$5)+1),ROW(10:10)))} -> 3.65 | C14: {=INDEX('Sheet 2'!V$5:V$3173,SMALL(IF(C$3='Sheet 2'!S$5:S$3173,ROW('Sheet 2'!V$5:V$3173)-ROW('Sheet 2'!V$5)+1),ROW(10:10)))} -> 40137079 | D14: {=INDEX('Sheet 2'!V$5:V$3173,SMALL(IF(D$3='Sheet 2'!S$5:S$3173,ROW('Sheet 2'!V$5:V$3173)-ROW('Sheet 2'!V$5)+1),ROW(10:10)))} -> 54437079 | E14: {=INDEX('Sheet 2'!V$5:V$3173,SMALL(IF(E$3='Sheet 2'!S$5:S$3173,ROW('Sheet 2'!V$5:V$3173)-ROW('Sheet 2'!V$5)+1),ROW(10:10)))} -> 30655000 | F14: {=INDEX('Sheet 2'!V$5:V$3173,SMALL(IF(F$3='Sheet 2'!S$5:S$3173,ROW('Sheet 2'!V$5:V$3173)-ROW('Sheet 2'!V$5)+1),ROW(10:10)))} -> 83548000 | I14: {=INDEX('Sheet 2'!V$5:V$3173,SMALL(IF(I$3='Sheet 2'!S$5:S$3173,ROW('Sheet 2'!V$5:V$3173)-ROW('Sheet 2'!V$5)+1),ROW(10:10)))} -> 73 | K14: {=INDEX('Sheet 2'!V$5:V$3173,SMALL(IF(K$3='Sheet 2'!S$5:S$3173,ROW('Sheet 2'!V$5:V$3173)-ROW('Sheet 2'!V$5)+1),ROW(10:10)))} -> 0.48040742 | M14: {=INDEX('Sheet 2'!V$5:V$3173,SMALL(IF(M$3='Sheet 2'!S$5:S$3173,ROW('Sheet 2'!V$5:V$3173)-ROW('Sheet 2'!V$5)+1),ROW(10:10)))} -> 1.3122265 | O14: {=INDEX('Sheet 2'!V$5:V$3173,SMALL(IF(O$3='Sheet 2'!S$5:S$3173,ROW('Sheet 2'!V$5:V$3173)-ROW('Sheet 2'!V$5)+1),ROW(10:10)))} | Q14: {=INDEX('Sheet 2'!V$5:V$3173,SMALL(IF(Q$3='Sheet 2'!S$5:S$3173,ROW('Sheet 2'!V$5:V$3173)-ROW('Sheet 2'!V$5)+1),ROW(10:10)))} | S14: {=INDEX('Sheet 2'!V$5:V$3173,SMALL(IF(S$3='Sheet 2'!S$5:S$3173,ROW('Sheet 2'!V$5:V$3173)-ROW('Sheet 2'!V$5)+1),ROW(10:10)))} -> 60.418512 | U14: {=INDEX('Sheet 2'!V$5:V$3173,SMALL(IF(U$3='Sheet 2'!S$5:S$3173,ROW('Sheet 2'!V$5:V$3173)-ROW('Sheet 2'!V$5)+1),ROW(10:10)))} -> #NUM! | X14: {=INDEX('Sheet 2'!AA$13:AA$3173,SMALL(IF(X$3='Sheet 2'!X$13:X$3173,ROW('Sheet 2'!AA$13:AA$3173)-ROW('Sheet 2'!AA$13)+1),ROW(10:10)))} -> 1.6510462 | Y14: {=INDEX('Sheet 2'!AA$13:AA$3173,SMALL(IF(Y$3='Sheet 2'!X$13:X$3173,ROW('Sheet 2'!AA$13:AA$3173)-ROW('Sheet 2'!AA$13)+1),ROW(10:10)))} -> 1.9037288 | Z14: {=INDEX('Sheet 2'!AA$13:AA$3173,SMALL(IF(Z$3='Sheet 2'!X$13:X$3173,ROW('Sheet 2'!AA$13:AA$3173)-ROW('Sheet 2'!AA$13)+1),ROW(10:10)))} -> #DIV/0! | AA14: {=INDEX('Sheet 2'!V$5:V$3173,SMALL(IF(AA$3='Sheet 2'!S$5:S$3173,ROW('Sheet 2'!V$5:V$3173)-ROW('Sheet 2'!V$5)+1),ROW(10:10)))} -> 0.29822378 | AB14: {=INDEX('Sheet 2'!V$5:V$3173,SMALL(IF(AB$3='Sheet 2'!S$5:S$3173,ROW('Sheet 2'!V$5:V$3173)-ROW('Sheet 2'!V$5)+1),ROW(10:10)))} -> 0.0053861253 | AC14: {=INDEX('Sheet 2'!V$5:V$3173,SMALL(IF(AC$3='Sheet 2'!S$5:S$3173,ROW('Sheet 2'!V$5:V$3173)-ROW('Sheet 2'!V$5)+1),ROW(10:10)))} -> 0.0081390338 | AD14: {=INDEX('Sheet 2'!V$5:V$3173,SMALL(IF(AD$3='Sheet 2'!S$5:S$3173,ROW('Sheet 2'!V$5:V$3173)-ROW('Sheet 2'!V$5)+1),ROW(10:10)))} -> 0.015025418 | AE14: {=INDEX('Sheet 2'!V$5:V$3173,SMALL(IF(AE$3='Sheet 2'!S$5:S$3173,ROW('Sheet 2'!V$5:V$3173)-ROW('Sheet 2'!V$5)+1),ROW(10:10)))} -> 0.0078926252 | AF14: {=INDEX('Sheet 2'!V$5:V$3173,SMALL(IF(AF$3='Sheet 2'!S$5:S$3173,ROW('Sheet 2'!V$5:V$3173)-ROW('Sheet 2'!V$5)+1),ROW(10:10)))} -> 1.4653623 | AH14: {=INDEX('Sheet 2'!AA$5:AA$3173,SMALL(IF(AH$3='Sheet 2'!X$5:X$3173,ROW('Sheet 2'!AA$5:AA$3173)-ROW('Sheet 2'!AA$5)+1),ROW(10:10)))} -> 53889000000 | AJ14: {=INDEX('Sheet 2'!V$5:V$3173,SMALL(IF(AJ$3='Sheet 2'!S$5:S$3173,ROW('Sheet 2'!V$5:V$3173)-ROW('Sheet 2'!V$5)+1),ROW(10:10)))} -> #NUM! | AL14: {=INDEX('Sheet 2'!AA$5:AA$3173,SMALL(IF(AL$3='Sheet 2'!X$5:X$3173,ROW('Sheet 2'!AA$5:AA$3173)-ROW('Sheet 2'!AA$5)+1),ROW(10:10)))} -> 3853000000 | AN14: {=INDEX('Sheet 2'!AA$5:AA$3173,SMALL(IF(AN$3='Sheet 2'!X$5:X$3173,ROW('Sheet 2'!AA$5:AA$3173)-ROW('Sheet 2'!AA$5)+1),ROW(10:10)))} -> 2.31

Sheet Sheet 2
A2: 1 | S2: Symbol | T2: CCUR | V2: USD
D4: Income Statement | F4: 2016-10 | G4: 2017-01 | H4: 2017-04 | I4: 2017-07 | J4: 2017-10 | L4: 2013 | M4: 2014 | N4: 2015 | O4: 2016 | P4: 2017 | Q4: TTM | S4: Quote | X4: Growth | AA4: 5-Year Average | AC4: Key Ratios ― Growth, YOY | AF4: =M4 -> 2014 | AG4: =N4 -> 2015 | AH4: =O4 -> 2016 | AI4: =P4 -> 2017
D5: Revenue | F5: 15547000 | G5: 14981000 | H5: -15997000 | I5: 7870000 | L5: 63444000 | M5: 71171000 | N5: 64459000 | O5: 61149000 | P5: 27647000 | Q5: 250000000 | S5: Last Price | V5: 5.42 | X5: Revenue | AA5: =IF(AA4="Year over Year",AI5,IF(AA4="3-Year Average",AVERAGE(AH5:AI5),IF(AA4="5-Year Average",AVERAGE(AF5:AI5),""))) -> -0.14293524 | AC5: Revenue % | AF5: =IF(AND(M5>0,L5>0,L5<>""),M5/L5-1,IF(AND(L5<0,M5<0,L5<>""),(M5-L5)/ABS(L5),IF(AND(L5>0,M5<0,L5<>""),"L",IF(AND(L5<0,M5>0,L5<>""),"P","")))) -> 0.12179245 | AG5: =IF(AND(N5>0,M5>0,M5<>""),N5/M5-1,IF(AND(M5<0,N5<0,M5<>""),(N5-M5)/ABS(M5),IF(AND(M5>0,N5<0,M5<>""),"L",IF(AND(M5<0,N5>0,M5<>""),"P","")))) -> -0.094308075 | AH5: =IF(AND(O5>0,N5>0,N5<>""),O5/N5-1,IF(AND(N5<0,O5<0,N5<>""),(O5-N5)/ABS(N5),IF(AND(N5>0,O5<0,N5<>""),"L",IF(AND(N5<0,O5>0,N5<>""),"P","")))) -> -0.051350471 | AI5: =IF(AND(P5>0,O5>0,O5<>""),P5/O5-1,IF(AND(O5<0,P5<0,O5<>""),(P5-O5)/ABS(O5),IF(AND(O5>0,P5<0,O5<>""),"L",IF(AND(O5<0,P5>0,O5<>""),"P","")))) -> -0.54787486
D6: Cost of revenue | F6: 6098000 | G6: 6477000 | H6: -6056000 | I6: 3220000 | L6: 26607000 | M6: 30758000 | N6: 28069000 | O6: 24893000 | P6: 12452000 | S6: Market Capitalization | V6: =V5*Q13 -> 50682702 | X6: Operating Income | AA6: =IF(AA4="Year over Year",AI6,IF(AA4="3-Year Average",AVERAGE(AH6:AI6),IF(AA4="5-Year Average",AVERAGE(AF6:AI6),""))) -> 0.095715838 | AC6: Operating Income % | AF6: =IF(AND(M8>0,L8>0,L8<>""),M8/L8-1,IF(AND(L8<0,M8<0,L8<>""),(M8-L8)/ABS(L8),IF(AND(L8>0,M8<0,L8<>""),"L",IF(AND(L8<0,M8>0,L8<>""),"P","")))) -> 0.052631579 | AG6: =IF(AND(N8>0,M8>0,M8<>""),N8/M8-1,IF(AND(M8<0,N8<0,M8<>""),(N8-M8)/ABS(M8),IF(AND(M8>0,N8<0,M8<>""),"L",IF(AND(M8<0,N8>0,M8<>""),"P","")))) -> -0.82150943 | AH6: =IF(AND(O8>0,N8>0,N8<>""),O8/N8-1,IF(AND(N8<0,O8<0,N8<>""),(O8-N8)/ABS(N8),IF(AND(N8>0,O8<0,N8<>""),"L",IF(AND(N8<0,O8>0,N8<>""),"P","")))) -> 1.0560254 | AI6: =IF(AND(P8>0,O8>0,O8<>""),P8/O8-1,IF(AND(O8<0,P8<0,O8<>""),(P8-O8)/ABS(O8),IF(AND(O8>0,P8<0,O8<>""),"L",IF(AND(O8<0,P8>0,O8<>""),"P","")))) -> L
D7: Gross profit | F7: 9449000 | G7: 8504000 | H7: -9941000 | I7: 4650000 | J7: 0 | L7: 36837000 | M7: 40413000 | N7: 36390000 | O7: 36256000 | P7: 15195000 | Q7: 0 | S7: Enterprise Value | V7: =V6+(J21+J23)-J17 -> -6864298.2 | X7: Net Income | AA7: =IF(AA4="Year over Year",AI7,IF(AA4="3-Year Average",AVERAGE(AH7:AI7),IF(AA4="5-Year Average",AVERAGE(AF7:AI7),""))) -> -13.927713 | AC7: Net Income % | AF7: =IF(AND(M9>0,L9>0,L9<>""),M9/L9-1,IF(AND(L9<0,M9<0,L9<>""),(M9-L9)/ABS(L9),IF(AND(L9>0,M9<0,L9<>""),"L",IF(AND(L9<0,M9>0,L9<>""),"P","")))) -> 3.3561676 | AG7: =IF(AND(N9>0,M9>0,M9<>""),N9/M9-1,IF(AND(M9<0,N9<0,M9<>""),(N9-M9)/ABS(M9),IF(AND(M9>0,N9<0,M9<>""),"L",IF(AND(M9<0,N9>0,M9<>""),"P","")))) -> L | AH7: =IF(AND(O9>0,N9>0,N9<>""),O9/N9-1,IF(AND(N9<0,O9<0,N9<>""),(O9-N9)/ABS(N9),IF(AND(N9>0,O9<0,N9<>""),"L",IF(AND(N9<0,O9>0,N9<>""),"P","")))) -> -31.211594 | AI7: =IF(AND(P9>0,O9>0,O9<>""),P9/O9-1,IF(AND(O9<0,P9<0,O9<>""),(P9-O9)/ABS(O9),IF(AND(O9>0,P9<0,O9<>""),"L",IF(AND(O9<0,P9>0,O9<>""),"P","")))) -> P
D8: Operating income | F8: -48000 | G8: -1573000 | H8: -7672000 | I8: -1115000 | J8: -3859000 | L8: 5035000 | M8: 5300000 | N8: 946000 | O8: 1945000 | P8: -12236000 | Q8: -29791000 | S8: Book Value | V8: =J20-J24 -> 62117000 | X8: Earnings Per Share | AA8: =IF(AA4="Year over Year",AI8,IF(AA4="3-Year Average",AVERAGE(AH8:AI8),IF(AA4="5-Year Average",AVERAGE(AF8:AI8),""))) -> -13.002551 | AC8: Earnings per share % | AF8: =IF(AND(M10>0,L10>0,L10<>""),M10/L10-1,IF(AND(L10<0,M10<0,L10<>""),(M10-L10)/ABS(L10),IF(AND(L10>0,M10<0,L10<>""),"L",IF(AND(L10<0,M10>0,L10<>""),"P","")))) -> 3.244898 | AG8: =IF(AND(N10>0,M10>0,M10<>""),N10/M10-1,IF(AND(M10<0,N10<0,M10<>""),(N10-M10)/ABS(M10),IF(AND(M10>0,N10<0,M10<>""),"L",IF(AND(M10<0,N10>0,M10<>""),"P","")))) -> L | AH8: =IF(AND(O10>0,N10>0,N10<>""),O10/N10-1,IF(AND(N10<0,O10<0,N10<>""),(O10-N10)/ABS(N10),IF(AND(N10>0,O10<0,N10<>""),"L",IF(AND(N10<0,O10>0,N10<>""),"P","")))) -> -29.25 | AI8: =IF(AND(P10>0,O10>0,O10<>""),P10/O10-1,IF(AND(O10<0,P10<0,O10<>""),(P10-O10)/ABS(O10),IF(AND(O10>0,P10<0,O10<>""),"L",IF(AND(O10<0,P10>0,O10<>""),"P","")))) -> P
D9: Net income | F9: -88000 | G9: -1658000 | H9: 33055000 | I9: -1010000 | J9: 19888000 | L9: 4248000 | M9: 18505000 | N9: -345000 | O9: -11113000 | P9: 28381000 | Q9: 50275000 | S9: Type | V9: =IF(V6>10000,"Large Cap",IF(AND(10000>V6,2000<V6),"Mid Cap",IF(AND(2000>V6,V6>50),"Small Cap",IF(V6<50,"Micro Cap",NA)))) -> Large Cap
D10: Earnings per share | F10: -0.01 | G10: -0.18 | H10: 3.58 | I10: -0.11 | J10: 2.11 | L10: 0.49 | M10: 2.08 | N10: -0.04 | O10: -1.21 | P10: 3.07 | Q10: 5.4 | S10: Dividend Yield | X10: Financial Health | AC10: Financials | AE10: =L4 -> 2013 | AF10: =M4 -> 2014 | AG10: =N4 -> 2015 | AH10: =O4 -> 2016 | AI10: =P4 -> 2017
F11: 9244590 | G11: 9261862 | H11: 9313304 | I11: 9392197 | J11: 9436845 | L11: 8736000 | M11: 8911000 | N11: 9067697 | O11: 9154437 | P11: 9252275 | Q11: 9351052
F12: -0.01 | G12: -0.18 | H12: 3.58 | I12: -0.11 | J12: 2.11 | L12: 0.49 | M12: 2.08 | N12: -0.04 | O12: -1.21 | P12: 3.07 | Q12: 5.4
D13: Weighted average share… | F13: 9244590 | G13: 9261862 | H13: 9313304 | I13: 9392197 | J13: 9436845 | L13: 8736000 | M13: 8911000 | N13: 9067697 | O13: 9154437 | P13: 9252275 | Q13: 9351052 | X13: Current Ratio | AA13: =AVERAGE(G19:J19)/AVERAGE(G22:J22) -> 5.4407029 | AC13: Revenue | AE13: =IF(L5="","",L5) -> 63444000 | AF13: =IF(M5="","",M5) -> 71171000 | AG13: =IF(N5="","",N5) -> 64459000 | AH13: =IF(O5="","",O5) -> 61149000 | AI13: =IF(P5="","",P5) -> 27647000
D14: EBITDA | F14: 478000 | G14: -1093000 | H14: -7467000 | I14: -786000 | J14: -3582000 | L14: 7845000 | M14: 7461000 | N14: 2102000 | O14: 4516000 | P14: -10421000 | Q14: -13095000 | S14: Valuation | X14: Financial Leverage | AA14: =AVERAGE(G20:J20)/AVERAGE(G25:J25) -> 1.3644479 | AC14: Gross Margin % | AE14: =IF(OR(L5="",L7=""),"",L7/L5) -> 0.58062228 | AF14: =IF(OR(M5="",M7=""),"",M7/M5) -> 0.56782959 | AG14: =IF(OR(N5="",N7=""),"",N7/N5) -> 0.5645449 | AH14: =IF(OR(O5="",O7=""),"",O7/O5) -> 0.59291239 | AI14: =IF(OR(P5="",P7=""),"",P7/P5) -> 0.54960755
S15: P / E | V15: =IF(Q10>0,V5/Q10,"") -> 1.0037037 | X15: Debt / Equity | AA15: =AVERAGE(G23:J23)/AVERAGE(G25:J25) -> #DIV/0! | AC15: Operating Income | AE15: =IF(L8="","",L8) -> 5035000 | AF15: =IF(M8="","",M8) -> 5300000 | AG15: =IF(N8="","",N8) -> 946000 | AH15: =IF(O8="","",O8) -> 1945000 | AI15: =IF(P8="","",P8) -> -12236000
D16: Balance Sheet | F16: =F4 -> 2016-10 | G16: =G4 -> 2017-01 | H16: =H4 -> 2017-04 | I16: =I4 -> 2017-07 | J16: =J4 -> 2017-10 | L16: =L4 -> 2013 | M16: =M4 -> 2014 | N16: =N4 -> 2015 | O16: =O4 -> 2016 | P16: =P4 -> 2017 | S16: P / B | V16: =V5/((J20-J24)/J13) -> 0.82340905 | AC16: Operating Margin % | AE16: =IF(OR(L5="",L8=""),"",L8/L5) -> 0.079361327 | AF16: =IF(OR(M5="",M8=""),"",M8/M5) -> 0.074468534 | AG16: =IF(OR(N5="",N8=""),"",N8/N5) -> 0.014675996 | AH16: =IF(OR(O5="",O8=""),"",O8/O5) -> 0.031807552 | AI16: =IF(OR(P5="",P8=""),"",P8/P5) -> -0.44257967
D17: Cash and cash equivale… | F17: 18804000 | G17: 15750000 | H17: 35893000 | I17: 31624000 | J17: 57547000 | L17: 27927000 | M17: 28074000 | N17: 25451000 | O17: 20268000 | P17: 35893000 | S17: P / S | V17: =V5/(Q5/Q13) -> 0.20273081 | X17: Income Statement | AC17: Net Income | AE17: =IF(L9="","",L9) -> 4248000 | AF17: =IF(M9="","",M9) -> 18505000 | AG17: =IF(N9="","",N9) -> -345000 | AH17: =IF(O9="","",O9) -> -11113000 | AI17: =IF(P9="","",P9) -> 28381000
D18: Total cash | F18: 18804000 | G18: 18173000 | H18: 42763000 | I18: 37908000 | J18: 65514000 | L18: 27927000 | M18: 28074000 | N18: 25451000 | O18: 20268000 | P18: 42763000 | S18: P / CFO | V18: =IF(AVERAGE(N28:P28)>0,V5/(AVERAGE(N28:P28)/Q13),"") | X18: Revenue | AA18: =Q5 -> 250000000 | AC18: Earnings Per Share | AE18: =IF(L10="","",L10) -> 0.49 | AF18: =IF(M10="","",M10) -> 2.08 | AG18: =IF(N10="","",N10) -> -0.04 | AH18: =IF(O10="","",O10) -> -1.21 | AI18: =IF(P10="","",P10) -> 3.07
D19: Total current assets | F19: 29921000 | G19: 31911000 | H19: 54924000 | I19: 50227000 | J19: 69750000 | L19: 43796000 | M19: 44963000 | N19: 41213000 | O19: 39928000 | P19: 54924000 | S19: P / FCF | V19: =IF(AVERAGE(N30:P30)>0,V6/AVERAGE(N30:P30),"") | X19: Gross Profit | AA19: =Q7 -> 0 | AC19: Shares | AE19: =IF(L13="","",L13) -> 8736000 | AF19: =IF(M13="","",M13) -> 8911000 | AG19: =IF(N13="","",N13) -> 9067697 | AH19: =IF(O13="","",O13) -> 9154437 | AI19: =IF(P13="","",P13) -> 9252275
D20: Total assets | F20: 34785000 | G20: 36347000 | H20: 57807000 | I20: 53132000 | J20: 71596000 | L20: 48469000 | M20: 62386000 | N20: 57873000 | O20: 45236000 | P20: 57807000 | S20: EV / EBITDA | V20: =(V6+(J21+J23)-J17)/J14 -> 1.9163311 | X20: Net Income | AA20: =Q9 -> 50275000 | AC20: Book Value Per Share | AE20: =IF(OR(L25="",L13="",L20="",L24=""),"",(L20-L24)/L13) -> 2.9515797 | AF20: =IF(OR(M25="",M13="",M20="",M24=""),"",(M20-M24)/M13) -> 4.5397823 | AG20: =IF(OR(N25="",N13="",N20="",N24=""),"",(N20-N24)/N13) -> 4.0369677 | AH20: =IF(OR(O25="",O13="",O20="",O24=""),"",(O20-O24)/O13) -> 2.2937511 | AI20: =IF(OR(P25="",P13="",P20="",P24=""),"",(P20-P24)/P13) -> 4.6981958
D21: Short-term debt | X21: Earnings Per Share | AA21: =Q10 -> 5.4
D22: Total current liabilities | F22: 12513000 | G22: 16619000 | H22: 9618000 | I22: 6946000 | J22: 4829000 | L22: 16054000 | M22: 15032000 | N22: 14704000 | O22: 17317000 | P22: 9618000 | AC22: Profitability | AE22: =L4 -> 2013 | AF22: =M4 -> 2014 | AG22: =N4 -> 2015 | AH22: =O4 -> 2016 | AI22: =P4 -> 2017
D23: Long-term debt | S23: Profitability | X23: Balance Sheet | AC23: Net Margin % | AE23: =IF(OR(L5="",L9="",L5=0,L9=0),"",L9/L5) -> 0.066956686 | AF23: =IF(OR(M5="",M9="",M5=0,M9=0),"",M9/M5) -> 0.26000759 | AG23: =IF(OR(N5="",N9="",N5=0,N9=0),"",N9/N5) -> -0.0053522394 | AH23: =IF(OR(O5="",O9="",O5=0,O9=0),"",O9/O5) -> -0.18173641 | AI23: =IF(OR(P5="",P9="",P5=0,P9=0),"",P9/P5) -> 1.026549
D24: Total liabilities | F24: 18780000 | G24: 22978000 | H24: 14338000 | I24: 11669000 | J24: 9479000 | L24: 22684000 | M24: 21932000 | N24: 21267000 | O24: 24238000 | P24: 14338000 | S24: Sales | V24: =Q5 -> 250000000 | X24: Total Cash | AA24: =J18 -> 65514000 | AC24: Return on Equity % | AE24: =IF(OR(L9="",L23="",L9=0,L23=0),"",L9/L23) | AF24: =IF(OR(M9="",M23="",M9=0,M23=0),"",M9/M23) | AG24: =IF(OR(N9="",N23="",N9=0,N23=0),"",N9/N23) | AH24: =IF(OR(O9="",O23="",O9=0,O23=0),"",O9/O23) | AI24: =IF(OR(P9="",P23="",P9=0,P23=0),"",P9/P23)
D25: Total stockholders' eq… | F25: 16005000 | G25: 13369000 | H25: 43469000 | I25: 41463000 | J25: 62117000 | L25: 25785000 | M25: 40454000 | N25: 36606000 | O25: 20998000 | P25: 43469000 | S25: Gross Margin | V25: =(Q5-Q6)/Q5 -> 1 | X25: Current Assets | AA25: =J19 -> 69750000 | AC25: Return on Assets % | AE25: =IF(OR(L9="",L20="",L9=0,L20=0),"",L9/L20) -> 0.087643649 | AF25: =IF(OR(M9="",M20="",M9=0,M20=0),"",M9/M20) -> 0.29662104 | AG25: =IF(OR(N9="",N20="",N9=0,N20=0),"",N9/N20) -> -0.0059613291 | AH25: =IF(OR(O9="",O20="",O9=0,O20=0),"",O9/O20) -> -0.24566717 | AI25: =IF(OR(P9="",P20="",P9=0,P20=0),"",P9/P20) -> 0.4909613
S26: Net Margin | V26: =Q9/Q5 -> 0.2011 | X26: Current Liabilities | AA26: =J22 -> 4829000 | AC26: Asset Turnover | AE26: =IF(OR(L5="",L20="",L5=0,L20=0),"",L5/L20) -> 1.3089604 | AF26: =IF(OR(M5="",M20="",M5=0,M20=0),"",M5/M20) -> 1.1408168 | AG26: =IF(OR(N5="",N20="",N5=0,N20=0),"",N5/N20) -> 1.1138009 | AH26: =IF(OR(O5="",O20="",O5=0,O20=0),"",O5/O20) -> 1.3517773 | AI26: =IF(OR(P5="",P20="",P5=0,P20=0),"",P5/P20) -> 0.47826388
D27: Cash Flow | F27: =F4 -> 2016-10 | G27: =G4 -> 2017-01 | H27: =H4 -> 2017-04 | I27: =I4 -> 2017-07 | J27: =J4 -> 2017-10 | L27: =L4 -> 2013 | M27: =M4 -> 2014 | N27: =N4 -> 2015 | O27: =O4 -> 2016 | P27: =P4 -> 2017 | Q27: TTM | S27: Operating Margin | V27: =Q8/Q5 -> -0.119164 | X27: Total Debt | AA27: =J21+J23 -> 0
D28: Operating cash flow | F28: 1134000 | G28: 622000 | H28: -5190000 | I28: -3505000 | J28: -113000 | L28: 4924000 | M28: 6768000 | N28: 3544000 | O28: -2221000 | P28: -3004000 | Q28: -8186000 | AC28: Financial Health | AE28: =L4 -> 2013 | AF28: =M4 -> 2014 | AG28: =N4 -> 2015 | AH28: =O4 -> 2016 | AI28: =P4 -> 2017
D29: Capital expenditure | F29: -190000 | G29: -182000 | H29: -193000 | I29: -222000 | J29: -53000 | L29: -1447000 | M29: -1900000 | N29: -1949000 | O29: -2286000 | P29: -912000 | Q29: -650000 | S29: Effectiveness | X29: Cash Flow Statement | AC29: Current Ratio | AE29: =IF(OR(L19="",L22="",L19=0,L22=0),"",L19/L22) -> 2.7280429 | AF29: =IF(OR(M19="",M22="",M19=0,M22=0),"",M19/M22) -> 2.9911522 | AG29: =IF(OR(N19="",N22="",N19=0,N22=0),"",N19/N22) -> 2.8028428 | AH29: =IF(OR(O19="",O22="",O19=0,O22=0),"",O19/O22) -> 2.3057112 | AI29: =IF(OR(P19="",P22="",P19=0,P22=0),"",P19/P22) -> 5.7105427
D30: Free cash flow | F30: 944000 | G30: 440000 | H30: -5383000 | I30: -3727000 | J30: -166000 | L30: 3477000 | M30: 4868000 | N30: 1595000 | O30: -4507000 | P30: -3916000 | Q30: -8836000 | S30: Return on Equity | V30: =Q9/AVERAGE(G25:J25) -> 1.2536 | X30: Operating Cash Flow | AA30: =AVERAGE(N28:P28) -> -560333.33 | AC30: Financial Leverage | AE30: =IF(OR(L20="",L23="",L20=0,L23=0),"",L20/L23) | AF30: =IF(OR(M20="",M23="",M20=0,M23=0),"",M20/M23) | AG30: =IF(OR(N20="",N23="",N20=0,N23=0),"",N20/N23) | AH30: =IF(OR(O20="",O23="",O20=0,O23=0),"",O20/O23) | AI30: =IF(OR(P20="",P23="",P20=0,P23=0),"",P20/P23)
S31: Return on Assets | V31: =Q9/AVERAGE(G20:J20) -> 0.91875988 | X31: Capital Expenditure | AA31: =ABS(AVERAGE(N29:P29)) -> 1715666.7 | AC31: Debt / Equity | AE31: =IF(OR(L25="",L23="",L23=0,L25=0),"",L25/L23) | AF31: =IF(OR(M25="",M23="",M23=0,M25=0),"",M25/M23) | AG31: =IF(OR(N25="",N23="",N23=0,N25=0),"",N25/N23) | AH31: =IF(OR(O25="",O23="",O23=0,O25=0),"",O25/O23) | AI31: =IF(OR(P25="",P23="",P23=0,P25=0),"",P25/P23)
S32: Return on Capital Employed | V32: =Q8/(AVERAGE(G25:J25)+(AVERAGE(G20:J20)-AVERAGE(G22:J22))) -> -0.34915965 | X32: Free Cash Flow | AA32: =AVERAGE(N30:P30) -> -2276000
S33: Asset Turnover | V33: =Q5/AVERAGE(G20:J20) -> 4.5686717
A36: 2 | S36: Symbol | T36: CRAY | V36: USD
D38: Income Statement | F38: 2016-10 | G38: 2017-01 | H38: 2017-04 | I38: 2017-07 | J38: 2017-10 | L38: 2013 | M38: 2014 | N38: 2015 | O38: 2016 | P38: 2017 | Q38: TTM | S38: Quote | X38: Growth | AA38: 5-Year Average | AC38: Key Ratios ― Growth, YOY | AF38: =M38 -> 2014 | AG38: =N38 -> 2015 | AH38: =O38 -> 2016 | AI38: =P38 -> 2017
D39: Revenue | F39: 346574000 | G39: 59031000 | H39: 87135000 | I39: 79700000 | J39: 166643000 | L39: 525749000 | M39: 561606000 | N39: 724689000 | O39: 629809000 | P39: 392509000 | Q39: 392509000 | S39: Last Price | V39: 21.25 | X39: Revenue | AA39: =IF(AA38="Year over Year",AI39,IF(AA38="3-Year Average",AVERAGE(AH39:AI39),IF(AA38="5-Year Average",AVERAGE(AF39:AI39),""))) -> -0.037279356 | AC39: Revenue % | AF39: =IF(AND(M39>0,L39>0,L39<>""),M39/L39-1,IF(AND(L39<0,M39<0,L39<>""),(M39-L39)/ABS(L39),IF(AND(L39>0,M39<0,L39<>""),"L",IF(AND(L39<0,M39>0,L39<>""),"P","")))) -> 0.068201746 | AG39: =IF(AND(N39>0,M39>0,M39<>""),N39/M39-1,IF(AND(M39<0,N39<0,M39<>""),(N39-M39)/ABS(M39),IF(AND(M39>0,N39<0,M39<>""),"L",IF(AND(M39<0,N39>0,M39<>""),"P","")))) -> 0.29038685 | AH39: =IF(AND(O39>0,N39>0,N39<>""),O39/N39-1,IF(AND(N39<0,O39<0,N39<>""),(O39-N39)/ABS(N39),IF(AND(N39>0,O39<0,N39<>""),"L",IF(AND(N39<0,O39>0,N39<>""),"P","")))) -> -0.13092513 | AI39: =IF(AND(P39>0,O39>0,O39<>""),P39/O39-1,IF(AND(O39<0,P39<0,O39<>""),(P39-O39)/ABS(O39),IF(AND(O39>0,P39<0,O39<>""),"L",IF(AND(O39<0,P39>0,O39<>""),"P","")))) -> -0.3767809
D40: Cost of revenue | F40: 226083000 | G40: 35222000 | H40: 58792000 | I40: 51208000 | J40: 116583000 | L40: 341423000 | M40: 377192000 | N40: 499006000 | O40: 409594000 | P40: 261805000 | Q40: 261805000 | S40: Market Capitalization | V40: =V39*Q47 -> 852953750 | X40: Operating Income | AA40: =IF(AA38="Year over Year",AI40,IF(AA38="3-Year Average",AVERAGE(AH40:AI40),IF(AA38="5-Year Average",AVERAGE(AF40:AI40),""))) -> 0.70159316 | AC40: Operating Income % | AF40: =IF(AND(M42>0,L42>0,L42<>""),M42/L42-1,IF(AND(L42<0,M42<0,L42<>""),(M42-L42)/ABS(L42),IF(AND(L42>0,M42<0,L42<>""),"L",IF(AND(L42<0,M42>0,L42<>""),"P","")))) -> -0.57505774 | AG40: =IF(AND(N42>0,M42>0,M42<>""),N42/M42-1,IF(AND(M42<0,N42<0,M42<>""),(N42-M42)/ABS(M42),IF(AND(M42>0,N42<0,M42<>""),"L",IF(AND(M42<0,N42>0,M42<>""),"P","")))) -> 3.4569565 | AH40: =IF(AND(O42>0,N42>0,N42<>""),O42/N42-1,IF(AND(N42<0,O42<0,N42<>""),(O42-N42)/ABS(N42),IF(AND(N42>0,O42<0,N42<>""),"L",IF(AND(N42<0,O42>0,N42<>""),"P","")))) -> -0.77711931 | AI40: =IF(AND(P42>0,O42>0,O42<>""),P42/O42-1,IF(AND(O42<0,P42<0,O42<>""),(P42-O42)/ABS(O42),IF(AND(O42>0,P42<0,O42<>""),"L",IF(AND(O42<0,P42>0,O42<>""),"P","")))) -> L
D41: Gross profit | F41: 120491000 | G41: 23809000 | H41: 28343000 | I41: 28492000 | J41: 50060000 | L41: 184326000 | M41: 184414000 | N41: 225683000 | O41: 220215000 | P41: 130704000 | Q41: 130704000 | S41: Enterprise Value | V41: =V40+(J55+J57)-J51 -> 715627750 | X41: Net Income | AA41: =IF(AA38="Year over Year",AI41,IF(AA38="3-Year Average",AVERAGE(AH41:AI41),IF(AA38="5-Year Average",AVERAGE(AF41:AI41),""))) -> -0.079519988 | AC41: Net Income % | AF41: =IF(AND(M43>0,L43>0,L43<>""),M43/L43-1,IF(AND(L43<0,M43<0,L43<>""),(M43-L43)/ABS(L43),IF(AND(L43>0,M43<0,L43<>""),"L",IF(AND(L43<0,M43>0,L43<>""),"P","")))) -> 0.93411538 | AG41: =IF(AND(N43>0,M43>0,M43<>""),N43/M43-1,IF(AND(M43<0,N43<0,M43<>""),(N43-M43)/ABS(M43),IF(AND(M43>0,N43<0,M43<>""),"L",IF(AND(M43<0,N43>0,M43<>""),"P","")))) -> -0.5581567 | AH41: =IF(AND(O43>0,N43>0,N43<>""),O43/N43-1,IF(AND(N43<0,O43<0,N43<>""),(O43-N43)/ABS(N43),IF(AND(N43>0,O43<0,N43<>""),"L",IF(AND(N43<0,O43>0,N43<>""),"P","")))) -> -0.61451865 | AI41: =IF(AND(P43>0,O43>0,O43<>""),P43/O43-1,IF(AND(O43<0,P43<0,O43<>""),(P43-O43)/ABS(O43),IF(AND(O43>0,P43<0,O43<>""),"L",IF(AND(O43<0,P43>0,O43<>""),"P","")))) -> L
D42: Operating income | F42: 62454000 | G42: -32281000 | H42: -11434000 | I42: -26201000 | J42: 4268000 | L42: 21650000 | M42: 9200000 | N42: 41004000 | O42: 9139000 | P42: -65648000 | Q42: -65648000 | S42: Book Value | V42: =J54-J58 -> 400297000 | X42: Earnings Per Share | AA42: =IF(AA38="Year over Year",AI42,IF(AA38="3-Year Average",AVERAGE(AH42:AI42),IF(AA38="5-Year Average",AVERAGE(AF42:AI42),""))) -> -0.095128486 | AC42: Earnings per share % | AF42: =IF(AND(M44>0,L44>0,L44<>""),M44/L44-1,IF(AND(L44<0,M44<0,L44<>""),(M44-L44)/ABS(L44),IF(AND(L44>0,M44<0,L44<>""),"L",IF(AND(L44<0,M44>0,L44<>""),"P","")))) -> 0.89411765 | AG42: =IF(AND(N44>0,M44>0,M44<>""),N44/M44-1,IF(AND(M44<0,N44<0,M44<>""),(N44-M44)/ABS(M44),IF(AND(M44>0,N44<0,M44<>""),"L",IF(AND(M44<0,N44>0,M44<>""),"P","")))) -> -0.56521739 | AH42: =IF(AND(O44>0,N44>0,N44<>""),O44/N44-1,IF(AND(N44<0,O44<0,N44<>""),(O44-N44)/ABS(N44),IF(AND(N44>0,O44<0,N44<>""),"L",IF(AND(N44<0,O44>0,N44<>""),"P","")))) -> -0.61428571 | AI42: =IF(AND(P44>0,O44>0,O44<>""),P44/O44-1,IF(AND(O44<0,P44<0,O44<>""),(P44-O44)/ABS(O44),IF(AND(O44>0,P44<0,O44<>""),"L",IF(AND(O44<0,P44>0,O44<>""),"P","")))) -> L
D43: Net income | F43: 51775000 | G43: -19215000 | H43: -6840000 | I43: -10232000 | J43: -97542000 | L43: 32223000 | M43: 62323000 | N43: 27537000 | O43: 10615000 | P43: -133829000 | Q43: -133829000 | S43: Type | V43: =IF(V40>10000,"Large Cap",IF(AND(10000>V40,2000<V40),"Mid Cap",IF(AND(2000>V40,V40>50),"Small Cap",IF(V40<50,"Micro Cap",NA)))) -> Large Cap
D44: Earnings per share | F44: 1.3 | G44: -0.48 | H44: -0.17 | I44: -0.25 | J44: -2.42 | L44: 0.85 | M44: 1.61 | N44: 0.7 | O44: 0.27 | P44: -3.33 | Q44: -3.33 | S44: Dividend Yield | X44: Financial Health | AC44: Financials | AE44: =L38 -> 2013 | AF44: =M38 -> 2014 | AG44: =N38 -> 2015 | AH44: =O38 -> 2016 | AI44: =P38 -> 2017
F45: 39974000 | G45: 39994000 | H45: 40051000 | I45: 40199000 | J45: 40310000 | L45: 37832000 | M45: 38634000 | N45: 39257000 | O45: 39833000 | P45: 40139000 | Q45: 40139000
...

Sheet Sheet 3
A1: source
A2: Gross Margin % | C2: Return on Equity % | E2: Debt / Equity | G2: Current Ratio | I2: USD in Billion | K2: Year over Year
A3: Net Margin % | C3: Return on Assets % | E3: Financial Leverage | G3: Quick Ratio | I3: USD in Million | K3: 3-Year Average
A4: Operating Margin % | I4: USD in Thousand | K4: 5-Year Average
I5: USD
